2025-10-20 12:09:11 | ERROR | dataiq | Failed to create SQLAlchemy engine: No module named 'cx_Oracle'
Traceback (most recent call last):
  File "C:\Users\ABIE\Desktop\DataIQ\dataiq\oracle_connector.py", line 186, in get_engine
    self.engine = create_engine(url, **kwargs)
                  ^^^^^^^^^^^^^^^^^^^^^^^^^^^^
  File "<string>", line 2, in create_engine
  File "C:\Users\ABIE\AppData\Local\Programs\Python\Python311\Lib\site-packages\sqlalchemy\util\deprecations.py", line 281, in warned
    return fn(*args, **kwargs)  # type: ignore[no-any-return]
           ^^^^^^^^^^^^^^^^^^^
  File "C:\Users\ABIE\AppData\Local\Programs\Python\Python311\Lib\site-packages\sqlalchemy\engine\create.py", line 601, in create_engine
    dbapi = dbapi_meth(**dbapi_args)
            ^^^^^^^^^^^^^^^^^^^^^^^^
  File "C:\Users\ABIE\AppData\Local\Programs\Python\Python311\Lib\site-packages\sqlalchemy\dialects\oracle\cx_oracle.py", line 1101, in import_dbapi
    import cx_Oracle
ModuleNotFoundError: No module named 'cx_Oracle'
2025-10-20 12:09:11 | ERROR | dataiq | Connection test failed: No module named 'cx_Oracle'
2025-10-20 12:12:34 | INFO | dataiq | SQLAlchemy engine created
2025-10-20 12:12:34 | ERROR | dataiq | Connection test failed: connect() got an unexpected keyword argument 'encoding'
2025-10-20 12:12:54 | INFO | dataiq | SQLAlchemy engine created
2025-10-20 12:12:55 | INFO | dataiq | Connected to Oracle database
2025-10-20 12:12:55 | INFO | dataiq | Connection test succeeded
2025-10-20 12:12:55 | INFO | dataiq | Connected to Oracle database
2025-10-20 12:12:55 | INFO | dataiq | Found 134 tables
2025-10-20 12:12:55 | INFO | dataiq | Loaded 3 columns for AQ$_INTERNET_AGENTS
2025-10-20 12:12:55 | INFO | dataiq | Sampled 5 rows from AQ$_INTERNET_AGENTS
2025-10-20 12:12:55 | INFO | dataiq | Disposed SQLAlchemy engine
2025-10-20 12:14:16 | INFO | dataiq | Starting environment setup
2025-10-20 12:14:16 | INFO | dataiq | Checking Oracle connectivity...
2025-10-20 12:14:16 | INFO | dataiq | python-oracledb module imported successfully
2025-10-20 12:14:16 | INFO | dataiq | SQLAlchemy engine created
2025-10-20 12:14:16 | INFO | dataiq | Connected to Oracle database
2025-10-20 12:14:16 | INFO | dataiq | Connection test succeeded
2025-10-20 12:14:16 | INFO | dataiq | Oracle connection test passed
2025-10-20 12:14:16 | INFO | dataiq | Disposed SQLAlchemy engine
2025-10-20 12:14:16 | INFO | dataiq | Verifying folder structure...
2025-10-20 12:14:16 | INFO | dataiq | Creating folder: outputs/reports
2025-10-20 12:14:16 | INFO | dataiq | Creating folder: outputs/profiles
2025-10-20 12:14:16 | INFO | dataiq | Creating folder: outputs/cleaned_data
2025-10-20 12:14:16 | INFO | dataiq | Creating folder: dashboard/assets/charts
2025-10-20 12:14:16 | INFO | dataiq | Folder structure verified
2025-10-20 12:14:16 | INFO | dataiq | Checking dependencies...
2025-10-20 12:14:16 | INFO | dataiq | All dependencies present
2025-10-20 12:14:16 | INFO | dataiq | Checking python-oracledb mode...
2025-10-20 12:14:16 | INFO | dataiq | python-oracledb version: 3.4.0
2025-10-20 12:14:16 | INFO | dataiq | python-oracledb running in thin mode
2025-10-20 12:14:16 | INFO | dataiq | Environment setup completed successfully
2025-10-20 12:15:07 | INFO | dataiq | SQLAlchemy engine created
2025-10-20 12:15:07 | INFO | dataiq | Connected to Oracle database
2025-10-20 12:15:07 | INFO | dataiq | Connection test succeeded
2025-10-20 12:15:07 | INFO | dataiq | Connected to Oracle database
2025-10-20 12:15:08 | INFO | dataiq | Found 134 tables
2025-10-20 12:15:08 | INFO | dataiq | Loaded 3 columns for AQ$_INTERNET_AGENTS
2025-10-20 12:15:08 | INFO | dataiq | Sampled 5 rows from AQ$_INTERNET_AGENTS
2025-10-20 12:15:08 | INFO | dataiq | Disposed SQLAlchemy engine
2025-10-20 12:16:20 | INFO | dataiq | SQLAlchemy engine created
2025-10-20 12:16:21 | INFO | dataiq | Connected to Oracle database
2025-10-20 12:16:21 | INFO | dataiq | Connection test succeeded
2025-10-20 12:16:21 | INFO | dataiq | Connected to Oracle database
2025-10-20 12:16:21 | ERROR | dataiq | Main orchestration failed: (oracledb.exceptions.DatabaseError) ORA-00942: table or view does not exist
Help: https://docs.oracle.com/error-help/db/ora-00942/
[SQL: SELECT * FROM AQ FETCH FIRST 100 ROWS ONLY]
(Background on this error at: https://sqlalche.me/e/20/4xp6)
Traceback (most recent call last):
  File "C:\Users\ABIE\AppData\Local\Programs\Python\Python311\Lib\site-packages\sqlalchemy\engine\base.py", line 1969, in _exec_single_context
    self.dialect.do_execute(
  File "C:\Users\ABIE\AppData\Local\Programs\Python\Python311\Lib\site-packages\sqlalchemy\engine\default.py", line 922, in do_execute
    cursor.execute(statement, parameters)
  File "C:\Users\ABIE\AppData\Local\Programs\Python\Python311\Lib\site-packages\oracledb\cursor.py", line 844, in execute
    impl.execute(self)
  File "src/oracledb/impl/thin/cursor.pyx", line 277, in oracledb.thin_impl.ThinCursorImpl.execute
  File "src/oracledb/impl/thin/protocol.pyx", line 501, in oracledb.thin_impl.Protocol._process_single_message
  File "src/oracledb/impl/thin/protocol.pyx", line 502, in oracledb.thin_impl.Protocol._process_single_message
  File "src/oracledb/impl/thin/protocol.pyx", line 494, in oracledb.thin_impl.Protocol._process_message
  File "src/oracledb/impl/thin/messages/base.pyx", line 102, in oracledb.thin_impl.Message._check_and_raise_exception
oracledb.exceptions.DatabaseError: ORA-00942: table or view does not exist
Help: https://docs.oracle.com/error-help/db/ora-00942/

The above exception was the direct cause of the following exception:

Traceback (most recent call last):
  File "C:\Users\ABIE\Desktop\DataIQ\main.py", line 81, in orchestrate
    result = run_profile(conn, table, limit)
             ^^^^^^^^^^^^^^^^^^^^^^^^^^^^^^^
  File "C:\Users\ABIE\Desktop\DataIQ\main.py", line 28, in run_profile
    df = conn.fetch_table_data(table_name=table, limit=limit)
         ^^^^^^^^^^^^^^^^^^^^^^^^^^^^^^^^^^^^^^^^^^^^^^^^^^^^
  File "C:\Users\ABIE\Desktop\DataIQ\dataiq\oracle_connector.py", line 231, in fetch_table_data
    return self.sample_table(table=table_name, schema=schema, rows=limit)
           ^^^^^^^^^^^^^^^^^^^^^^^^^^^^^^^^^^^^^^^^^^^^^^^^^^^^^^^^^^^^^^
  File "C:\Users\ABIE\Desktop\DataIQ\dataiq\oracle_connector.py", line 346, in sample_table
    df = pd.read_sql(text(q), conn)
         ^^^^^^^^^^^^^^^^^^^^^^^^^^
  File "C:\Users\ABIE\AppData\Local\Programs\Python\Python311\Lib\site-packages\pandas\io\sql.py", line 734, in read_sql
    return pandas_sql.read_query(
           ^^^^^^^^^^^^^^^^^^^^^^
  File "C:\Users\ABIE\AppData\Local\Programs\Python\Python311\Lib\site-packages\pandas\io\sql.py", line 1839, in read_query
    result = self.execute(sql, params)
             ^^^^^^^^^^^^^^^^^^^^^^^^^
  File "C:\Users\ABIE\AppData\Local\Programs\Python\Python311\Lib\site-packages\pandas\io\sql.py", line 1663, in execute
    return self.con.execute(sql, *args)
           ^^^^^^^^^^^^^^^^^^^^^^^^^^^^
  File "C:\Users\ABIE\AppData\Local\Programs\Python\Python311\Lib\site-packages\sqlalchemy\engine\base.py", line 1416, in execute
    return meth(
           ^^^^^
  File "C:\Users\ABIE\AppData\Local\Programs\Python\Python311\Lib\site-packages\sqlalchemy\sql\elements.py", line 517, in _execute_on_connection
    return connection._execute_clauseelement(
           ^^^^^^^^^^^^^^^^^^^^^^^^^^^^^^^^^^
  File "C:\Users\ABIE\AppData\Local\Programs\Python\Python311\Lib\site-packages\sqlalchemy\engine\base.py", line 1639, in _execute_clauseelement
    ret = self._execute_context(
          ^^^^^^^^^^^^^^^^^^^^^^
  File "C:\Users\ABIE\AppData\Local\Programs\Python\Python311\Lib\site-packages\sqlalchemy\engine\base.py", line 1848, in _execute_context
    return self._exec_single_context(
           ^^^^^^^^^^^^^^^^^^^^^^^^^^
  File "C:\Users\ABIE\AppData\Local\Programs\Python\Python311\Lib\site-packages\sqlalchemy\engine\base.py", line 1988, in _exec_single_context
    self._handle_dbapi_exception(
  File "C:\Users\ABIE\AppData\Local\Programs\Python\Python311\Lib\site-packages\sqlalchemy\engine\base.py", line 2344, in _handle_dbapi_exception
    raise sqlalchemy_exception.with_traceback(exc_info[2]) from e
  File "C:\Users\ABIE\AppData\Local\Programs\Python\Python311\Lib\site-packages\sqlalchemy\engine\base.py", line 1969, in _exec_single_context
    self.dialect.do_execute(
  File "C:\Users\ABIE\AppData\Local\Programs\Python\Python311\Lib\site-packages\sqlalchemy\engine\default.py", line 922, in do_execute
    cursor.execute(statement, parameters)
  File "C:\Users\ABIE\AppData\Local\Programs\Python\Python311\Lib\site-packages\oracledb\cursor.py", line 844, in execute
    impl.execute(self)
  File "src/oracledb/impl/thin/cursor.pyx", line 277, in oracledb.thin_impl.ThinCursorImpl.execute
  File "src/oracledb/impl/thin/protocol.pyx", line 501, in oracledb.thin_impl.Protocol._process_single_message
  File "src/oracledb/impl/thin/protocol.pyx", line 502, in oracledb.thin_impl.Protocol._process_single_message
  File "src/oracledb/impl/thin/protocol.pyx", line 494, in oracledb.thin_impl.Protocol._process_message
  File "src/oracledb/impl/thin/messages/base.pyx", line 102, in oracledb.thin_impl.Message._check_and_raise_exception
sqlalchemy.exc.DatabaseError: (oracledb.exceptions.DatabaseError) ORA-00942: table or view does not exist
Help: https://docs.oracle.com/error-help/db/ora-00942/
[SQL: SELECT * FROM AQ FETCH FIRST 100 ROWS ONLY]
(Background on this error at: https://sqlalche.me/e/20/4xp6)
Traceback (most recent call last):
  File "C:\Users\ABIE\AppData\Local\Programs\Python\Python311\Lib\site-packages\sqlalchemy\engine\base.py", line 1969, in _exec_single_context
    self.dialect.do_execute(
  File "C:\Users\ABIE\AppData\Local\Programs\Python\Python311\Lib\site-packages\sqlalchemy\engine\default.py", line 922, in do_execute
    cursor.execute(statement, parameters)
  File "C:\Users\ABIE\AppData\Local\Programs\Python\Python311\Lib\site-packages\oracledb\cursor.py", line 844, in execute
    impl.execute(self)
  File "src/oracledb/impl/thin/cursor.pyx", line 277, in oracledb.thin_impl.ThinCursorImpl.execute
  File "src/oracledb/impl/thin/protocol.pyx", line 501, in oracledb.thin_impl.Protocol._process_single_message
  File "src/oracledb/impl/thin/protocol.pyx", line 502, in oracledb.thin_impl.Protocol._process_single_message
  File "src/oracledb/impl/thin/protocol.pyx", line 494, in oracledb.thin_impl.Protocol._process_message
  File "src/oracledb/impl/thin/messages/base.pyx", line 102, in oracledb.thin_impl.Message._check_and_raise_exception
oracledb.exceptions.DatabaseError: ORA-00942: table or view does not exist
Help: https://docs.oracle.com/error-help/db/ora-00942/

The above exception was the direct cause of the following exception:

Traceback (most recent call last):
  File "C:\Users\ABIE\Desktop\DataIQ\main.py", line 81, in orchestrate
    result = run_profile(conn, table, limit)
             ^^^^^^^^^^^^^^^^^^^^^^^^^^^^^^^
  File "C:\Users\ABIE\Desktop\DataIQ\main.py", line 28, in run_profile
    df = conn.fetch_table_data(table_name=table, limit=limit)
         ^^^^^^^^^^^^^^^^^^^^^^^^^^^^^^^^^^^^^^^^^^^^^^^^^^^^
  File "C:\Users\ABIE\Desktop\DataIQ\dataiq\oracle_connector.py", line 231, in fetch_table_data
    return self.sample_table(table=table_name, schema=schema, rows=limit)
           ^^^^^^^^^^^^^^^^^^^^^^^^^^^^^^^^^^^^^^^^^^^^^^^^^^^^^^^^^^^^^^
  File "C:\Users\ABIE\Desktop\DataIQ\dataiq\oracle_connector.py", line 346, in sample_table
    df = pd.read_sql(text(q), conn)
         ^^^^^^^^^^^^^^^^^^^^^^^^^^
  File "C:\Users\ABIE\AppData\Local\Programs\Python\Python311\Lib\site-packages\pandas\io\sql.py", line 734, in read_sql
    return pandas_sql.read_query(
           ^^^^^^^^^^^^^^^^^^^^^^
  File "C:\Users\ABIE\AppData\Local\Programs\Python\Python311\Lib\site-packages\pandas\io\sql.py", line 1839, in read_query
    result = self.execute(sql, params)
             ^^^^^^^^^^^^^^^^^^^^^^^^^
  File "C:\Users\ABIE\AppData\Local\Programs\Python\Python311\Lib\site-packages\pandas\io\sql.py", line 1663, in execute
    return self.con.execute(sql, *args)
           ^^^^^^^^^^^^^^^^^^^^^^^^^^^^
  File "C:\Users\ABIE\AppData\Local\Programs\Python\Python311\Lib\site-packages\sqlalchemy\engine\base.py", line 1416, in execute
    return meth(
           ^^^^^
  File "C:\Users\ABIE\AppData\Local\Programs\Python\Python311\Lib\site-packages\sqlalchemy\sql\elements.py", line 517, in _execute_on_connection
    return connection._execute_clauseelement(
           ^^^^^^^^^^^^^^^^^^^^^^^^^^^^^^^^^^
  File "C:\Users\ABIE\AppData\Local\Programs\Python\Python311\Lib\site-packages\sqlalchemy\engine\base.py", line 1639, in _execute_clauseelement
    ret = self._execute_context(
          ^^^^^^^^^^^^^^^^^^^^^^
  File "C:\Users\ABIE\AppData\Local\Programs\Python\Python311\Lib\site-packages\sqlalchemy\engine\base.py", line 1848, in _execute_context
    return self._exec_single_context(
           ^^^^^^^^^^^^^^^^^^^^^^^^^^
  File "C:\Users\ABIE\AppData\Local\Programs\Python\Python311\Lib\site-packages\sqlalchemy\engine\base.py", line 1988, in _exec_single_context
    self._handle_dbapi_exception(
  File "C:\Users\ABIE\AppData\Local\Programs\Python\Python311\Lib\site-packages\sqlalchemy\engine\base.py", line 2344, in _handle_dbapi_exception
    raise sqlalchemy_exception.with_traceback(exc_info[2]) from e
  File "C:\Users\ABIE\AppData\Local\Programs\Python\Python311\Lib\site-packages\sqlalchemy\engine\base.py", line 1969, in _exec_single_context
    self.dialect.do_execute(
  File "C:\Users\ABIE\AppData\Local\Programs\Python\Python311\Lib\site-packages\sqlalchemy\engine\default.py", line 922, in do_execute
    cursor.execute(statement, parameters)
  File "C:\Users\ABIE\AppData\Local\Programs\Python\Python311\Lib\site-packages\oracledb\cursor.py", line 844, in execute
    impl.execute(self)
  File "src/oracledb/impl/thin/cursor.pyx", line 277, in oracledb.thin_impl.ThinCursorImpl.execute
  File "src/oracledb/impl/thin/protocol.pyx", line 501, in oracledb.thin_impl.Protocol._process_single_message
  File "src/oracledb/impl/thin/protocol.pyx", line 502, in oracledb.thin_impl.Protocol._process_single_message
  File "src/oracledb/impl/thin/protocol.pyx", line 494, in oracledb.thin_impl.Protocol._process_message
  File "src/oracledb/impl/thin/messages/base.pyx", line 102, in oracledb.thin_impl.Message._check_and_raise_exception
sqlalchemy.exc.DatabaseError: (oracledb.exceptions.DatabaseError) ORA-00942: table or view does not exist
Help: https://docs.oracle.com/error-help/db/ora-00942/
[SQL: SELECT * FROM AQ FETCH FIRST 100 ROWS ONLY]
(Background on this error at: https://sqlalche.me/e/20/4xp6)
2025-10-20 12:16:21 | INFO | dataiq | Disposed SQLAlchemy engine
2025-10-20 12:17:11 | INFO | dataiq | SQLAlchemy engine created
2025-10-20 12:17:11 | INFO | dataiq | Connected to Oracle database
2025-10-20 12:17:11 | INFO | dataiq | Connection test succeeded
2025-10-20 12:17:11 | INFO | dataiq | Connected to Oracle database
2025-10-20 12:17:11 | ERROR | dataiq | Main orchestration failed: (oracledb.exceptions.DatabaseError) ORA-00942: table or view does not exist
Help: https://docs.oracle.com/error-help/db/ora-00942/
[SQL: SELECT * FROM AQ FETCH FIRST 100 ROWS ONLY]
(Background on this error at: https://sqlalche.me/e/20/4xp6)
Traceback (most recent call last):
  File "C:\Users\ABIE\Desktop\DataIQ\.venv\Lib\site-packages\sqlalchemy\engine\base.py", line 1967, in _exec_single_context
    self.dialect.do_execute(
  File "C:\Users\ABIE\Desktop\DataIQ\.venv\Lib\site-packages\sqlalchemy\engine\default.py", line 951, in do_execute
    cursor.execute(statement, parameters)
  File "C:\Users\ABIE\Desktop\DataIQ\.venv\Lib\site-packages\oracledb\cursor.py", line 844, in execute
    impl.execute(self)
  File "src/oracledb/impl/thin/cursor.pyx", line 277, in oracledb.thin_impl.ThinCursorImpl.execute
  File "src/oracledb/impl/thin/protocol.pyx", line 501, in oracledb.thin_impl.Protocol._process_single_message
  File "src/oracledb/impl/thin/protocol.pyx", line 502, in oracledb.thin_impl.Protocol._process_single_message
  File "src/oracledb/impl/thin/protocol.pyx", line 494, in oracledb.thin_impl.Protocol._process_message
  File "src/oracledb/impl/thin/messages/base.pyx", line 102, in oracledb.thin_impl.Message._check_and_raise_exception
oracledb.exceptions.DatabaseError: ORA-00942: table or view does not exist
Help: https://docs.oracle.com/error-help/db/ora-00942/

The above exception was the direct cause of the following exception:

Traceback (most recent call last):
  File "C:\Users\ABIE\Desktop\DataIQ\main.py", line 81, in orchestrate
    result = run_profile(conn, table, limit)
             ^^^^^^^^^^^^^^^^^^^^^^^^^^^^^^^
  File "C:\Users\ABIE\Desktop\DataIQ\main.py", line 28, in run_profile
    df = conn.fetch_table_data(table_name=table, limit=limit)
         ^^^^^^^^^^^^^^^^^^^^^^^^^^^^^^^^^^^^^^^^^^^^^^^^^^^^
  File "C:\Users\ABIE\Desktop\DataIQ\dataiq\oracle_connector.py", line 231, in fetch_table_data
    return self.sample_table(table=table_name, schema=schema, rows=limit)
           ^^^^^^^^^^^^^^^^^^^^^^^^^^^^^^^^^^^^^^^^^^^^^^^^^^^^^^^^^^^^^^
  File "C:\Users\ABIE\Desktop\DataIQ\dataiq\oracle_connector.py", line 346, in sample_table
    df = pd.read_sql(text(q), conn)
         ^^^^^^^^^^^^^^^^^^^^^^^^^^
  File "C:\Users\ABIE\Desktop\DataIQ\.venv\Lib\site-packages\pandas\io\sql.py", line 736, in read_sql
    return pandas_sql.read_query(
           ^^^^^^^^^^^^^^^^^^^^^^
  File "C:\Users\ABIE\Desktop\DataIQ\.venv\Lib\site-packages\pandas\io\sql.py", line 1848, in read_query
    result = self.execute(sql, params)
             ^^^^^^^^^^^^^^^^^^^^^^^^^
  File "C:\Users\ABIE\Desktop\DataIQ\.venv\Lib\site-packages\pandas\io\sql.py", line 1672, in execute
    return self.con.execute(sql, *args)
           ^^^^^^^^^^^^^^^^^^^^^^^^^^^^
  File "C:\Users\ABIE\Desktop\DataIQ\.venv\Lib\site-packages\sqlalchemy\engine\base.py", line 1419, in execute
    return meth(
           ^^^^^
  File "C:\Users\ABIE\Desktop\DataIQ\.venv\Lib\site-packages\sqlalchemy\sql\elements.py", line 526, in _execute_on_connection
    return connection._execute_clauseelement(
           ^^^^^^^^^^^^^^^^^^^^^^^^^^^^^^^^^^
  File "C:\Users\ABIE\Desktop\DataIQ\.venv\Lib\site-packages\sqlalchemy\engine\base.py", line 1641, in _execute_clauseelement
    ret = self._execute_context(
          ^^^^^^^^^^^^^^^^^^^^^^
  File "C:\Users\ABIE\Desktop\DataIQ\.venv\Lib\site-packages\sqlalchemy\engine\base.py", line 1846, in _execute_context
    return self._exec_single_context(
           ^^^^^^^^^^^^^^^^^^^^^^^^^^
  File "C:\Users\ABIE\Desktop\DataIQ\.venv\Lib\site-packages\sqlalchemy\engine\base.py", line 1986, in _exec_single_context
    self._handle_dbapi_exception(
  File "C:\Users\ABIE\Desktop\DataIQ\.venv\Lib\site-packages\sqlalchemy\engine\base.py", line 2355, in _handle_dbapi_exception
    raise sqlalchemy_exception.with_traceback(exc_info[2]) from e
  File "C:\Users\ABIE\Desktop\DataIQ\.venv\Lib\site-packages\sqlalchemy\engine\base.py", line 1967, in _exec_single_context
    self.dialect.do_execute(
  File "C:\Users\ABIE\Desktop\DataIQ\.venv\Lib\site-packages\sqlalchemy\engine\default.py", line 951, in do_execute
    cursor.execute(statement, parameters)
  File "C:\Users\ABIE\Desktop\DataIQ\.venv\Lib\site-packages\oracledb\cursor.py", line 844, in execute
    impl.execute(self)
  File "src/oracledb/impl/thin/cursor.pyx", line 277, in oracledb.thin_impl.ThinCursorImpl.execute
  File "src/oracledb/impl/thin/protocol.pyx", line 501, in oracledb.thin_impl.Protocol._process_single_message
  File "src/oracledb/impl/thin/protocol.pyx", line 502, in oracledb.thin_impl.Protocol._process_single_message
  File "src/oracledb/impl/thin/protocol.pyx", line 494, in oracledb.thin_impl.Protocol._process_message
  File "src/oracledb/impl/thin/messages/base.pyx", line 102, in oracledb.thin_impl.Message._check_and_raise_exception
sqlalchemy.exc.DatabaseError: (oracledb.exceptions.DatabaseError) ORA-00942: table or view does not exist
Help: https://docs.oracle.com/error-help/db/ora-00942/
[SQL: SELECT * FROM AQ FETCH FIRST 100 ROWS ONLY]
(Background on this error at: https://sqlalche.me/e/20/4xp6)
Traceback (most recent call last):
  File "C:\Users\ABIE\Desktop\DataIQ\.venv\Lib\site-packages\sqlalchemy\engine\base.py", line 1967, in _exec_single_context
    self.dialect.do_execute(
  File "C:\Users\ABIE\Desktop\DataIQ\.venv\Lib\site-packages\sqlalchemy\engine\default.py", line 951, in do_execute
    cursor.execute(statement, parameters)
  File "C:\Users\ABIE\Desktop\DataIQ\.venv\Lib\site-packages\oracledb\cursor.py", line 844, in execute
    impl.execute(self)
  File "src/oracledb/impl/thin/cursor.pyx", line 277, in oracledb.thin_impl.ThinCursorImpl.execute
  File "src/oracledb/impl/thin/protocol.pyx", line 501, in oracledb.thin_impl.Protocol._process_single_message
  File "src/oracledb/impl/thin/protocol.pyx", line 502, in oracledb.thin_impl.Protocol._process_single_message
  File "src/oracledb/impl/thin/protocol.pyx", line 494, in oracledb.thin_impl.Protocol._process_message
  File "src/oracledb/impl/thin/messages/base.pyx", line 102, in oracledb.thin_impl.Message._check_and_raise_exception
oracledb.exceptions.DatabaseError: ORA-00942: table or view does not exist
Help: https://docs.oracle.com/error-help/db/ora-00942/

The above exception was the direct cause of the following exception:

Traceback (most recent call last):
  File "C:\Users\ABIE\Desktop\DataIQ\main.py", line 81, in orchestrate
    result = run_profile(conn, table, limit)
             ^^^^^^^^^^^^^^^^^^^^^^^^^^^^^^^
  File "C:\Users\ABIE\Desktop\DataIQ\main.py", line 28, in run_profile
    df = conn.fetch_table_data(table_name=table, limit=limit)
         ^^^^^^^^^^^^^^^^^^^^^^^^^^^^^^^^^^^^^^^^^^^^^^^^^^^^
  File "C:\Users\ABIE\Desktop\DataIQ\dataiq\oracle_connector.py", line 231, in fetch_table_data
    return self.sample_table(table=table_name, schema=schema, rows=limit)
           ^^^^^^^^^^^^^^^^^^^^^^^^^^^^^^^^^^^^^^^^^^^^^^^^^^^^^^^^^^^^^^
  File "C:\Users\ABIE\Desktop\DataIQ\dataiq\oracle_connector.py", line 346, in sample_table
    df = pd.read_sql(text(q), conn)
         ^^^^^^^^^^^^^^^^^^^^^^^^^^
  File "C:\Users\ABIE\Desktop\DataIQ\.venv\Lib\site-packages\pandas\io\sql.py", line 736, in read_sql
    return pandas_sql.read_query(
           ^^^^^^^^^^^^^^^^^^^^^^
  File "C:\Users\ABIE\Desktop\DataIQ\.venv\Lib\site-packages\pandas\io\sql.py", line 1848, in read_query
    result = self.execute(sql, params)
             ^^^^^^^^^^^^^^^^^^^^^^^^^
  File "C:\Users\ABIE\Desktop\DataIQ\.venv\Lib\site-packages\pandas\io\sql.py", line 1672, in execute
    return self.con.execute(sql, *args)
           ^^^^^^^^^^^^^^^^^^^^^^^^^^^^
  File "C:\Users\ABIE\Desktop\DataIQ\.venv\Lib\site-packages\sqlalchemy\engine\base.py", line 1419, in execute
    return meth(
           ^^^^^
  File "C:\Users\ABIE\Desktop\DataIQ\.venv\Lib\site-packages\sqlalchemy\sql\elements.py", line 526, in _execute_on_connection
    return connection._execute_clauseelement(
           ^^^^^^^^^^^^^^^^^^^^^^^^^^^^^^^^^^
  File "C:\Users\ABIE\Desktop\DataIQ\.venv\Lib\site-packages\sqlalchemy\engine\base.py", line 1641, in _execute_clauseelement
    ret = self._execute_context(
          ^^^^^^^^^^^^^^^^^^^^^^
  File "C:\Users\ABIE\Desktop\DataIQ\.venv\Lib\site-packages\sqlalchemy\engine\base.py", line 1846, in _execute_context
    return self._exec_single_context(
           ^^^^^^^^^^^^^^^^^^^^^^^^^^
  File "C:\Users\ABIE\Desktop\DataIQ\.venv\Lib\site-packages\sqlalchemy\engine\base.py", line 1986, in _exec_single_context
    self._handle_dbapi_exception(
  File "C:\Users\ABIE\Desktop\DataIQ\.venv\Lib\site-packages\sqlalchemy\engine\base.py", line 2355, in _handle_dbapi_exception
    raise sqlalchemy_exception.with_traceback(exc_info[2]) from e
  File "C:\Users\ABIE\Desktop\DataIQ\.venv\Lib\site-packages\sqlalchemy\engine\base.py", line 1967, in _exec_single_context
    self.dialect.do_execute(
  File "C:\Users\ABIE\Desktop\DataIQ\.venv\Lib\site-packages\sqlalchemy\engine\default.py", line 951, in do_execute
    cursor.execute(statement, parameters)
  File "C:\Users\ABIE\Desktop\DataIQ\.venv\Lib\site-packages\oracledb\cursor.py", line 844, in execute
    impl.execute(self)
  File "src/oracledb/impl/thin/cursor.pyx", line 277, in oracledb.thin_impl.ThinCursorImpl.execute
  File "src/oracledb/impl/thin/protocol.pyx", line 501, in oracledb.thin_impl.Protocol._process_single_message
  File "src/oracledb/impl/thin/protocol.pyx", line 502, in oracledb.thin_impl.Protocol._process_single_message
  File "src/oracledb/impl/thin/protocol.pyx", line 494, in oracledb.thin_impl.Protocol._process_message
  File "src/oracledb/impl/thin/messages/base.pyx", line 102, in oracledb.thin_impl.Message._check_and_raise_exception
sqlalchemy.exc.DatabaseError: (oracledb.exceptions.DatabaseError) ORA-00942: table or view does not exist
Help: https://docs.oracle.com/error-help/db/ora-00942/
[SQL: SELECT * FROM AQ FETCH FIRST 100 ROWS ONLY]
(Background on this error at: https://sqlalche.me/e/20/4xp6)
2025-10-20 12:17:11 | INFO | dataiq | Disposed SQLAlchemy engine
2025-10-20 12:17:30 | INFO | dataiq | Starting environment setup
2025-10-20 12:17:30 | INFO | dataiq | Checking Oracle connectivity...
2025-10-20 12:17:31 | INFO | dataiq | python-oracledb module imported successfully
2025-10-20 12:17:31 | INFO | dataiq | SQLAlchemy engine created
2025-10-20 12:17:31 | INFO | dataiq | Connected to Oracle database
2025-10-20 12:17:31 | INFO | dataiq | Connection test succeeded
2025-10-20 12:17:31 | INFO | dataiq | Oracle connection test passed
2025-10-20 12:17:31 | INFO | dataiq | Disposed SQLAlchemy engine
2025-10-20 12:17:31 | INFO | dataiq | Verifying folder structure...
2025-10-20 12:17:31 | INFO | dataiq | Folder structure verified
2025-10-20 12:17:31 | INFO | dataiq | Checking dependencies...
2025-10-20 12:17:31 | INFO | dataiq | All dependencies present
2025-10-20 12:17:31 | INFO | dataiq | Checking python-oracledb mode...
2025-10-20 12:17:31 | INFO | dataiq | python-oracledb version: 3.4.0
2025-10-20 12:17:31 | INFO | dataiq | python-oracledb running in thin mode
2025-10-20 12:17:31 | INFO | dataiq | Environment setup completed successfully
2025-10-20 12:17:39 | INFO | dataiq | Starting automated test suite
2025-10-20 12:17:39 | INFO | dataiq | Starting pytest test suite
2025-10-20 12:17:40 | INFO | dataiq | Removed 1 duplicate rows
2025-10-20 12:17:40 | INFO | dataiq | Filled NaNs in numeric column 'a' with mean 1.5000
2025-10-20 12:17:40 | INFO | dataiq | Filled NaNs in non-numeric column 'b' with mode/default
2025-10-20 12:17:40 | INFO | dataiq | Normalized string columns: ['b']
2025-10-20 12:17:40 | INFO | dataiq | Saved cleaned dataset: C:\Users\ABIE\AppData\Local\Temp\pytest-of-ABIE\pytest-0\test_clean_duplicates_and_null0\outputs\cleaned_data\cleaned_test.csv
2025-10-20 12:17:40 | ERROR | dataiq | Connection test failed: 'DummyConn' object does not support the context manager protocol
2025-10-20 12:17:40 | INFO | dataiq | Found 2 tables
2025-10-20 12:17:40 | INFO | dataiq | Starting profiling for test
2025-10-20 12:17:40 | INFO | dataiq | Profile saved: C:\Users\ABIE\AppData\Local\Temp\pytest-of-ABIE\pytest-0\test_profile_and_health_score0\outputs\profiles\profile_test.csv
2025-10-20 12:17:40 | INFO | dataiq | Computing data health score
2025-10-20 12:17:40 | INFO | dataiq | Data health score: 91.67
2025-10-20 12:17:40 | ERROR | dataiq | pytest tests failed
2025-10-20 12:17:40 | INFO | dataiq | Verifying Oracle connection
2025-10-20 12:17:40 | INFO | dataiq | SQLAlchemy engine created
2025-10-20 12:17:40 | INFO | dataiq | Connected to Oracle database
2025-10-20 12:17:40 | INFO | dataiq | Connection test succeeded
2025-10-20 12:17:40 | INFO | dataiq | Oracle connection verified
2025-10-20 12:17:40 | INFO | dataiq | Connected to Oracle database
2025-10-20 12:17:41 | INFO | dataiq | Connected to Oracle database
2025-10-20 12:17:41 | INFO | dataiq | Found 134 tables
2025-10-20 12:17:41 | INFO | dataiq | Found 134 tables
2025-10-20 12:17:41 | INFO | dataiq | Disposed SQLAlchemy engine
2025-10-20 12:17:41 | INFO | dataiq | SQLAlchemy engine created
2025-10-20 12:17:41 | INFO | dataiq | Connected to Oracle database
2025-10-20 12:17:41 | INFO | dataiq | Connected to Oracle database
2025-10-20 12:17:41 | INFO | dataiq | Found 134 tables
2025-10-20 12:17:41 | INFO | dataiq | Disposed SQLAlchemy engine
2025-10-20 12:17:41 | INFO | dataiq | Using table 'AQ$_INTERNET_AGENTS' for testing
2025-10-20 12:17:41 | INFO | dataiq | Executing main.py --mode profile
2025-10-20 12:17:42 | INFO | dataiq | SQLAlchemy engine created
2025-10-20 12:17:42 | INFO | dataiq | Connected to Oracle database
2025-10-20 12:17:42 | INFO | dataiq | Connection test succeeded
2025-10-20 12:17:42 | INFO | dataiq | Connected to Oracle database
2025-10-20 12:17:42 | INFO | dataiq | Sampled 6 rows from AQ$_INTERNET_AGENTS
2025-10-20 12:17:42 | INFO | dataiq | Starting profiling for AQ$_INTERNET_AGENTS
2025-10-20 12:17:43 | INFO | dataiq | Profile saved: outputs\profiles\profile_AQ$_INTERNET_AGENTS.csv
2025-10-20 12:17:43 | INFO | dataiq | Computing data health score
2025-10-20 12:17:43 | INFO | dataiq | Data health score: 83.33
2025-10-20 12:17:43 | INFO | dataiq | Disposed SQLAlchemy engine
2025-10-20 12:17:43 | INFO | dataiq | main.py --mode profile completed successfully
2025-10-20 12:17:43 | INFO | dataiq | Executing main.py --mode clean
2025-10-20 12:17:44 | INFO | dataiq | SQLAlchemy engine created
2025-10-20 12:17:44 | INFO | dataiq | Connected to Oracle database
2025-10-20 12:17:44 | INFO | dataiq | Connection test succeeded
2025-10-20 12:17:44 | INFO | dataiq | Connected to Oracle database
2025-10-20 12:17:44 | INFO | dataiq | Sampled 6 rows from AQ$_INTERNET_AGENTS
2025-10-20 12:17:44 | INFO | dataiq | Removed 0 duplicate rows
2025-10-20 12:17:44 | INFO | dataiq | Filled NaNs in non-numeric column 'spare1' with mode/default
2025-10-20 12:17:44 | INFO | dataiq | Normalized string columns: ['agent_name', 'spare1']
2025-10-20 12:17:44 | INFO | dataiq | Saved cleaned dataset: outputs\cleaned_data\cleaned_AQ$_INTERNET_AGENTS.csv
2025-10-20 12:17:44 | INFO | dataiq | Disposed SQLAlchemy engine
2025-10-20 12:17:45 | INFO | dataiq | main.py --mode clean completed successfully
2025-10-20 12:17:45 | INFO | dataiq | Executing main.py --mode detect
2025-10-20 12:17:46 | INFO | dataiq | SQLAlchemy engine created
2025-10-20 12:17:46 | INFO | dataiq | Connected to Oracle database
2025-10-20 12:17:46 | INFO | dataiq | Connection test succeeded
2025-10-20 12:17:46 | INFO | dataiq | Connected to Oracle database
2025-10-20 12:17:46 | INFO | dataiq | Sampled 6 rows from AQ$_INTERNET_AGENTS
2025-10-20 12:17:46 | INFO | dataiq | Starting anomaly detection
2025-10-20 12:17:47 | INFO | dataiq | Anomaly chart saved: dashboard\assets\charts\anomalies_per_column.png
2025-10-20 12:17:47 | INFO | dataiq | Disposed SQLAlchemy engine
2025-10-20 12:17:47 | INFO | dataiq | main.py --mode detect completed successfully
2025-10-20 12:17:47 | ERROR | dataiq | Test suite completed with failures
2025-10-20 12:18:22 | INFO | dataiq | SQLAlchemy engine created
2025-10-20 12:18:22 | INFO | dataiq | Connected to Oracle database
2025-10-20 12:18:22 | INFO | dataiq | Connection test succeeded
2025-10-20 12:18:22 | INFO | dataiq | Connected to Oracle database
2025-10-20 12:18:22 | ERROR | dataiq | Main orchestration failed: (oracledb.exceptions.DatabaseError) ORA-00942: table or view does not exist
Help: https://docs.oracle.com/error-help/db/ora-00942/
[SQL: SELECT * FROM YOUR_TABLE FETCH FIRST 1000 ROWS ONLY]
(Background on this error at: https://sqlalche.me/e/20/4xp6)
Traceback (most recent call last):
  File "C:\Users\ABIE\Desktop\DataIQ\.venv\Lib\site-packages\sqlalchemy\engine\base.py", line 1967, in _exec_single_context
    self.dialect.do_execute(
  File "C:\Users\ABIE\Desktop\DataIQ\.venv\Lib\site-packages\sqlalchemy\engine\default.py", line 951, in do_execute
    cursor.execute(statement, parameters)
  File "C:\Users\ABIE\Desktop\DataIQ\.venv\Lib\site-packages\oracledb\cursor.py", line 844, in execute
    impl.execute(self)
  File "src/oracledb/impl/thin/cursor.pyx", line 277, in oracledb.thin_impl.ThinCursorImpl.execute
  File "src/oracledb/impl/thin/protocol.pyx", line 501, in oracledb.thin_impl.Protocol._process_single_message
  File "src/oracledb/impl/thin/protocol.pyx", line 502, in oracledb.thin_impl.Protocol._process_single_message
  File "src/oracledb/impl/thin/protocol.pyx", line 494, in oracledb.thin_impl.Protocol._process_message
  File "src/oracledb/impl/thin/messages/base.pyx", line 102, in oracledb.thin_impl.Message._check_and_raise_exception
oracledb.exceptions.DatabaseError: ORA-00942: table or view does not exist
Help: https://docs.oracle.com/error-help/db/ora-00942/

The above exception was the direct cause of the following exception:

Traceback (most recent call last):
  File "C:\Users\ABIE\Desktop\DataIQ\main.py", line 81, in orchestrate
    result = run_profile(conn, table, limit)
             ^^^^^^^^^^^^^^^^^^^^^^^^^^^^^^^
  File "C:\Users\ABIE\Desktop\DataIQ\main.py", line 28, in run_profile
    df = conn.fetch_table_data(table_name=table, limit=limit)
         ^^^^^^^^^^^^^^^^^^^^^^^^^^^^^^^^^^^^^^^^^^^^^^^^^^^^
  File "C:\Users\ABIE\Desktop\DataIQ\dataiq\oracle_connector.py", line 231, in fetch_table_data
    return self.sample_table(table=table_name, schema=schema, rows=limit)
           ^^^^^^^^^^^^^^^^^^^^^^^^^^^^^^^^^^^^^^^^^^^^^^^^^^^^^^^^^^^^^^
  File "C:\Users\ABIE\Desktop\DataIQ\dataiq\oracle_connector.py", line 346, in sample_table
    df = pd.read_sql(text(q), conn)
         ^^^^^^^^^^^^^^^^^^^^^^^^^^
  File "C:\Users\ABIE\Desktop\DataIQ\.venv\Lib\site-packages\pandas\io\sql.py", line 736, in read_sql
    return pandas_sql.read_query(
           ^^^^^^^^^^^^^^^^^^^^^^
  File "C:\Users\ABIE\Desktop\DataIQ\.venv\Lib\site-packages\pandas\io\sql.py", line 1848, in read_query
    result = self.execute(sql, params)
             ^^^^^^^^^^^^^^^^^^^^^^^^^
  File "C:\Users\ABIE\Desktop\DataIQ\.venv\Lib\site-packages\pandas\io\sql.py", line 1672, in execute
    return self.con.execute(sql, *args)
           ^^^^^^^^^^^^^^^^^^^^^^^^^^^^
  File "C:\Users\ABIE\Desktop\DataIQ\.venv\Lib\site-packages\sqlalchemy\engine\base.py", line 1419, in execute
    return meth(
           ^^^^^
  File "C:\Users\ABIE\Desktop\DataIQ\.venv\Lib\site-packages\sqlalchemy\sql\elements.py", line 526, in _execute_on_connection
    return connection._execute_clauseelement(
           ^^^^^^^^^^^^^^^^^^^^^^^^^^^^^^^^^^
  File "C:\Users\ABIE\Desktop\DataIQ\.venv\Lib\site-packages\sqlalchemy\engine\base.py", line 1641, in _execute_clauseelement
    ret = self._execute_context(
          ^^^^^^^^^^^^^^^^^^^^^^
  File "C:\Users\ABIE\Desktop\DataIQ\.venv\Lib\site-packages\sqlalchemy\engine\base.py", line 1846, in _execute_context
    return self._exec_single_context(
           ^^^^^^^^^^^^^^^^^^^^^^^^^^
  File "C:\Users\ABIE\Desktop\DataIQ\.venv\Lib\site-packages\sqlalchemy\engine\base.py", line 1986, in _exec_single_context
    self._handle_dbapi_exception(
  File "C:\Users\ABIE\Desktop\DataIQ\.venv\Lib\site-packages\sqlalchemy\engine\base.py", line 2355, in _handle_dbapi_exception
    raise sqlalchemy_exception.with_traceback(exc_info[2]) from e
  File "C:\Users\ABIE\Desktop\DataIQ\.venv\Lib\site-packages\sqlalchemy\engine\base.py", line 1967, in _exec_single_context
    self.dialect.do_execute(
  File "C:\Users\ABIE\Desktop\DataIQ\.venv\Lib\site-packages\sqlalchemy\engine\default.py", line 951, in do_execute
    cursor.execute(statement, parameters)
  File "C:\Users\ABIE\Desktop\DataIQ\.venv\Lib\site-packages\oracledb\cursor.py", line 844, in execute
    impl.execute(self)
  File "src/oracledb/impl/thin/cursor.pyx", line 277, in oracledb.thin_impl.ThinCursorImpl.execute
  File "src/oracledb/impl/thin/protocol.pyx", line 501, in oracledb.thin_impl.Protocol._process_single_message
  File "src/oracledb/impl/thin/protocol.pyx", line 502, in oracledb.thin_impl.Protocol._process_single_message
  File "src/oracledb/impl/thin/protocol.pyx", line 494, in oracledb.thin_impl.Protocol._process_message
  File "src/oracledb/impl/thin/messages/base.pyx", line 102, in oracledb.thin_impl.Message._check_and_raise_exception
sqlalchemy.exc.DatabaseError: (oracledb.exceptions.DatabaseError) ORA-00942: table or view does not exist
Help: https://docs.oracle.com/error-help/db/ora-00942/
[SQL: SELECT * FROM YOUR_TABLE FETCH FIRST 1000 ROWS ONLY]
(Background on this error at: https://sqlalche.me/e/20/4xp6)
Traceback (most recent call last):
  File "C:\Users\ABIE\Desktop\DataIQ\.venv\Lib\site-packages\sqlalchemy\engine\base.py", line 1967, in _exec_single_context
    self.dialect.do_execute(
  File "C:\Users\ABIE\Desktop\DataIQ\.venv\Lib\site-packages\sqlalchemy\engine\default.py", line 951, in do_execute
    cursor.execute(statement, parameters)
  File "C:\Users\ABIE\Desktop\DataIQ\.venv\Lib\site-packages\oracledb\cursor.py", line 844, in execute
    impl.execute(self)
  File "src/oracledb/impl/thin/cursor.pyx", line 277, in oracledb.thin_impl.ThinCursorImpl.execute
  File "src/oracledb/impl/thin/protocol.pyx", line 501, in oracledb.thin_impl.Protocol._process_single_message
  File "src/oracledb/impl/thin/protocol.pyx", line 502, in oracledb.thin_impl.Protocol._process_single_message
  File "src/oracledb/impl/thin/protocol.pyx", line 494, in oracledb.thin_impl.Protocol._process_message
  File "src/oracledb/impl/thin/messages/base.pyx", line 102, in oracledb.thin_impl.Message._check_and_raise_exception
oracledb.exceptions.DatabaseError: ORA-00942: table or view does not exist
Help: https://docs.oracle.com/error-help/db/ora-00942/

The above exception was the direct cause of the following exception:

Traceback (most recent call last):
  File "C:\Users\ABIE\Desktop\DataIQ\main.py", line 81, in orchestrate
    result = run_profile(conn, table, limit)
             ^^^^^^^^^^^^^^^^^^^^^^^^^^^^^^^
  File "C:\Users\ABIE\Desktop\DataIQ\main.py", line 28, in run_profile
    df = conn.fetch_table_data(table_name=table, limit=limit)
         ^^^^^^^^^^^^^^^^^^^^^^^^^^^^^^^^^^^^^^^^^^^^^^^^^^^^
  File "C:\Users\ABIE\Desktop\DataIQ\dataiq\oracle_connector.py", line 231, in fetch_table_data
    return self.sample_table(table=table_name, schema=schema, rows=limit)
           ^^^^^^^^^^^^^^^^^^^^^^^^^^^^^^^^^^^^^^^^^^^^^^^^^^^^^^^^^^^^^^
  File "C:\Users\ABIE\Desktop\DataIQ\dataiq\oracle_connector.py", line 346, in sample_table
    df = pd.read_sql(text(q), conn)
         ^^^^^^^^^^^^^^^^^^^^^^^^^^
  File "C:\Users\ABIE\Desktop\DataIQ\.venv\Lib\site-packages\pandas\io\sql.py", line 736, in read_sql
    return pandas_sql.read_query(
           ^^^^^^^^^^^^^^^^^^^^^^
  File "C:\Users\ABIE\Desktop\DataIQ\.venv\Lib\site-packages\pandas\io\sql.py", line 1848, in read_query
    result = self.execute(sql, params)
             ^^^^^^^^^^^^^^^^^^^^^^^^^
  File "C:\Users\ABIE\Desktop\DataIQ\.venv\Lib\site-packages\pandas\io\sql.py", line 1672, in execute
    return self.con.execute(sql, *args)
           ^^^^^^^^^^^^^^^^^^^^^^^^^^^^
  File "C:\Users\ABIE\Desktop\DataIQ\.venv\Lib\site-packages\sqlalchemy\engine\base.py", line 1419, in execute
    return meth(
           ^^^^^
  File "C:\Users\ABIE\Desktop\DataIQ\.venv\Lib\site-packages\sqlalchemy\sql\elements.py", line 526, in _execute_on_connection
    return connection._execute_clauseelement(
           ^^^^^^^^^^^^^^^^^^^^^^^^^^^^^^^^^^
  File "C:\Users\ABIE\Desktop\DataIQ\.venv\Lib\site-packages\sqlalchemy\engine\base.py", line 1641, in _execute_clauseelement
    ret = self._execute_context(
          ^^^^^^^^^^^^^^^^^^^^^^
  File "C:\Users\ABIE\Desktop\DataIQ\.venv\Lib\site-packages\sqlalchemy\engine\base.py", line 1846, in _execute_context
    return self._exec_single_context(
           ^^^^^^^^^^^^^^^^^^^^^^^^^^
  File "C:\Users\ABIE\Desktop\DataIQ\.venv\Lib\site-packages\sqlalchemy\engine\base.py", line 1986, in _exec_single_context
    self._handle_dbapi_exception(
  File "C:\Users\ABIE\Desktop\DataIQ\.venv\Lib\site-packages\sqlalchemy\engine\base.py", line 2355, in _handle_dbapi_exception
    raise sqlalchemy_exception.with_traceback(exc_info[2]) from e
  File "C:\Users\ABIE\Desktop\DataIQ\.venv\Lib\site-packages\sqlalchemy\engine\base.py", line 1967, in _exec_single_context
    self.dialect.do_execute(
  File "C:\Users\ABIE\Desktop\DataIQ\.venv\Lib\site-packages\sqlalchemy\engine\default.py", line 951, in do_execute
    cursor.execute(statement, parameters)
  File "C:\Users\ABIE\Desktop\DataIQ\.venv\Lib\site-packages\oracledb\cursor.py", line 844, in execute
    impl.execute(self)
  File "src/oracledb/impl/thin/cursor.pyx", line 277, in oracledb.thin_impl.ThinCursorImpl.execute
  File "src/oracledb/impl/thin/protocol.pyx", line 501, in oracledb.thin_impl.Protocol._process_single_message
  File "src/oracledb/impl/thin/protocol.pyx", line 502, in oracledb.thin_impl.Protocol._process_single_message
  File "src/oracledb/impl/thin/protocol.pyx", line 494, in oracledb.thin_impl.Protocol._process_message
  File "src/oracledb/impl/thin/messages/base.pyx", line 102, in oracledb.thin_impl.Message._check_and_raise_exception
sqlalchemy.exc.DatabaseError: (oracledb.exceptions.DatabaseError) ORA-00942: table or view does not exist
Help: https://docs.oracle.com/error-help/db/ora-00942/
[SQL: SELECT * FROM YOUR_TABLE FETCH FIRST 1000 ROWS ONLY]
(Background on this error at: https://sqlalche.me/e/20/4xp6)
2025-10-20 12:18:22 | INFO | dataiq | Disposed SQLAlchemy engine
2025-10-20 12:18:46 | INFO | dataiq | SQLAlchemy engine created
2025-10-20 12:18:46 | INFO | dataiq | Connected to Oracle database
2025-10-20 12:18:46 | INFO | dataiq | Connection test succeeded
2025-10-20 12:18:46 | INFO | dataiq | Connected to Oracle database
2025-10-20 12:18:46 | INFO | dataiq | Sampled 6 rows from AQ$_INTERNET_AGENTS
2025-10-20 12:18:46 | INFO | dataiq | Starting profiling for AQ$_INTERNET_AGENTS
2025-10-20 12:18:46 | INFO | dataiq | Profile saved: outputs\profiles\profile_AQ$_INTERNET_AGENTS.csv
2025-10-20 12:18:46 | INFO | dataiq | Computing data health score
2025-10-20 12:18:46 | INFO | dataiq | Data health score: 83.33
2025-10-20 12:18:46 | INFO | dataiq | Disposed SQLAlchemy engine
2025-10-20 12:20:12 | INFO | dataiq | SQLAlchemy engine created
2025-10-20 12:20:12 | INFO | dataiq | Connected to Oracle database
2025-10-20 12:20:12 | INFO | dataiq | Connection test succeeded
2025-10-20 12:20:12 | INFO | dataiq | Connected to Oracle database
2025-10-20 12:20:12 | INFO | dataiq | Sampled 6 rows from AQ$_INTERNET_AGENTS
2025-10-20 12:20:12 | INFO | dataiq | Removed 0 duplicate rows
2025-10-20 12:20:12 | INFO | dataiq | Filled NaNs in non-numeric column 'spare1' with mode/default
2025-10-20 12:20:12 | INFO | dataiq | Normalized string columns: ['agent_name', 'spare1']
2025-10-20 12:20:12 | INFO | dataiq | Saved cleaned dataset: outputs\cleaned_data\cleaned_AQ$_INTERNET_AGENTS.csv
2025-10-20 12:20:12 | INFO | dataiq | Disposed SQLAlchemy engine
2025-10-20 12:36:22 | INFO | dataiq | SQLAlchemy engine created
2025-10-20 12:36:23 | INFO | dataiq | Connected to Oracle database
2025-10-20 12:36:23 | INFO | dataiq | Connection test succeeded
2025-10-20 12:36:23 | INFO | dataiq | Connected to Oracle database
2025-10-20 12:36:23 | INFO | dataiq | Sampled 50 rows from HELP
2025-10-20 12:36:23 | INFO | dataiq | Starting profiling for HELP
2025-10-20 12:36:23 | INFO | dataiq | Profile saved: outputs\profiles\profile_HELP.csv
2025-10-20 12:36:23 | INFO | dataiq | Computing data health score
2025-10-20 12:36:23 | INFO | dataiq | Data health score: 93.33
2025-10-20 12:36:23 | INFO | dataiq | Disposed SQLAlchemy engine
2025-10-20 12:36:37 | INFO | dataiq | SQLAlchemy engine created
2025-10-20 12:36:37 | INFO | dataiq | Connected to Oracle database
2025-10-20 12:36:37 | INFO | dataiq | Connection test succeeded
2025-10-20 12:36:37 | INFO | dataiq | Connected to Oracle database
2025-10-20 12:36:37 | INFO | dataiq | Sampled 50 rows from HELP
2025-10-20 12:36:37 | INFO | dataiq | Removed 0 duplicate rows
2025-10-20 12:36:37 | INFO | dataiq | Filled NaNs in non-numeric column 'info' with mode/default
2025-10-20 12:36:37 | INFO | dataiq | Normalized string columns: ['topic', 'info']
2025-10-20 12:36:37 | INFO | dataiq | Saved cleaned dataset: outputs\cleaned_data\cleaned_HELP.csv
2025-10-20 12:36:37 | INFO | dataiq | Disposed SQLAlchemy engine
2025-10-20 12:36:45 | INFO | dataiq | SQLAlchemy engine created
2025-10-20 12:36:45 | INFO | dataiq | Connected to Oracle database
2025-10-20 12:36:45 | INFO | dataiq | Connection test succeeded
2025-10-20 12:36:45 | INFO | dataiq | Connected to Oracle database
2025-10-20 12:36:45 | INFO | dataiq | Sampled 50 rows from HELP
2025-10-20 12:36:45 | INFO | dataiq | Starting anomaly detection
2025-10-20 12:36:45 | INFO | dataiq | Anomaly chart saved: dashboard\assets\charts\anomalies_per_column.png
2025-10-20 12:36:45 | INFO | dataiq | Disposed SQLAlchemy engine
2025-10-20 12:36:55 | INFO | dataiq | SQLAlchemy engine created
2025-10-20 12:36:55 | INFO | dataiq | Connected to Oracle database
2025-10-20 12:36:55 | INFO | dataiq | Connection test succeeded
2025-10-20 12:36:55 | INFO | dataiq | Connected to Oracle database
2025-10-20 12:36:55 | INFO | dataiq | Sampled 50 rows from HELP
2025-10-20 12:36:55 | INFO | dataiq | Starting profiling for HELP
2025-10-20 12:36:55 | INFO | dataiq | Profile saved: outputs\profiles\profile_HELP.csv
2025-10-20 12:36:55 | INFO | dataiq | Computing data health score
2025-10-20 12:36:55 | INFO | dataiq | Data health score: 93.33
2025-10-20 12:36:55 | INFO | dataiq | Starting anomaly detection
2025-10-20 12:36:56 | INFO | dataiq | Anomaly chart saved: dashboard\assets\charts\anomalies_per_column.png
2025-10-20 12:36:56 | ERROR | dataiq | Failed to generate reports: Not enough horizontal space to render a single character
Traceback (most recent call last):
  File "C:\Users\ABIE\Desktop\DataIQ\dataiq\report_generator.py", line 54, in generate_reports
    pdf_path = self._create_pdf(profiling_summary, health_score, anomaly_summary)
               ^^^^^^^^^^^^^^^^^^^^^^^^^^^^^^^^^^^^^^^^^^^^^^^^^^^^^^^^^^^^^^^^^^
  File "C:\Users\ABIE\Desktop\DataIQ\dataiq\report_generator.py", line 91, in _create_pdf
    pdf.multi_cell(0, 6, line)
  File "C:\Users\ABIE\Desktop\DataIQ\.venv\Lib\site-packages\fpdf\fpdf.py", line 221, in wrapper
    return fn(self, *args, **kwargs)
           ^^^^^^^^^^^^^^^^^^^^^^^^^
  File "C:\Users\ABIE\Desktop\DataIQ\.venv\Lib\site-packages\fpdf\deprecation.py", line 32, in wrapper
    return fn(self, *args, **kwargs)
           ^^^^^^^^^^^^^^^^^^^^^^^^^
  File "C:\Users\ABIE\Desktop\DataIQ\.venv\Lib\site-packages\fpdf\fpdf.py", line 4208, in multi_cell
    text_line = multi_line_break.get_line()
                ^^^^^^^^^^^^^^^^^^^^^^^^^^^
  File "C:\Users\ABIE\Desktop\DataIQ\.venv\Lib\site-packages\fpdf\line_break.py", line 794, in get_line
    raise FPDFException(
fpdf.errors.FPDFException: Not enough horizontal space to render a single character
2025-10-20 12:36:56 | ERROR | dataiq | Main orchestration failed: Not enough horizontal space to render a single character
Traceback (most recent call last):
  File "C:\Users\ABIE\Desktop\DataIQ\main.py", line 91, in orchestrate
    result = run_report(prof["profile"], prof["score"], run_detect(prof["df"]))
             ^^^^^^^^^^^^^^^^^^^^^^^^^^^^^^^^^^^^^^^^^^^^^^^^^^^^^^^^^^^^^^^^^^
  File "C:\Users\ABIE\Desktop\DataIQ\main.py", line 58, in run_report
    paths = generator.generate_reports(profile, score, anomalies)
            ^^^^^^^^^^^^^^^^^^^^^^^^^^^^^^^^^^^^^^^^^^^^^^^^^^^^^
  File "C:\Users\ABIE\Desktop\DataIQ\dataiq\report_generator.py", line 54, in generate_reports
    pdf_path = self._create_pdf(profiling_summary, health_score, anomaly_summary)
               ^^^^^^^^^^^^^^^^^^^^^^^^^^^^^^^^^^^^^^^^^^^^^^^^^^^^^^^^^^^^^^^^^^
  File "C:\Users\ABIE\Desktop\DataIQ\dataiq\report_generator.py", line 91, in _create_pdf
    pdf.multi_cell(0, 6, line)
  File "C:\Users\ABIE\Desktop\DataIQ\.venv\Lib\site-packages\fpdf\fpdf.py", line 221, in wrapper
    return fn(self, *args, **kwargs)
           ^^^^^^^^^^^^^^^^^^^^^^^^^
  File "C:\Users\ABIE\Desktop\DataIQ\.venv\Lib\site-packages\fpdf\deprecation.py", line 32, in wrapper
    return fn(self, *args, **kwargs)
           ^^^^^^^^^^^^^^^^^^^^^^^^^
  File "C:\Users\ABIE\Desktop\DataIQ\.venv\Lib\site-packages\fpdf\fpdf.py", line 4208, in multi_cell
    text_line = multi_line_break.get_line()
                ^^^^^^^^^^^^^^^^^^^^^^^^^^^
  File "C:\Users\ABIE\Desktop\DataIQ\.venv\Lib\site-packages\fpdf\line_break.py", line 794, in get_line
    raise FPDFException(
fpdf.errors.FPDFException: Not enough horizontal space to render a single character
Traceback (most recent call last):
  File "C:\Users\ABIE\Desktop\DataIQ\main.py", line 91, in orchestrate
    result = run_report(prof["profile"], prof["score"], run_detect(prof["df"]))
             ^^^^^^^^^^^^^^^^^^^^^^^^^^^^^^^^^^^^^^^^^^^^^^^^^^^^^^^^^^^^^^^^^^
  File "C:\Users\ABIE\Desktop\DataIQ\main.py", line 58, in run_report
    paths = generator.generate_reports(profile, score, anomalies)
            ^^^^^^^^^^^^^^^^^^^^^^^^^^^^^^^^^^^^^^^^^^^^^^^^^^^^^
  File "C:\Users\ABIE\Desktop\DataIQ\dataiq\report_generator.py", line 54, in generate_reports
    pdf_path = self._create_pdf(profiling_summary, health_score, anomaly_summary)
               ^^^^^^^^^^^^^^^^^^^^^^^^^^^^^^^^^^^^^^^^^^^^^^^^^^^^^^^^^^^^^^^^^^
  File "C:\Users\ABIE\Desktop\DataIQ\dataiq\report_generator.py", line 91, in _create_pdf
    pdf.multi_cell(0, 6, line)
  File "C:\Users\ABIE\Desktop\DataIQ\.venv\Lib\site-packages\fpdf\fpdf.py", line 221, in wrapper
    return fn(self, *args, **kwargs)
           ^^^^^^^^^^^^^^^^^^^^^^^^^
  File "C:\Users\ABIE\Desktop\DataIQ\.venv\Lib\site-packages\fpdf\deprecation.py", line 32, in wrapper
    return fn(self, *args, **kwargs)
           ^^^^^^^^^^^^^^^^^^^^^^^^^
  File "C:\Users\ABIE\Desktop\DataIQ\.venv\Lib\site-packages\fpdf\fpdf.py", line 4208, in multi_cell
    text_line = multi_line_break.get_line()
                ^^^^^^^^^^^^^^^^^^^^^^^^^^^
  File "C:\Users\ABIE\Desktop\DataIQ\.venv\Lib\site-packages\fpdf\line_break.py", line 794, in get_line
    raise FPDFException(
fpdf.errors.FPDFException: Not enough horizontal space to render a single character
2025-10-20 12:36:56 | INFO | dataiq | Disposed SQLAlchemy engine
2025-10-20 12:37:09 | INFO | dataiq | Removed 1 duplicate rows
2025-10-20 12:37:09 | INFO | dataiq | Filled NaNs in numeric column 'a' with mean 1.5000
2025-10-20 12:37:09 | INFO | dataiq | Filled NaNs in non-numeric column 'b' with mode/default
2025-10-20 12:37:09 | INFO | dataiq | Normalized string columns: ['b']
2025-10-20 12:37:09 | INFO | dataiq | Saved cleaned dataset: C:\Users\ABIE\AppData\Local\Temp\pytest-of-ABIE\pytest-1\test_clean_duplicates_and_null0\outputs\cleaned_data\cleaned_test.csv
2025-10-20 12:37:09 | ERROR | dataiq | Connection test failed: 'DummyConn' object does not support the context manager protocol
2025-10-20 12:37:09 | INFO | dataiq | Found 2 tables
2025-10-20 12:37:09 | INFO | dataiq | Starting profiling for test
2025-10-20 12:37:09 | INFO | dataiq | Profile saved: C:\Users\ABIE\AppData\Local\Temp\pytest-of-ABIE\pytest-1\test_profile_and_health_score0\outputs\profiles\profile_test.csv
2025-10-20 12:37:09 | INFO | dataiq | Computing data health score
2025-10-20 12:37:09 | INFO | dataiq | Data health score: 91.67
2025-10-20 12:38:23 | INFO | dataiq | Connection test succeeded
2025-10-20 12:38:23 | INFO | dataiq | Found 2 tables
2025-10-20 12:38:31 | INFO | dataiq | SQLAlchemy engine created
2025-10-20 12:38:31 | INFO | dataiq | Connected to Oracle database
2025-10-20 12:38:31 | INFO | dataiq | Connection test succeeded
2025-10-20 12:38:31 | INFO | dataiq | Connected to Oracle database
2025-10-20 12:38:31 | INFO | dataiq | Sampled 50 rows from HELP
2025-10-20 12:38:31 | INFO | dataiq | Starting profiling for HELP
2025-10-20 12:38:31 | INFO | dataiq | Profile saved: outputs\profiles\profile_HELP.csv
2025-10-20 12:38:31 | INFO | dataiq | Computing data health score
2025-10-20 12:38:31 | INFO | dataiq | Data health score: 93.33
2025-10-20 12:38:31 | INFO | dataiq | Starting anomaly detection
2025-10-20 12:38:32 | INFO | dataiq | Anomaly chart saved: dashboard\assets\charts\anomalies_per_column.png
2025-10-20 12:38:32 | ERROR | dataiq | Failed to generate reports: Not enough horizontal space to render a single character
Traceback (most recent call last):
  File "C:\Users\ABIE\Desktop\DataIQ\dataiq\report_generator.py", line 54, in generate_reports
    pdf_path = self._create_pdf(profiling_summary, health_score, anomaly_summary)
               ^^^^^^^^^^^^^^^^^^^^^^^^^^^^^^^^^^^^^^^^^^^^^^^^^^^^^^^^^^^^^^^^^^
  File "C:\Users\ABIE\Desktop\DataIQ\dataiq\report_generator.py", line 100, in _create_pdf
    pdf.multi_cell(0, 5, line[:180])  # Truncate to 180 chars max
    ^^^^^^^^^^^^^^^^^^^^^^^^^^^^^^^^
  File "C:\Users\ABIE\Desktop\DataIQ\.venv\Lib\site-packages\fpdf\fpdf.py", line 221, in wrapper
    return fn(self, *args, **kwargs)
           ^^^^^^^^^^^^^^^^^^^^^^^^^
  File "C:\Users\ABIE\Desktop\DataIQ\.venv\Lib\site-packages\fpdf\deprecation.py", line 32, in wrapper
    return fn(self, *args, **kwargs)
           ^^^^^^^^^^^^^^^^^^^^^^^^^
  File "C:\Users\ABIE\Desktop\DataIQ\.venv\Lib\site-packages\fpdf\fpdf.py", line 4208, in multi_cell
    text_line = multi_line_break.get_line()
                ^^^^^^^^^^^^^^^^^^^^^^^^^^^
  File "C:\Users\ABIE\Desktop\DataIQ\.venv\Lib\site-packages\fpdf\line_break.py", line 794, in get_line
    raise FPDFException(
fpdf.errors.FPDFException: Not enough horizontal space to render a single character
2025-10-20 12:38:32 | ERROR | dataiq | Main orchestration failed: Not enough horizontal space to render a single character
Traceback (most recent call last):
  File "C:\Users\ABIE\Desktop\DataIQ\main.py", line 91, in orchestrate
    result = run_report(prof["profile"], prof["score"], run_detect(prof["df"]))
             ^^^^^^^^^^^^^^^^^^^^^^^^^^^^^^^^^^^^^^^^^^^^^^^^^^^^^^^^^^^^^^^^^^
  File "C:\Users\ABIE\Desktop\DataIQ\main.py", line 58, in run_report
    paths = generator.generate_reports(profile, score, anomalies)
            ^^^^^^^^^^^^^^^^^^^^^^^^^^^^^^^^^^^^^^^^^^^^^^^^^^^^^
  File "C:\Users\ABIE\Desktop\DataIQ\dataiq\report_generator.py", line 54, in generate_reports
    pdf_path = self._create_pdf(profiling_summary, health_score, anomaly_summary)
               ^^^^^^^^^^^^^^^^^^^^^^^^^^^^^^^^^^^^^^^^^^^^^^^^^^^^^^^^^^^^^^^^^^
  File "C:\Users\ABIE\Desktop\DataIQ\dataiq\report_generator.py", line 100, in _create_pdf
    pdf.multi_cell(0, 5, line[:180])  # Truncate to 180 chars max
    ^^^^^^^^^^^^^^^^^^^^^^^^^^^^^^^^
  File "C:\Users\ABIE\Desktop\DataIQ\.venv\Lib\site-packages\fpdf\fpdf.py", line 221, in wrapper
    return fn(self, *args, **kwargs)
           ^^^^^^^^^^^^^^^^^^^^^^^^^
  File "C:\Users\ABIE\Desktop\DataIQ\.venv\Lib\site-packages\fpdf\deprecation.py", line 32, in wrapper
    return fn(self, *args, **kwargs)
           ^^^^^^^^^^^^^^^^^^^^^^^^^
  File "C:\Users\ABIE\Desktop\DataIQ\.venv\Lib\site-packages\fpdf\fpdf.py", line 4208, in multi_cell
    text_line = multi_line_break.get_line()
                ^^^^^^^^^^^^^^^^^^^^^^^^^^^
  File "C:\Users\ABIE\Desktop\DataIQ\.venv\Lib\site-packages\fpdf\line_break.py", line 794, in get_line
    raise FPDFException(
fpdf.errors.FPDFException: Not enough horizontal space to render a single character
Traceback (most recent call last):
  File "C:\Users\ABIE\Desktop\DataIQ\main.py", line 91, in orchestrate
    result = run_report(prof["profile"], prof["score"], run_detect(prof["df"]))
             ^^^^^^^^^^^^^^^^^^^^^^^^^^^^^^^^^^^^^^^^^^^^^^^^^^^^^^^^^^^^^^^^^^
  File "C:\Users\ABIE\Desktop\DataIQ\main.py", line 58, in run_report
    paths = generator.generate_reports(profile, score, anomalies)
            ^^^^^^^^^^^^^^^^^^^^^^^^^^^^^^^^^^^^^^^^^^^^^^^^^^^^^
  File "C:\Users\ABIE\Desktop\DataIQ\dataiq\report_generator.py", line 54, in generate_reports
    pdf_path = self._create_pdf(profiling_summary, health_score, anomaly_summary)
               ^^^^^^^^^^^^^^^^^^^^^^^^^^^^^^^^^^^^^^^^^^^^^^^^^^^^^^^^^^^^^^^^^^
  File "C:\Users\ABIE\Desktop\DataIQ\dataiq\report_generator.py", line 100, in _create_pdf
    pdf.multi_cell(0, 5, line[:180])  # Truncate to 180 chars max
    ^^^^^^^^^^^^^^^^^^^^^^^^^^^^^^^^
  File "C:\Users\ABIE\Desktop\DataIQ\.venv\Lib\site-packages\fpdf\fpdf.py", line 221, in wrapper
    return fn(self, *args, **kwargs)
           ^^^^^^^^^^^^^^^^^^^^^^^^^
  File "C:\Users\ABIE\Desktop\DataIQ\.venv\Lib\site-packages\fpdf\deprecation.py", line 32, in wrapper
    return fn(self, *args, **kwargs)
           ^^^^^^^^^^^^^^^^^^^^^^^^^
  File "C:\Users\ABIE\Desktop\DataIQ\.venv\Lib\site-packages\fpdf\fpdf.py", line 4208, in multi_cell
    text_line = multi_line_break.get_line()
                ^^^^^^^^^^^^^^^^^^^^^^^^^^^
  File "C:\Users\ABIE\Desktop\DataIQ\.venv\Lib\site-packages\fpdf\line_break.py", line 794, in get_line
    raise FPDFException(
fpdf.errors.FPDFException: Not enough horizontal space to render a single character
2025-10-20 12:38:32 | INFO | dataiq | Disposed SQLAlchemy engine
2025-10-20 12:39:17 | INFO | dataiq | SQLAlchemy engine created
2025-10-20 12:39:17 | INFO | dataiq | Connected to Oracle database
2025-10-20 12:39:17 | INFO | dataiq | Connection test succeeded
2025-10-20 12:39:17 | INFO | dataiq | Connected to Oracle database
2025-10-20 12:39:17 | INFO | dataiq | Sampled 50 rows from HELP
2025-10-20 12:39:17 | INFO | dataiq | Starting profiling for HELP
2025-10-20 12:39:17 | INFO | dataiq | Profile saved: outputs\profiles\profile_HELP.csv
2025-10-20 12:39:17 | INFO | dataiq | Computing data health score
2025-10-20 12:39:17 | INFO | dataiq | Data health score: 93.33
2025-10-20 12:39:17 | INFO | dataiq | Starting anomaly detection
2025-10-20 12:39:17 | INFO | dataiq | Anomaly chart saved: dashboard\assets\charts\anomalies_per_column.png
2025-10-20 12:39:17 | INFO | dataiq | Reports generated: PDF=outputs\reports\dataiq_report_20251020_123917.pdf, HTML=outputs\reports\dataiq_report_20251020_123917.html
2025-10-20 12:39:17 | INFO | dataiq | Disposed SQLAlchemy engine
2025-10-20 12:42:50 | INFO | dataiq | Removed 1 duplicate rows
2025-10-20 12:42:50 | INFO | dataiq | Filled NaNs in numeric column 'a' with mean 1.5000
2025-10-20 12:42:50 | INFO | dataiq | Filled NaNs in non-numeric column 'b' with mode/default
2025-10-20 12:42:50 | INFO | dataiq | Normalized string columns: ['b']
2025-10-20 12:42:50 | INFO | dataiq | Saved cleaned dataset: C:\Users\ABIE\AppData\Local\Temp\pytest-of-ABIE\pytest-2\test_clean_duplicates_and_null0\outputs\cleaned_data\cleaned_test.csv
2025-10-20 12:42:50 | INFO | dataiq | Connection test succeeded
2025-10-20 12:42:50 | INFO | dataiq | Found 2 tables
2025-10-20 12:42:50 | INFO | dataiq | Starting profiling for test
2025-10-20 12:42:50 | INFO | dataiq | Profile saved: C:\Users\ABIE\AppData\Local\Temp\pytest-of-ABIE\pytest-2\test_profile_and_health_score0\outputs\profiles\profile_test.csv
2025-10-20 12:42:50 | INFO | dataiq | Computing data health score
2025-10-20 12:42:50 | INFO | dataiq | Data health score: 91.67
2025-10-20 12:42:59 | INFO | dataiq | SQLAlchemy engine created
2025-10-20 12:42:59 | INFO | dataiq | Connected to Oracle database
2025-10-20 12:42:59 | INFO | dataiq | Connection test succeeded
2025-10-20 12:42:59 | INFO | dataiq | Connected to Oracle database
2025-10-20 12:42:59 | INFO | dataiq | Sampled 30 rows from HELP
2025-10-20 12:42:59 | INFO | dataiq | Starting profiling for HELP
2025-10-20 12:42:59 | INFO | dataiq | Profile saved: outputs\profiles\profile_HELP.csv
2025-10-20 12:42:59 | INFO | dataiq | Computing data health score
2025-10-20 12:42:59 | INFO | dataiq | Data health score: 93.89
2025-10-20 12:42:59 | INFO | dataiq | Removed 0 duplicate rows
2025-10-20 12:42:59 | INFO | dataiq | Filled NaNs in non-numeric column 'info' with mode/default
2025-10-20 12:42:59 | INFO | dataiq | Normalized string columns: ['topic', 'info']
2025-10-20 12:42:59 | INFO | dataiq | Saved cleaned dataset: outputs\cleaned_data\cleaned_HELP.csv
2025-10-20 12:42:59 | INFO | dataiq | Starting anomaly detection
2025-10-20 12:42:59 | INFO | dataiq | Anomaly chart saved: dashboard\assets\charts\anomalies_per_column.png
2025-10-20 12:42:59 | INFO | dataiq | Reports generated: PDF=outputs\reports\dataiq_report_20251020_124259.pdf, HTML=outputs\reports\dataiq_report_20251020_124259.html
2025-10-20 12:42:59 | INFO | dataiq | Disposed SQLAlchemy engine
2025-10-20 12:46:45 | INFO | dataiq | SQLAlchemy engine created
2025-10-20 12:46:45 | INFO | dataiq | Connected to Oracle database
2025-10-20 12:46:45 | INFO | dataiq | Connection test succeeded
2025-10-20 12:46:45 | INFO | dataiq | Connected to Oracle database
2025-10-20 12:46:45 | INFO | dataiq | Sampled 978 rows from HELP
2025-10-20 12:46:45 | INFO | dataiq | Starting profiling for HELP
2025-10-20 12:46:45 | INFO | dataiq | Profile saved: outputs\profiles\profile_HELP.csv
2025-10-20 12:46:45 | INFO | dataiq | Computing data health score
2025-10-20 12:46:45 | INFO | dataiq | Data health score: 95.13
2025-10-20 12:46:45 | INFO | dataiq | Disposed SQLAlchemy engine
2025-10-20 12:46:55 | INFO | dataiq | SQLAlchemy engine created
2025-10-20 12:46:55 | INFO | dataiq | Connected to Oracle database
2025-10-20 12:46:55 | INFO | dataiq | Connection test succeeded
2025-10-20 12:46:55 | INFO | dataiq | Connected to Oracle database
2025-10-20 12:46:55 | INFO | dataiq | Sampled 978 rows from HELP
2025-10-20 12:46:55 | INFO | dataiq | Removed 0 duplicate rows
2025-10-20 12:46:55 | INFO | dataiq | Filled NaNs in non-numeric column 'info' with mode/default
2025-10-20 12:46:55 | INFO | dataiq | Normalized string columns: ['topic', 'info']
2025-10-20 12:46:55 | INFO | dataiq | Saved cleaned dataset: outputs\cleaned_data\cleaned_HELP.csv
2025-10-20 12:46:55 | INFO | dataiq | Disposed SQLAlchemy engine
2025-10-20 12:47:21 | INFO | dataiq | SQLAlchemy engine created
2025-10-20 12:47:21 | INFO | dataiq | Connected to Oracle database
2025-10-20 12:47:21 | INFO | dataiq | Connection test succeeded
2025-10-20 12:47:21 | INFO | dataiq | Connected to Oracle database
2025-10-20 12:47:21 | INFO | dataiq | Sampled 6 rows from AQ$_INTERNET_AGENTS
2025-10-20 12:47:21 | INFO | dataiq | Starting profiling for AQ$_INTERNET_AGENTS
2025-10-20 12:47:21 | INFO | dataiq | Profile saved: outputs\profiles\profile_AQ$_INTERNET_AGENTS.csv
2025-10-20 12:47:21 | INFO | dataiq | Computing data health score
2025-10-20 12:47:21 | INFO | dataiq | Data health score: 83.33
2025-10-20 12:47:21 | INFO | dataiq | Disposed SQLAlchemy engine
2025-10-20 12:47:26 | INFO | dataiq | SQLAlchemy engine created
2025-10-20 12:47:27 | INFO | dataiq | Connected to Oracle database
2025-10-20 12:47:27 | INFO | dataiq | Connection test succeeded
2025-10-20 12:47:27 | INFO | dataiq | Connected to Oracle database
2025-10-20 12:47:27 | INFO | dataiq | Sampled 6 rows from AQ$_INTERNET_AGENTS
2025-10-20 12:47:27 | INFO | dataiq | Removed 0 duplicate rows
2025-10-20 12:47:27 | INFO | dataiq | Filled NaNs in non-numeric column 'spare1' with mode/default
2025-10-20 12:47:27 | INFO | dataiq | Normalized string columns: ['agent_name', 'spare1']
2025-10-20 12:47:27 | INFO | dataiq | Saved cleaned dataset: outputs\cleaned_data\cleaned_AQ$_INTERNET_AGENTS.csv
2025-10-20 12:47:27 | INFO | dataiq | Disposed SQLAlchemy engine
2025-10-20 12:47:34 | INFO | dataiq | SQLAlchemy engine created
2025-10-20 12:47:34 | INFO | dataiq | Connected to Oracle database
2025-10-20 12:47:34 | INFO | dataiq | Connection test succeeded
2025-10-20 12:47:34 | INFO | dataiq | Connected to Oracle database
2025-10-20 12:47:34 | INFO | dataiq | Sampled 6 rows from AQ$_INTERNET_AGENTS
2025-10-20 12:47:34 | INFO | dataiq | Starting profiling for AQ$_INTERNET_AGENTS
2025-10-20 12:47:34 | INFO | dataiq | Profile saved: outputs\profiles\profile_AQ$_INTERNET_AGENTS.csv
2025-10-20 12:47:34 | INFO | dataiq | Computing data health score
2025-10-20 12:47:34 | INFO | dataiq | Data health score: 83.33
2025-10-20 12:47:34 | INFO | dataiq | Disposed SQLAlchemy engine
2025-10-21 10:20:10 | INFO | dataiq | Starting profiling for test_data
2025-10-21 10:20:10 | INFO | dataiq | Profile saved: outputs\profiles\profile_test_data.csv
2025-10-21 10:20:10 | INFO | dataiq | Computing data health score
2025-10-21 10:20:10 | INFO | dataiq | Data health score: 98.33
2025-10-21 10:20:57 | INFO | dataiq | Starting profiling for test_data
2025-10-21 10:20:57 | INFO | dataiq | Profile saved: outputs\profiles\profile_test_data.csv
2025-10-21 10:20:57 | INFO | dataiq | Computing data health score
2025-10-21 10:20:57 | INFO | dataiq | Data health score: 98.33
2025-10-21 10:20:57 | INFO | dataiq | Removed 0 duplicate rows
2025-10-21 10:20:57 | INFO | dataiq | Filled NaNs in numeric column 'salary' with mean 66814.8148
2025-10-21 10:20:57 | INFO | dataiq | Filled NaNs in numeric column 'age' with mean 32.7857
2025-10-21 10:20:57 | INFO | dataiq | Filled NaNs in numeric column 'performance_score' with mean 87.2759
2025-10-21 10:20:57 | INFO | dataiq | Filled NaNs in non-numeric column 'email' with mode/default
2025-10-21 10:20:57 | INFO | dataiq | Normalized string columns: ['name', 'department', 'hire_date', 'email']
2025-10-21 10:20:57 | INFO | dataiq | Starting anomaly detection
2025-10-21 10:20:58 | INFO | dataiq | Anomaly chart saved: dashboard\assets\charts\anomalies_per_column.png
2025-10-21 10:21:54 | INFO | dataiq | SQLAlchemy engine created
2025-10-21 10:21:54 | ERROR | dataiq | Failed to connect to Oracle: (oracledb.exceptions.OperationalError) DPY-6005: cannot connect to database (CONNECTION_ID=RduRNkWwyv28Wo0YPzeq1w==).
DPY-6001: Service "XEPDB1" is not registered with the listener at host "127.0.0.1" port 1521. (Similar to ORA-12514)
(Background on this error at: https://sqlalche.me/e/20/e3q8)
Traceback (most recent call last):
  File "src/oracledb/impl/thin/connection.pyx", line 414, in oracledb.thin_impl.ThinConnImpl._connect_with_address
  File "src/oracledb/impl/thin/protocol.pyx", line 288, in oracledb.thin_impl.Protocol._connect_phase_one
  File "src/oracledb/impl/thin/protocol.pyx", line 470, in oracledb.thin_impl.Protocol._process_message
  File "src/oracledb/impl/thin/protocol.pyx", line 446, in oracledb.thin_impl.Protocol._process_message
  File "src/oracledb/impl/thin/messages/connect.pyx", line 95, in oracledb.thin_impl.ConnectMessage.process
  File "C:\Users\ABIE\AppData\Local\Programs\Python\Python311\Lib\site-packages\oracledb\errors.py", line 199, in _raise_err
    raise error.exc_type(error) from cause
oracledb.exceptions.OperationalError: DPY-6001: Service "XEPDB1" is not registered with the listener at host "127.0.0.1" port 1521. (Similar to ORA-12514)

The above exception was the direct cause of the following exception:

Traceback (most recent call last):
  File "C:\Users\ABIE\AppData\Local\Programs\Python\Python311\Lib\site-packages\sqlalchemy\engine\base.py", line 145, in __init__
    self._dbapi_connection = engine.raw_connection()
                             ^^^^^^^^^^^^^^^^^^^^^^^
  File "C:\Users\ABIE\AppData\Local\Programs\Python\Python311\Lib\site-packages\sqlalchemy\engine\base.py", line 3293, in raw_connection
    return self.pool.connect()
           ^^^^^^^^^^^^^^^^^^^
  File "C:\Users\ABIE\AppData\Local\Programs\Python\Python311\Lib\site-packages\sqlalchemy\pool\base.py", line 452, in connect
    return _ConnectionFairy._checkout(self)
           ^^^^^^^^^^^^^^^^^^^^^^^^^^^^^^^^
  File "C:\Users\ABIE\AppData\Local\Programs\Python\Python311\Lib\site-packages\sqlalchemy\pool\base.py", line 1269, in _checkout
    fairy = _ConnectionRecord.checkout(pool)
            ^^^^^^^^^^^^^^^^^^^^^^^^^^^^^^^^
  File "C:\Users\ABIE\AppData\Local\Programs\Python\Python311\Lib\site-packages\sqlalchemy\pool\base.py", line 716, in checkout
    rec = pool._do_get()
          ^^^^^^^^^^^^^^
  File "C:\Users\ABIE\AppData\Local\Programs\Python\Python311\Lib\site-packages\sqlalchemy\pool\impl.py", line 169, in _do_get
    with util.safe_reraise():
  File "C:\Users\ABIE\AppData\Local\Programs\Python\Python311\Lib\site-packages\sqlalchemy\util\langhelpers.py", line 146, in __exit__
    raise exc_value.with_traceback(exc_tb)
  File "C:\Users\ABIE\AppData\Local\Programs\Python\Python311\Lib\site-packages\sqlalchemy\pool\impl.py", line 167, in _do_get
    return self._create_connection()
           ^^^^^^^^^^^^^^^^^^^^^^^^^
  File "C:\Users\ABIE\AppData\Local\Programs\Python\Python311\Lib\site-packages\sqlalchemy\pool\base.py", line 393, in _create_connection
    return _ConnectionRecord(self)
           ^^^^^^^^^^^^^^^^^^^^^^^
  File "C:\Users\ABIE\AppData\Local\Programs\Python\Python311\Lib\site-packages\sqlalchemy\pool\base.py", line 678, in __init__
    self.__connect()
  File "C:\Users\ABIE\AppData\Local\Programs\Python\Python311\Lib\site-packages\sqlalchemy\pool\base.py", line 902, in __connect
    with util.safe_reraise():
  File "C:\Users\ABIE\AppData\Local\Programs\Python\Python311\Lib\site-packages\sqlalchemy\util\langhelpers.py", line 146, in __exit__
    raise exc_value.with_traceback(exc_tb)
  File "C:\Users\ABIE\AppData\Local\Programs\Python\Python311\Lib\site-packages\sqlalchemy\pool\base.py", line 898, in __connect
    self.dbapi_connection = connection = pool._invoke_creator(self)
                                         ^^^^^^^^^^^^^^^^^^^^^^^^^^
  File "C:\Users\ABIE\AppData\Local\Programs\Python\Python311\Lib\site-packages\sqlalchemy\engine\create.py", line 645, in connect
    return dialect.connect(*cargs, **cparams)
           ^^^^^^^^^^^^^^^^^^^^^^^^^^^^^^^^^^
  File "C:\Users\ABIE\AppData\Local\Programs\Python\Python311\Lib\site-packages\sqlalchemy\engine\default.py", line 616, in connect
    return self.loaded_dbapi.connect(*cargs, **cparams)
           ^^^^^^^^^^^^^^^^^^^^^^^^^^^^^^^^^^^^^^^^^^^^
  File "C:\Users\ABIE\AppData\Local\Programs\Python\Python311\Lib\site-packages\oracledb\connection.py", line 1698, in connect
    return conn_class(dsn=dsn, pool=pool, params=params, **kwargs)
           ^^^^^^^^^^^^^^^^^^^^^^^^^^^^^^^^^^^^^^^^^^^^^^^^^^^^^^^
  File "C:\Users\ABIE\AppData\Local\Programs\Python\Python311\Lib\site-packages\oracledb\connection.py", line 892, in __init__
    impl.connect(params_impl)
  File "src/oracledb/impl/thin/connection.pyx", line 536, in oracledb.thin_impl.ThinConnImpl.connect
  File "src/oracledb/impl/thin/connection.pyx", line 532, in oracledb.thin_impl.ThinConnImpl.connect
  File "src/oracledb/impl/thin/connection.pyx", line 475, in oracledb.thin_impl.ThinConnImpl._connect_with_params
  File "src/oracledb/impl/thin/connection.pyx", line 456, in oracledb.thin_impl.ThinConnImpl._connect_with_description
  File "src/oracledb/impl/thin/connection.pyx", line 418, in oracledb.thin_impl.ThinConnImpl._connect_with_address
  File "C:\Users\ABIE\AppData\Local\Programs\Python\Python311\Lib\site-packages\oracledb\errors.py", line 199, in _raise_err
    raise error.exc_type(error) from cause
oracledb.exceptions.OperationalError: DPY-6005: cannot connect to database (CONNECTION_ID=RduRNkWwyv28Wo0YPzeq1w==).
DPY-6001: Service "XEPDB1" is not registered with the listener at host "127.0.0.1" port 1521. (Similar to ORA-12514)

The above exception was the direct cause of the following exception:

Traceback (most recent call last):
  File "C:\Users\ABIE\Desktop\DataIQ\dataiq\oracle_connector.py", line 200, in connect
    conn = engine.connect()
           ^^^^^^^^^^^^^^^^
  File "C:\Users\ABIE\AppData\Local\Programs\Python\Python311\Lib\site-packages\sqlalchemy\engine\base.py", line 3269, in connect
    return self._connection_cls(self)
           ^^^^^^^^^^^^^^^^^^^^^^^^^^
  File "C:\Users\ABIE\AppData\Local\Programs\Python\Python311\Lib\site-packages\sqlalchemy\engine\base.py", line 147, in __init__
    Connection._handle_dbapi_exception_noconnection(
  File "C:\Users\ABIE\AppData\Local\Programs\Python\Python311\Lib\site-packages\sqlalchemy\engine\base.py", line 2431, in _handle_dbapi_exception_noconnection
    raise sqlalchemy_exception.with_traceback(exc_info[2]) from e
  File "C:\Users\ABIE\AppData\Local\Programs\Python\Python311\Lib\site-packages\sqlalchemy\engine\base.py", line 145, in __init__
    self._dbapi_connection = engine.raw_connection()
                             ^^^^^^^^^^^^^^^^^^^^^^^
  File "C:\Users\ABIE\AppData\Local\Programs\Python\Python311\Lib\site-packages\sqlalchemy\engine\base.py", line 3293, in raw_connection
    return self.pool.connect()
           ^^^^^^^^^^^^^^^^^^^
  File "C:\Users\ABIE\AppData\Local\Programs\Python\Python311\Lib\site-packages\sqlalchemy\pool\base.py", line 452, in connect
    return _ConnectionFairy._checkout(self)
           ^^^^^^^^^^^^^^^^^^^^^^^^^^^^^^^^
  File "C:\Users\ABIE\AppData\Local\Programs\Python\Python311\Lib\site-packages\sqlalchemy\pool\base.py", line 1269, in _checkout
    fairy = _ConnectionRecord.checkout(pool)
            ^^^^^^^^^^^^^^^^^^^^^^^^^^^^^^^^
  File "C:\Users\ABIE\AppData\Local\Programs\Python\Python311\Lib\site-packages\sqlalchemy\pool\base.py", line 716, in checkout
    rec = pool._do_get()
          ^^^^^^^^^^^^^^
  File "C:\Users\ABIE\AppData\Local\Programs\Python\Python311\Lib\site-packages\sqlalchemy\pool\impl.py", line 169, in _do_get
    with util.safe_reraise():
  File "C:\Users\ABIE\AppData\Local\Programs\Python\Python311\Lib\site-packages\sqlalchemy\util\langhelpers.py", line 146, in __exit__
    raise exc_value.with_traceback(exc_tb)
  File "C:\Users\ABIE\AppData\Local\Programs\Python\Python311\Lib\site-packages\sqlalchemy\pool\impl.py", line 167, in _do_get
    return self._create_connection()
           ^^^^^^^^^^^^^^^^^^^^^^^^^
  File "C:\Users\ABIE\AppData\Local\Programs\Python\Python311\Lib\site-packages\sqlalchemy\pool\base.py", line 393, in _create_connection
    return _ConnectionRecord(self)
           ^^^^^^^^^^^^^^^^^^^^^^^
  File "C:\Users\ABIE\AppData\Local\Programs\Python\Python311\Lib\site-packages\sqlalchemy\pool\base.py", line 678, in __init__
    self.__connect()
  File "C:\Users\ABIE\AppData\Local\Programs\Python\Python311\Lib\site-packages\sqlalchemy\pool\base.py", line 902, in __connect
    with util.safe_reraise():
  File "C:\Users\ABIE\AppData\Local\Programs\Python\Python311\Lib\site-packages\sqlalchemy\util\langhelpers.py", line 146, in __exit__
    raise exc_value.with_traceback(exc_tb)
  File "C:\Users\ABIE\AppData\Local\Programs\Python\Python311\Lib\site-packages\sqlalchemy\pool\base.py", line 898, in __connect
    self.dbapi_connection = connection = pool._invoke_creator(self)
                                         ^^^^^^^^^^^^^^^^^^^^^^^^^^
  File "C:\Users\ABIE\AppData\Local\Programs\Python\Python311\Lib\site-packages\sqlalchemy\engine\create.py", line 645, in connect
    return dialect.connect(*cargs, **cparams)
           ^^^^^^^^^^^^^^^^^^^^^^^^^^^^^^^^^^
  File "C:\Users\ABIE\AppData\Local\Programs\Python\Python311\Lib\site-packages\sqlalchemy\engine\default.py", line 616, in connect
    return self.loaded_dbapi.connect(*cargs, **cparams)
           ^^^^^^^^^^^^^^^^^^^^^^^^^^^^^^^^^^^^^^^^^^^^
  File "C:\Users\ABIE\AppData\Local\Programs\Python\Python311\Lib\site-packages\oracledb\connection.py", line 1698, in connect
    return conn_class(dsn=dsn, pool=pool, params=params, **kwargs)
           ^^^^^^^^^^^^^^^^^^^^^^^^^^^^^^^^^^^^^^^^^^^^^^^^^^^^^^^
  File "C:\Users\ABIE\AppData\Local\Programs\Python\Python311\Lib\site-packages\oracledb\connection.py", line 892, in __init__
    impl.connect(params_impl)
  File "src/oracledb/impl/thin/connection.pyx", line 536, in oracledb.thin_impl.ThinConnImpl.connect
  File "src/oracledb/impl/thin/connection.pyx", line 532, in oracledb.thin_impl.ThinConnImpl.connect
  File "src/oracledb/impl/thin/connection.pyx", line 475, in oracledb.thin_impl.ThinConnImpl._connect_with_params
  File "src/oracledb/impl/thin/connection.pyx", line 456, in oracledb.thin_impl.ThinConnImpl._connect_with_description
  File "src/oracledb/impl/thin/connection.pyx", line 418, in oracledb.thin_impl.ThinConnImpl._connect_with_address
  File "C:\Users\ABIE\AppData\Local\Programs\Python\Python311\Lib\site-packages\oracledb\errors.py", line 199, in _raise_err
    raise error.exc_type(error) from cause
sqlalchemy.exc.OperationalError: (oracledb.exceptions.OperationalError) DPY-6005: cannot connect to database (CONNECTION_ID=RduRNkWwyv28Wo0YPzeq1w==).
DPY-6001: Service "XEPDB1" is not registered with the listener at host "127.0.0.1" port 1521. (Similar to ORA-12514)
(Background on this error at: https://sqlalche.me/e/20/e3q8)
2025-10-21 10:21:54 | ERROR | dataiq | Connection test failed: (oracledb.exceptions.OperationalError) DPY-6005: cannot connect to database (CONNECTION_ID=RduRNkWwyv28Wo0YPzeq1w==).
DPY-6001: Service "XEPDB1" is not registered with the listener at host "127.0.0.1" port 1521. (Similar to ORA-12514)
(Background on this error at: https://sqlalche.me/e/20/e3q8)
2025-10-21 10:21:54 | INFO | dataiq | Disposed SQLAlchemy engine
2025-10-21 10:22:59 | INFO | dataiq | SQLAlchemy engine created
2025-10-21 10:22:59 | ERROR | dataiq | Failed to connect to Oracle: (oracledb.exceptions.OperationalError) DPY-6005: cannot connect to database (CONNECTION_ID=p3rbKvu/RvRDjRjTMGxtjw==).
DPY-6001: Service "XEPDB1" is not registered with the listener at host "127.0.0.1" port 1521. (Similar to ORA-12514)
(Background on this error at: https://sqlalche.me/e/20/e3q8)
Traceback (most recent call last):
  File "src/oracledb/impl/thin/connection.pyx", line 414, in oracledb.thin_impl.ThinConnImpl._connect_with_address
  File "src/oracledb/impl/thin/protocol.pyx", line 288, in oracledb.thin_impl.Protocol._connect_phase_one
  File "src/oracledb/impl/thin/protocol.pyx", line 470, in oracledb.thin_impl.Protocol._process_message
  File "src/oracledb/impl/thin/protocol.pyx", line 446, in oracledb.thin_impl.Protocol._process_message
  File "src/oracledb/impl/thin/messages/connect.pyx", line 95, in oracledb.thin_impl.ConnectMessage.process
  File "C:\Users\ABIE\AppData\Local\Programs\Python\Python311\Lib\site-packages\oracledb\errors.py", line 199, in _raise_err
    raise error.exc_type(error) from cause
oracledb.exceptions.OperationalError: DPY-6001: Service "XEPDB1" is not registered with the listener at host "127.0.0.1" port 1521. (Similar to ORA-12514)

The above exception was the direct cause of the following exception:

Traceback (most recent call last):
  File "C:\Users\ABIE\AppData\Local\Programs\Python\Python311\Lib\site-packages\sqlalchemy\engine\base.py", line 145, in __init__
    self._dbapi_connection = engine.raw_connection()
                             ^^^^^^^^^^^^^^^^^^^^^^^
  File "C:\Users\ABIE\AppData\Local\Programs\Python\Python311\Lib\site-packages\sqlalchemy\engine\base.py", line 3293, in raw_connection
    return self.pool.connect()
           ^^^^^^^^^^^^^^^^^^^
  File "C:\Users\ABIE\AppData\Local\Programs\Python\Python311\Lib\site-packages\sqlalchemy\pool\base.py", line 452, in connect
    return _ConnectionFairy._checkout(self)
           ^^^^^^^^^^^^^^^^^^^^^^^^^^^^^^^^
  File "C:\Users\ABIE\AppData\Local\Programs\Python\Python311\Lib\site-packages\sqlalchemy\pool\base.py", line 1269, in _checkout
    fairy = _ConnectionRecord.checkout(pool)
            ^^^^^^^^^^^^^^^^^^^^^^^^^^^^^^^^
  File "C:\Users\ABIE\AppData\Local\Programs\Python\Python311\Lib\site-packages\sqlalchemy\pool\base.py", line 716, in checkout
    rec = pool._do_get()
          ^^^^^^^^^^^^^^
  File "C:\Users\ABIE\AppData\Local\Programs\Python\Python311\Lib\site-packages\sqlalchemy\pool\impl.py", line 169, in _do_get
    with util.safe_reraise():
  File "C:\Users\ABIE\AppData\Local\Programs\Python\Python311\Lib\site-packages\sqlalchemy\util\langhelpers.py", line 146, in __exit__
    raise exc_value.with_traceback(exc_tb)
  File "C:\Users\ABIE\AppData\Local\Programs\Python\Python311\Lib\site-packages\sqlalchemy\pool\impl.py", line 167, in _do_get
    return self._create_connection()
           ^^^^^^^^^^^^^^^^^^^^^^^^^
  File "C:\Users\ABIE\AppData\Local\Programs\Python\Python311\Lib\site-packages\sqlalchemy\pool\base.py", line 393, in _create_connection
    return _ConnectionRecord(self)
           ^^^^^^^^^^^^^^^^^^^^^^^
  File "C:\Users\ABIE\AppData\Local\Programs\Python\Python311\Lib\site-packages\sqlalchemy\pool\base.py", line 678, in __init__
    self.__connect()
  File "C:\Users\ABIE\AppData\Local\Programs\Python\Python311\Lib\site-packages\sqlalchemy\pool\base.py", line 902, in __connect
    with util.safe_reraise():
  File "C:\Users\ABIE\AppData\Local\Programs\Python\Python311\Lib\site-packages\sqlalchemy\util\langhelpers.py", line 146, in __exit__
    raise exc_value.with_traceback(exc_tb)
  File "C:\Users\ABIE\AppData\Local\Programs\Python\Python311\Lib\site-packages\sqlalchemy\pool\base.py", line 898, in __connect
    self.dbapi_connection = connection = pool._invoke_creator(self)
                                         ^^^^^^^^^^^^^^^^^^^^^^^^^^
  File "C:\Users\ABIE\AppData\Local\Programs\Python\Python311\Lib\site-packages\sqlalchemy\engine\create.py", line 645, in connect
    return dialect.connect(*cargs, **cparams)
           ^^^^^^^^^^^^^^^^^^^^^^^^^^^^^^^^^^
  File "C:\Users\ABIE\AppData\Local\Programs\Python\Python311\Lib\site-packages\sqlalchemy\engine\default.py", line 616, in connect
    return self.loaded_dbapi.connect(*cargs, **cparams)
           ^^^^^^^^^^^^^^^^^^^^^^^^^^^^^^^^^^^^^^^^^^^^
  File "C:\Users\ABIE\AppData\Local\Programs\Python\Python311\Lib\site-packages\oracledb\connection.py", line 1698, in connect
    return conn_class(dsn=dsn, pool=pool, params=params, **kwargs)
           ^^^^^^^^^^^^^^^^^^^^^^^^^^^^^^^^^^^^^^^^^^^^^^^^^^^^^^^
  File "C:\Users\ABIE\AppData\Local\Programs\Python\Python311\Lib\site-packages\oracledb\connection.py", line 892, in __init__
    impl.connect(params_impl)
  File "src/oracledb/impl/thin/connection.pyx", line 536, in oracledb.thin_impl.ThinConnImpl.connect
  File "src/oracledb/impl/thin/connection.pyx", line 532, in oracledb.thin_impl.ThinConnImpl.connect
  File "src/oracledb/impl/thin/connection.pyx", line 475, in oracledb.thin_impl.ThinConnImpl._connect_with_params
  File "src/oracledb/impl/thin/connection.pyx", line 456, in oracledb.thin_impl.ThinConnImpl._connect_with_description
  File "src/oracledb/impl/thin/connection.pyx", line 418, in oracledb.thin_impl.ThinConnImpl._connect_with_address
  File "C:\Users\ABIE\AppData\Local\Programs\Python\Python311\Lib\site-packages\oracledb\errors.py", line 199, in _raise_err
    raise error.exc_type(error) from cause
oracledb.exceptions.OperationalError: DPY-6005: cannot connect to database (CONNECTION_ID=p3rbKvu/RvRDjRjTMGxtjw==).
DPY-6001: Service "XEPDB1" is not registered with the listener at host "127.0.0.1" port 1521. (Similar to ORA-12514)

The above exception was the direct cause of the following exception:

Traceback (most recent call last):
  File "C:\Users\ABIE\Desktop\DataIQ\dataiq\oracle_connector.py", line 200, in connect
    conn = engine.connect()
           ^^^^^^^^^^^^^^^^
  File "C:\Users\ABIE\AppData\Local\Programs\Python\Python311\Lib\site-packages\sqlalchemy\engine\base.py", line 3269, in connect
    return self._connection_cls(self)
           ^^^^^^^^^^^^^^^^^^^^^^^^^^
  File "C:\Users\ABIE\AppData\Local\Programs\Python\Python311\Lib\site-packages\sqlalchemy\engine\base.py", line 147, in __init__
    Connection._handle_dbapi_exception_noconnection(
  File "C:\Users\ABIE\AppData\Local\Programs\Python\Python311\Lib\site-packages\sqlalchemy\engine\base.py", line 2431, in _handle_dbapi_exception_noconnection
    raise sqlalchemy_exception.with_traceback(exc_info[2]) from e
  File "C:\Users\ABIE\AppData\Local\Programs\Python\Python311\Lib\site-packages\sqlalchemy\engine\base.py", line 145, in __init__
    self._dbapi_connection = engine.raw_connection()
                             ^^^^^^^^^^^^^^^^^^^^^^^
  File "C:\Users\ABIE\AppData\Local\Programs\Python\Python311\Lib\site-packages\sqlalchemy\engine\base.py", line 3293, in raw_connection
    return self.pool.connect()
           ^^^^^^^^^^^^^^^^^^^
  File "C:\Users\ABIE\AppData\Local\Programs\Python\Python311\Lib\site-packages\sqlalchemy\pool\base.py", line 452, in connect
    return _ConnectionFairy._checkout(self)
           ^^^^^^^^^^^^^^^^^^^^^^^^^^^^^^^^
  File "C:\Users\ABIE\AppData\Local\Programs\Python\Python311\Lib\site-packages\sqlalchemy\pool\base.py", line 1269, in _checkout
    fairy = _ConnectionRecord.checkout(pool)
            ^^^^^^^^^^^^^^^^^^^^^^^^^^^^^^^^
  File "C:\Users\ABIE\AppData\Local\Programs\Python\Python311\Lib\site-packages\sqlalchemy\pool\base.py", line 716, in checkout
    rec = pool._do_get()
          ^^^^^^^^^^^^^^
  File "C:\Users\ABIE\AppData\Local\Programs\Python\Python311\Lib\site-packages\sqlalchemy\pool\impl.py", line 169, in _do_get
    with util.safe_reraise():
  File "C:\Users\ABIE\AppData\Local\Programs\Python\Python311\Lib\site-packages\sqlalchemy\util\langhelpers.py", line 146, in __exit__
    raise exc_value.with_traceback(exc_tb)
  File "C:\Users\ABIE\AppData\Local\Programs\Python\Python311\Lib\site-packages\sqlalchemy\pool\impl.py", line 167, in _do_get
    return self._create_connection()
           ^^^^^^^^^^^^^^^^^^^^^^^^^
  File "C:\Users\ABIE\AppData\Local\Programs\Python\Python311\Lib\site-packages\sqlalchemy\pool\base.py", line 393, in _create_connection
    return _ConnectionRecord(self)
           ^^^^^^^^^^^^^^^^^^^^^^^
  File "C:\Users\ABIE\AppData\Local\Programs\Python\Python311\Lib\site-packages\sqlalchemy\pool\base.py", line 678, in __init__
    self.__connect()
  File "C:\Users\ABIE\AppData\Local\Programs\Python\Python311\Lib\site-packages\sqlalchemy\pool\base.py", line 902, in __connect
    with util.safe_reraise():
  File "C:\Users\ABIE\AppData\Local\Programs\Python\Python311\Lib\site-packages\sqlalchemy\util\langhelpers.py", line 146, in __exit__
    raise exc_value.with_traceback(exc_tb)
  File "C:\Users\ABIE\AppData\Local\Programs\Python\Python311\Lib\site-packages\sqlalchemy\pool\base.py", line 898, in __connect
    self.dbapi_connection = connection = pool._invoke_creator(self)
                                         ^^^^^^^^^^^^^^^^^^^^^^^^^^
  File "C:\Users\ABIE\AppData\Local\Programs\Python\Python311\Lib\site-packages\sqlalchemy\engine\create.py", line 645, in connect
    return dialect.connect(*cargs, **cparams)
           ^^^^^^^^^^^^^^^^^^^^^^^^^^^^^^^^^^
  File "C:\Users\ABIE\AppData\Local\Programs\Python\Python311\Lib\site-packages\sqlalchemy\engine\default.py", line 616, in connect
    return self.loaded_dbapi.connect(*cargs, **cparams)
           ^^^^^^^^^^^^^^^^^^^^^^^^^^^^^^^^^^^^^^^^^^^^
  File "C:\Users\ABIE\AppData\Local\Programs\Python\Python311\Lib\site-packages\oracledb\connection.py", line 1698, in connect
    return conn_class(dsn=dsn, pool=pool, params=params, **kwargs)
           ^^^^^^^^^^^^^^^^^^^^^^^^^^^^^^^^^^^^^^^^^^^^^^^^^^^^^^^
  File "C:\Users\ABIE\AppData\Local\Programs\Python\Python311\Lib\site-packages\oracledb\connection.py", line 892, in __init__
    impl.connect(params_impl)
  File "src/oracledb/impl/thin/connection.pyx", line 536, in oracledb.thin_impl.ThinConnImpl.connect
  File "src/oracledb/impl/thin/connection.pyx", line 532, in oracledb.thin_impl.ThinConnImpl.connect
  File "src/oracledb/impl/thin/connection.pyx", line 475, in oracledb.thin_impl.ThinConnImpl._connect_with_params
  File "src/oracledb/impl/thin/connection.pyx", line 456, in oracledb.thin_impl.ThinConnImpl._connect_with_description
  File "src/oracledb/impl/thin/connection.pyx", line 418, in oracledb.thin_impl.ThinConnImpl._connect_with_address
  File "C:\Users\ABIE\AppData\Local\Programs\Python\Python311\Lib\site-packages\oracledb\errors.py", line 199, in _raise_err
    raise error.exc_type(error) from cause
sqlalchemy.exc.OperationalError: (oracledb.exceptions.OperationalError) DPY-6005: cannot connect to database (CONNECTION_ID=p3rbKvu/RvRDjRjTMGxtjw==).
DPY-6001: Service "XEPDB1" is not registered with the listener at host "127.0.0.1" port 1521. (Similar to ORA-12514)
(Background on this error at: https://sqlalche.me/e/20/e3q8)
2025-10-21 10:22:59 | ERROR | dataiq | Connection test failed: (oracledb.exceptions.OperationalError) DPY-6005: cannot connect to database (CONNECTION_ID=p3rbKvu/RvRDjRjTMGxtjw==).
DPY-6001: Service "XEPDB1" is not registered with the listener at host "127.0.0.1" port 1521. (Similar to ORA-12514)
(Background on this error at: https://sqlalche.me/e/20/e3q8)
2025-10-21 10:22:59 | INFO | dataiq | Disposed SQLAlchemy engine
2025-10-21 10:23:20 | INFO | dataiq | SQLAlchemy engine created
2025-10-21 10:23:20 | ERROR | dataiq | Failed to connect to Oracle: (oracledb.exceptions.OperationalError) DPY-6005: cannot connect to database (CONNECTION_ID=SqioWWDVzme0OPxXDaIVHw==).
DPY-6001: Service "XEPDB1" is not registered with the listener at host "127.0.0.1" port 1521. (Similar to ORA-12514)
(Background on this error at: https://sqlalche.me/e/20/e3q8)
Traceback (most recent call last):
  File "src/oracledb/impl/thin/connection.pyx", line 414, in oracledb.thin_impl.ThinConnImpl._connect_with_address
  File "src/oracledb/impl/thin/protocol.pyx", line 288, in oracledb.thin_impl.Protocol._connect_phase_one
  File "src/oracledb/impl/thin/protocol.pyx", line 470, in oracledb.thin_impl.Protocol._process_message
  File "src/oracledb/impl/thin/protocol.pyx", line 446, in oracledb.thin_impl.Protocol._process_message
  File "src/oracledb/impl/thin/messages/connect.pyx", line 95, in oracledb.thin_impl.ConnectMessage.process
  File "C:\Users\ABIE\AppData\Local\Programs\Python\Python311\Lib\site-packages\oracledb\errors.py", line 199, in _raise_err
    raise error.exc_type(error) from cause
oracledb.exceptions.OperationalError: DPY-6001: Service "XEPDB1" is not registered with the listener at host "127.0.0.1" port 1521. (Similar to ORA-12514)

The above exception was the direct cause of the following exception:

Traceback (most recent call last):
  File "C:\Users\ABIE\AppData\Local\Programs\Python\Python311\Lib\site-packages\sqlalchemy\engine\base.py", line 145, in __init__
    self._dbapi_connection = engine.raw_connection()
                             ^^^^^^^^^^^^^^^^^^^^^^^
  File "C:\Users\ABIE\AppData\Local\Programs\Python\Python311\Lib\site-packages\sqlalchemy\engine\base.py", line 3293, in raw_connection
    return self.pool.connect()
           ^^^^^^^^^^^^^^^^^^^
  File "C:\Users\ABIE\AppData\Local\Programs\Python\Python311\Lib\site-packages\sqlalchemy\pool\base.py", line 452, in connect
    return _ConnectionFairy._checkout(self)
           ^^^^^^^^^^^^^^^^^^^^^^^^^^^^^^^^
  File "C:\Users\ABIE\AppData\Local\Programs\Python\Python311\Lib\site-packages\sqlalchemy\pool\base.py", line 1269, in _checkout
    fairy = _ConnectionRecord.checkout(pool)
            ^^^^^^^^^^^^^^^^^^^^^^^^^^^^^^^^
  File "C:\Users\ABIE\AppData\Local\Programs\Python\Python311\Lib\site-packages\sqlalchemy\pool\base.py", line 716, in checkout
    rec = pool._do_get()
          ^^^^^^^^^^^^^^
  File "C:\Users\ABIE\AppData\Local\Programs\Python\Python311\Lib\site-packages\sqlalchemy\pool\impl.py", line 169, in _do_get
    with util.safe_reraise():
  File "C:\Users\ABIE\AppData\Local\Programs\Python\Python311\Lib\site-packages\sqlalchemy\util\langhelpers.py", line 146, in __exit__
    raise exc_value.with_traceback(exc_tb)
  File "C:\Users\ABIE\AppData\Local\Programs\Python\Python311\Lib\site-packages\sqlalchemy\pool\impl.py", line 167, in _do_get
    return self._create_connection()
           ^^^^^^^^^^^^^^^^^^^^^^^^^
  File "C:\Users\ABIE\AppData\Local\Programs\Python\Python311\Lib\site-packages\sqlalchemy\pool\base.py", line 393, in _create_connection
    return _ConnectionRecord(self)
           ^^^^^^^^^^^^^^^^^^^^^^^
  File "C:\Users\ABIE\AppData\Local\Programs\Python\Python311\Lib\site-packages\sqlalchemy\pool\base.py", line 678, in __init__
    self.__connect()
  File "C:\Users\ABIE\AppData\Local\Programs\Python\Python311\Lib\site-packages\sqlalchemy\pool\base.py", line 902, in __connect
    with util.safe_reraise():
  File "C:\Users\ABIE\AppData\Local\Programs\Python\Python311\Lib\site-packages\sqlalchemy\util\langhelpers.py", line 146, in __exit__
    raise exc_value.with_traceback(exc_tb)
  File "C:\Users\ABIE\AppData\Local\Programs\Python\Python311\Lib\site-packages\sqlalchemy\pool\base.py", line 898, in __connect
    self.dbapi_connection = connection = pool._invoke_creator(self)
                                         ^^^^^^^^^^^^^^^^^^^^^^^^^^
  File "C:\Users\ABIE\AppData\Local\Programs\Python\Python311\Lib\site-packages\sqlalchemy\engine\create.py", line 645, in connect
    return dialect.connect(*cargs, **cparams)
           ^^^^^^^^^^^^^^^^^^^^^^^^^^^^^^^^^^
  File "C:\Users\ABIE\AppData\Local\Programs\Python\Python311\Lib\site-packages\sqlalchemy\engine\default.py", line 616, in connect
    return self.loaded_dbapi.connect(*cargs, **cparams)
           ^^^^^^^^^^^^^^^^^^^^^^^^^^^^^^^^^^^^^^^^^^^^
  File "C:\Users\ABIE\AppData\Local\Programs\Python\Python311\Lib\site-packages\oracledb\connection.py", line 1698, in connect
    return conn_class(dsn=dsn, pool=pool, params=params, **kwargs)
           ^^^^^^^^^^^^^^^^^^^^^^^^^^^^^^^^^^^^^^^^^^^^^^^^^^^^^^^
  File "C:\Users\ABIE\AppData\Local\Programs\Python\Python311\Lib\site-packages\oracledb\connection.py", line 892, in __init__
    impl.connect(params_impl)
  File "src/oracledb/impl/thin/connection.pyx", line 536, in oracledb.thin_impl.ThinConnImpl.connect
  File "src/oracledb/impl/thin/connection.pyx", line 532, in oracledb.thin_impl.ThinConnImpl.connect
  File "src/oracledb/impl/thin/connection.pyx", line 475, in oracledb.thin_impl.ThinConnImpl._connect_with_params
  File "src/oracledb/impl/thin/connection.pyx", line 456, in oracledb.thin_impl.ThinConnImpl._connect_with_description
  File "src/oracledb/impl/thin/connection.pyx", line 418, in oracledb.thin_impl.ThinConnImpl._connect_with_address
  File "C:\Users\ABIE\AppData\Local\Programs\Python\Python311\Lib\site-packages\oracledb\errors.py", line 199, in _raise_err
    raise error.exc_type(error) from cause
oracledb.exceptions.OperationalError: DPY-6005: cannot connect to database (CONNECTION_ID=SqioWWDVzme0OPxXDaIVHw==).
DPY-6001: Service "XEPDB1" is not registered with the listener at host "127.0.0.1" port 1521. (Similar to ORA-12514)

The above exception was the direct cause of the following exception:

Traceback (most recent call last):
  File "C:\Users\ABIE\Desktop\DataIQ\dataiq\oracle_connector.py", line 200, in connect
    conn = engine.connect()
           ^^^^^^^^^^^^^^^^
  File "C:\Users\ABIE\AppData\Local\Programs\Python\Python311\Lib\site-packages\sqlalchemy\engine\base.py", line 3269, in connect
    return self._connection_cls(self)
           ^^^^^^^^^^^^^^^^^^^^^^^^^^
  File "C:\Users\ABIE\AppData\Local\Programs\Python\Python311\Lib\site-packages\sqlalchemy\engine\base.py", line 147, in __init__
    Connection._handle_dbapi_exception_noconnection(
  File "C:\Users\ABIE\AppData\Local\Programs\Python\Python311\Lib\site-packages\sqlalchemy\engine\base.py", line 2431, in _handle_dbapi_exception_noconnection
    raise sqlalchemy_exception.with_traceback(exc_info[2]) from e
  File "C:\Users\ABIE\AppData\Local\Programs\Python\Python311\Lib\site-packages\sqlalchemy\engine\base.py", line 145, in __init__
    self._dbapi_connection = engine.raw_connection()
                             ^^^^^^^^^^^^^^^^^^^^^^^
  File "C:\Users\ABIE\AppData\Local\Programs\Python\Python311\Lib\site-packages\sqlalchemy\engine\base.py", line 3293, in raw_connection
    return self.pool.connect()
           ^^^^^^^^^^^^^^^^^^^
  File "C:\Users\ABIE\AppData\Local\Programs\Python\Python311\Lib\site-packages\sqlalchemy\pool\base.py", line 452, in connect
    return _ConnectionFairy._checkout(self)
           ^^^^^^^^^^^^^^^^^^^^^^^^^^^^^^^^
  File "C:\Users\ABIE\AppData\Local\Programs\Python\Python311\Lib\site-packages\sqlalchemy\pool\base.py", line 1269, in _checkout
    fairy = _ConnectionRecord.checkout(pool)
            ^^^^^^^^^^^^^^^^^^^^^^^^^^^^^^^^
  File "C:\Users\ABIE\AppData\Local\Programs\Python\Python311\Lib\site-packages\sqlalchemy\pool\base.py", line 716, in checkout
    rec = pool._do_get()
          ^^^^^^^^^^^^^^
  File "C:\Users\ABIE\AppData\Local\Programs\Python\Python311\Lib\site-packages\sqlalchemy\pool\impl.py", line 169, in _do_get
    with util.safe_reraise():
  File "C:\Users\ABIE\AppData\Local\Programs\Python\Python311\Lib\site-packages\sqlalchemy\util\langhelpers.py", line 146, in __exit__
    raise exc_value.with_traceback(exc_tb)
  File "C:\Users\ABIE\AppData\Local\Programs\Python\Python311\Lib\site-packages\sqlalchemy\pool\impl.py", line 167, in _do_get
    return self._create_connection()
           ^^^^^^^^^^^^^^^^^^^^^^^^^
  File "C:\Users\ABIE\AppData\Local\Programs\Python\Python311\Lib\site-packages\sqlalchemy\pool\base.py", line 393, in _create_connection
    return _ConnectionRecord(self)
           ^^^^^^^^^^^^^^^^^^^^^^^
  File "C:\Users\ABIE\AppData\Local\Programs\Python\Python311\Lib\site-packages\sqlalchemy\pool\base.py", line 678, in __init__
    self.__connect()
  File "C:\Users\ABIE\AppData\Local\Programs\Python\Python311\Lib\site-packages\sqlalchemy\pool\base.py", line 902, in __connect
    with util.safe_reraise():
  File "C:\Users\ABIE\AppData\Local\Programs\Python\Python311\Lib\site-packages\sqlalchemy\util\langhelpers.py", line 146, in __exit__
    raise exc_value.with_traceback(exc_tb)
  File "C:\Users\ABIE\AppData\Local\Programs\Python\Python311\Lib\site-packages\sqlalchemy\pool\base.py", line 898, in __connect
    self.dbapi_connection = connection = pool._invoke_creator(self)
                                         ^^^^^^^^^^^^^^^^^^^^^^^^^^
  File "C:\Users\ABIE\AppData\Local\Programs\Python\Python311\Lib\site-packages\sqlalchemy\engine\create.py", line 645, in connect
    return dialect.connect(*cargs, **cparams)
           ^^^^^^^^^^^^^^^^^^^^^^^^^^^^^^^^^^
  File "C:\Users\ABIE\AppData\Local\Programs\Python\Python311\Lib\site-packages\sqlalchemy\engine\default.py", line 616, in connect
    return self.loaded_dbapi.connect(*cargs, **cparams)
           ^^^^^^^^^^^^^^^^^^^^^^^^^^^^^^^^^^^^^^^^^^^^
  File "C:\Users\ABIE\AppData\Local\Programs\Python\Python311\Lib\site-packages\oracledb\connection.py", line 1698, in connect
    return conn_class(dsn=dsn, pool=pool, params=params, **kwargs)
           ^^^^^^^^^^^^^^^^^^^^^^^^^^^^^^^^^^^^^^^^^^^^^^^^^^^^^^^
  File "C:\Users\ABIE\AppData\Local\Programs\Python\Python311\Lib\site-packages\oracledb\connection.py", line 892, in __init__
    impl.connect(params_impl)
  File "src/oracledb/impl/thin/connection.pyx", line 536, in oracledb.thin_impl.ThinConnImpl.connect
  File "src/oracledb/impl/thin/connection.pyx", line 532, in oracledb.thin_impl.ThinConnImpl.connect
  File "src/oracledb/impl/thin/connection.pyx", line 475, in oracledb.thin_impl.ThinConnImpl._connect_with_params
  File "src/oracledb/impl/thin/connection.pyx", line 456, in oracledb.thin_impl.ThinConnImpl._connect_with_description
  File "src/oracledb/impl/thin/connection.pyx", line 418, in oracledb.thin_impl.ThinConnImpl._connect_with_address
  File "C:\Users\ABIE\AppData\Local\Programs\Python\Python311\Lib\site-packages\oracledb\errors.py", line 199, in _raise_err
    raise error.exc_type(error) from cause
sqlalchemy.exc.OperationalError: (oracledb.exceptions.OperationalError) DPY-6005: cannot connect to database (CONNECTION_ID=SqioWWDVzme0OPxXDaIVHw==).
DPY-6001: Service "XEPDB1" is not registered with the listener at host "127.0.0.1" port 1521. (Similar to ORA-12514)
(Background on this error at: https://sqlalche.me/e/20/e3q8)
2025-10-21 10:23:20 | ERROR | dataiq | Connection test failed: (oracledb.exceptions.OperationalError) DPY-6005: cannot connect to database (CONNECTION_ID=SqioWWDVzme0OPxXDaIVHw==).
DPY-6001: Service "XEPDB1" is not registered with the listener at host "127.0.0.1" port 1521. (Similar to ORA-12514)
(Background on this error at: https://sqlalche.me/e/20/e3q8)
2025-10-21 10:23:20 | INFO | dataiq | Disposed SQLAlchemy engine
2025-10-21 10:24:27 | INFO | dataiq | Starting profiling for bank_data
2025-10-21 10:24:28 | INFO | dataiq | Profile saved: outputs\profiles\profile_bank_data.csv
2025-10-21 10:24:28 | INFO | dataiq | Computing data health score
2025-10-21 10:24:28 | INFO | dataiq | Data health score: 100.00
2025-10-21 10:24:43 | INFO | dataiq | Removed 0 duplicate rows
2025-10-21 10:24:43 | INFO | dataiq | Normalized string columns: ['JOB', 'MARTIAL', 'EDUCATION', 'DEFAULT_STATUS ', 'HOUSING', 'LOAN', 'CONTACT', 'MONTH', 'POUTCOME', 'DEPOSIT']
2025-10-21 10:25:11 | INFO | dataiq | Starting anomaly detection
2025-10-21 10:25:16 | INFO | dataiq | Anomaly chart saved: dashboard\assets\charts\anomalies_per_column.png
2025-10-21 10:33:29 | INFO | dataiq | SQLAlchemy engine created
2025-10-21 10:33:30 | ERROR | dataiq | Failed to connect to Oracle: (oracledb.exceptions.OperationalError) DPY-6005: cannot connect to database (CONNECTION_ID=y4x7/jKIxQdxYU0dgiSjkg==).
DPY-6001: Service "XEPDB1" is not registered with the listener at host "127.0.0.1" port 1521. (Similar to ORA-12514)
(Background on this error at: https://sqlalche.me/e/20/e3q8)
Traceback (most recent call last):
  File "src/oracledb/impl/thin/connection.pyx", line 414, in oracledb.thin_impl.ThinConnImpl._connect_with_address
  File "src/oracledb/impl/thin/protocol.pyx", line 288, in oracledb.thin_impl.Protocol._connect_phase_one
  File "src/oracledb/impl/thin/protocol.pyx", line 470, in oracledb.thin_impl.Protocol._process_message
  File "src/oracledb/impl/thin/protocol.pyx", line 446, in oracledb.thin_impl.Protocol._process_message
  File "src/oracledb/impl/thin/messages/connect.pyx", line 95, in oracledb.thin_impl.ConnectMessage.process
  File "C:\Users\ABIE\AppData\Local\Programs\Python\Python311\Lib\site-packages\oracledb\errors.py", line 199, in _raise_err
    raise error.exc_type(error) from cause
oracledb.exceptions.OperationalError: DPY-6001: Service "XEPDB1" is not registered with the listener at host "127.0.0.1" port 1521. (Similar to ORA-12514)

The above exception was the direct cause of the following exception:

Traceback (most recent call last):
  File "C:\Users\ABIE\AppData\Local\Programs\Python\Python311\Lib\site-packages\sqlalchemy\engine\base.py", line 145, in __init__
    self._dbapi_connection = engine.raw_connection()
                             ^^^^^^^^^^^^^^^^^^^^^^^
  File "C:\Users\ABIE\AppData\Local\Programs\Python\Python311\Lib\site-packages\sqlalchemy\engine\base.py", line 3293, in raw_connection
    return self.pool.connect()
           ^^^^^^^^^^^^^^^^^^^
  File "C:\Users\ABIE\AppData\Local\Programs\Python\Python311\Lib\site-packages\sqlalchemy\pool\base.py", line 452, in connect
    return _ConnectionFairy._checkout(self)
           ^^^^^^^^^^^^^^^^^^^^^^^^^^^^^^^^
  File "C:\Users\ABIE\AppData\Local\Programs\Python\Python311\Lib\site-packages\sqlalchemy\pool\base.py", line 1269, in _checkout
    fairy = _ConnectionRecord.checkout(pool)
            ^^^^^^^^^^^^^^^^^^^^^^^^^^^^^^^^
  File "C:\Users\ABIE\AppData\Local\Programs\Python\Python311\Lib\site-packages\sqlalchemy\pool\base.py", line 716, in checkout
    rec = pool._do_get()
          ^^^^^^^^^^^^^^
  File "C:\Users\ABIE\AppData\Local\Programs\Python\Python311\Lib\site-packages\sqlalchemy\pool\impl.py", line 169, in _do_get
    with util.safe_reraise():
  File "C:\Users\ABIE\AppData\Local\Programs\Python\Python311\Lib\site-packages\sqlalchemy\util\langhelpers.py", line 146, in __exit__
    raise exc_value.with_traceback(exc_tb)
  File "C:\Users\ABIE\AppData\Local\Programs\Python\Python311\Lib\site-packages\sqlalchemy\pool\impl.py", line 167, in _do_get
    return self._create_connection()
           ^^^^^^^^^^^^^^^^^^^^^^^^^
  File "C:\Users\ABIE\AppData\Local\Programs\Python\Python311\Lib\site-packages\sqlalchemy\pool\base.py", line 393, in _create_connection
    return _ConnectionRecord(self)
           ^^^^^^^^^^^^^^^^^^^^^^^
  File "C:\Users\ABIE\AppData\Local\Programs\Python\Python311\Lib\site-packages\sqlalchemy\pool\base.py", line 678, in __init__
    self.__connect()
  File "C:\Users\ABIE\AppData\Local\Programs\Python\Python311\Lib\site-packages\sqlalchemy\pool\base.py", line 902, in __connect
    with util.safe_reraise():
  File "C:\Users\ABIE\AppData\Local\Programs\Python\Python311\Lib\site-packages\sqlalchemy\util\langhelpers.py", line 146, in __exit__
    raise exc_value.with_traceback(exc_tb)
  File "C:\Users\ABIE\AppData\Local\Programs\Python\Python311\Lib\site-packages\sqlalchemy\pool\base.py", line 898, in __connect
    self.dbapi_connection = connection = pool._invoke_creator(self)
                                         ^^^^^^^^^^^^^^^^^^^^^^^^^^
  File "C:\Users\ABIE\AppData\Local\Programs\Python\Python311\Lib\site-packages\sqlalchemy\engine\create.py", line 645, in connect
    return dialect.connect(*cargs, **cparams)
           ^^^^^^^^^^^^^^^^^^^^^^^^^^^^^^^^^^
  File "C:\Users\ABIE\AppData\Local\Programs\Python\Python311\Lib\site-packages\sqlalchemy\engine\default.py", line 616, in connect
    return self.loaded_dbapi.connect(*cargs, **cparams)
           ^^^^^^^^^^^^^^^^^^^^^^^^^^^^^^^^^^^^^^^^^^^^
  File "C:\Users\ABIE\AppData\Local\Programs\Python\Python311\Lib\site-packages\oracledb\connection.py", line 1698, in connect
    return conn_class(dsn=dsn, pool=pool, params=params, **kwargs)
           ^^^^^^^^^^^^^^^^^^^^^^^^^^^^^^^^^^^^^^^^^^^^^^^^^^^^^^^
  File "C:\Users\ABIE\AppData\Local\Programs\Python\Python311\Lib\site-packages\oracledb\connection.py", line 892, in __init__
    impl.connect(params_impl)
  File "src/oracledb/impl/thin/connection.pyx", line 536, in oracledb.thin_impl.ThinConnImpl.connect
  File "src/oracledb/impl/thin/connection.pyx", line 532, in oracledb.thin_impl.ThinConnImpl.connect
  File "src/oracledb/impl/thin/connection.pyx", line 475, in oracledb.thin_impl.ThinConnImpl._connect_with_params
  File "src/oracledb/impl/thin/connection.pyx", line 456, in oracledb.thin_impl.ThinConnImpl._connect_with_description
  File "src/oracledb/impl/thin/connection.pyx", line 418, in oracledb.thin_impl.ThinConnImpl._connect_with_address
  File "C:\Users\ABIE\AppData\Local\Programs\Python\Python311\Lib\site-packages\oracledb\errors.py", line 199, in _raise_err
    raise error.exc_type(error) from cause
oracledb.exceptions.OperationalError: DPY-6005: cannot connect to database (CONNECTION_ID=y4x7/jKIxQdxYU0dgiSjkg==).
DPY-6001: Service "XEPDB1" is not registered with the listener at host "127.0.0.1" port 1521. (Similar to ORA-12514)

The above exception was the direct cause of the following exception:

Traceback (most recent call last):
  File "C:\Users\ABIE\Desktop\DataIQ\dataiq\oracle_connector.py", line 200, in connect
    conn = engine.connect()
           ^^^^^^^^^^^^^^^^
  File "C:\Users\ABIE\AppData\Local\Programs\Python\Python311\Lib\site-packages\sqlalchemy\engine\base.py", line 3269, in connect
    return self._connection_cls(self)
           ^^^^^^^^^^^^^^^^^^^^^^^^^^
  File "C:\Users\ABIE\AppData\Local\Programs\Python\Python311\Lib\site-packages\sqlalchemy\engine\base.py", line 147, in __init__
    Connection._handle_dbapi_exception_noconnection(
  File "C:\Users\ABIE\AppData\Local\Programs\Python\Python311\Lib\site-packages\sqlalchemy\engine\base.py", line 2431, in _handle_dbapi_exception_noconnection
    raise sqlalchemy_exception.with_traceback(exc_info[2]) from e
  File "C:\Users\ABIE\AppData\Local\Programs\Python\Python311\Lib\site-packages\sqlalchemy\engine\base.py", line 145, in __init__
    self._dbapi_connection = engine.raw_connection()
                             ^^^^^^^^^^^^^^^^^^^^^^^
  File "C:\Users\ABIE\AppData\Local\Programs\Python\Python311\Lib\site-packages\sqlalchemy\engine\base.py", line 3293, in raw_connection
    return self.pool.connect()
           ^^^^^^^^^^^^^^^^^^^
  File "C:\Users\ABIE\AppData\Local\Programs\Python\Python311\Lib\site-packages\sqlalchemy\pool\base.py", line 452, in connect
    return _ConnectionFairy._checkout(self)
           ^^^^^^^^^^^^^^^^^^^^^^^^^^^^^^^^
  File "C:\Users\ABIE\AppData\Local\Programs\Python\Python311\Lib\site-packages\sqlalchemy\pool\base.py", line 1269, in _checkout
    fairy = _ConnectionRecord.checkout(pool)
            ^^^^^^^^^^^^^^^^^^^^^^^^^^^^^^^^
  File "C:\Users\ABIE\AppData\Local\Programs\Python\Python311\Lib\site-packages\sqlalchemy\pool\base.py", line 716, in checkout
    rec = pool._do_get()
          ^^^^^^^^^^^^^^
  File "C:\Users\ABIE\AppData\Local\Programs\Python\Python311\Lib\site-packages\sqlalchemy\pool\impl.py", line 169, in _do_get
    with util.safe_reraise():
  File "C:\Users\ABIE\AppData\Local\Programs\Python\Python311\Lib\site-packages\sqlalchemy\util\langhelpers.py", line 146, in __exit__
    raise exc_value.with_traceback(exc_tb)
  File "C:\Users\ABIE\AppData\Local\Programs\Python\Python311\Lib\site-packages\sqlalchemy\pool\impl.py", line 167, in _do_get
    return self._create_connection()
           ^^^^^^^^^^^^^^^^^^^^^^^^^
  File "C:\Users\ABIE\AppData\Local\Programs\Python\Python311\Lib\site-packages\sqlalchemy\pool\base.py", line 393, in _create_connection
    return _ConnectionRecord(self)
           ^^^^^^^^^^^^^^^^^^^^^^^
  File "C:\Users\ABIE\AppData\Local\Programs\Python\Python311\Lib\site-packages\sqlalchemy\pool\base.py", line 678, in __init__
    self.__connect()
  File "C:\Users\ABIE\AppData\Local\Programs\Python\Python311\Lib\site-packages\sqlalchemy\pool\base.py", line 902, in __connect
    with util.safe_reraise():
  File "C:\Users\ABIE\AppData\Local\Programs\Python\Python311\Lib\site-packages\sqlalchemy\util\langhelpers.py", line 146, in __exit__
    raise exc_value.with_traceback(exc_tb)
  File "C:\Users\ABIE\AppData\Local\Programs\Python\Python311\Lib\site-packages\sqlalchemy\pool\base.py", line 898, in __connect
    self.dbapi_connection = connection = pool._invoke_creator(self)
                                         ^^^^^^^^^^^^^^^^^^^^^^^^^^
  File "C:\Users\ABIE\AppData\Local\Programs\Python\Python311\Lib\site-packages\sqlalchemy\engine\create.py", line 645, in connect
    return dialect.connect(*cargs, **cparams)
           ^^^^^^^^^^^^^^^^^^^^^^^^^^^^^^^^^^
  File "C:\Users\ABIE\AppData\Local\Programs\Python\Python311\Lib\site-packages\sqlalchemy\engine\default.py", line 616, in connect
    return self.loaded_dbapi.connect(*cargs, **cparams)
           ^^^^^^^^^^^^^^^^^^^^^^^^^^^^^^^^^^^^^^^^^^^^
  File "C:\Users\ABIE\AppData\Local\Programs\Python\Python311\Lib\site-packages\oracledb\connection.py", line 1698, in connect
    return conn_class(dsn=dsn, pool=pool, params=params, **kwargs)
           ^^^^^^^^^^^^^^^^^^^^^^^^^^^^^^^^^^^^^^^^^^^^^^^^^^^^^^^
  File "C:\Users\ABIE\AppData\Local\Programs\Python\Python311\Lib\site-packages\oracledb\connection.py", line 892, in __init__
    impl.connect(params_impl)
  File "src/oracledb/impl/thin/connection.pyx", line 536, in oracledb.thin_impl.ThinConnImpl.connect
  File "src/oracledb/impl/thin/connection.pyx", line 532, in oracledb.thin_impl.ThinConnImpl.connect
  File "src/oracledb/impl/thin/connection.pyx", line 475, in oracledb.thin_impl.ThinConnImpl._connect_with_params
  File "src/oracledb/impl/thin/connection.pyx", line 456, in oracledb.thin_impl.ThinConnImpl._connect_with_description
  File "src/oracledb/impl/thin/connection.pyx", line 418, in oracledb.thin_impl.ThinConnImpl._connect_with_address
  File "C:\Users\ABIE\AppData\Local\Programs\Python\Python311\Lib\site-packages\oracledb\errors.py", line 199, in _raise_err
    raise error.exc_type(error) from cause
sqlalchemy.exc.OperationalError: (oracledb.exceptions.OperationalError) DPY-6005: cannot connect to database (CONNECTION_ID=y4x7/jKIxQdxYU0dgiSjkg==).
DPY-6001: Service "XEPDB1" is not registered with the listener at host "127.0.0.1" port 1521. (Similar to ORA-12514)
(Background on this error at: https://sqlalche.me/e/20/e3q8)
2025-10-21 10:33:30 | ERROR | dataiq | Connection test failed: (oracledb.exceptions.OperationalError) DPY-6005: cannot connect to database (CONNECTION_ID=y4x7/jKIxQdxYU0dgiSjkg==).
DPY-6001: Service "XEPDB1" is not registered with the listener at host "127.0.0.1" port 1521. (Similar to ORA-12514)
(Background on this error at: https://sqlalche.me/e/20/e3q8)
2025-10-21 10:33:30 | INFO | dataiq | Disposed SQLAlchemy engine
2025-10-21 10:33:38 | INFO | dataiq | SQLAlchemy engine created
2025-10-21 10:33:38 | ERROR | dataiq | Failed to connect to Oracle: (oracledb.exceptions.OperationalError) DPY-6005: cannot connect to database (CONNECTION_ID=DcjtJ6o9vCBxd5ZqxJpzOA==).
DPY-6001: Service "XEPDB1" is not registered with the listener at host "127.0.0.1" port 1521. (Similar to ORA-12514)
(Background on this error at: https://sqlalche.me/e/20/e3q8)
Traceback (most recent call last):
  File "src/oracledb/impl/thin/connection.pyx", line 414, in oracledb.thin_impl.ThinConnImpl._connect_with_address
  File "src/oracledb/impl/thin/protocol.pyx", line 288, in oracledb.thin_impl.Protocol._connect_phase_one
  File "src/oracledb/impl/thin/protocol.pyx", line 470, in oracledb.thin_impl.Protocol._process_message
  File "src/oracledb/impl/thin/protocol.pyx", line 446, in oracledb.thin_impl.Protocol._process_message
  File "src/oracledb/impl/thin/messages/connect.pyx", line 95, in oracledb.thin_impl.ConnectMessage.process
  File "C:\Users\ABIE\AppData\Local\Programs\Python\Python311\Lib\site-packages\oracledb\errors.py", line 199, in _raise_err
    raise error.exc_type(error) from cause
oracledb.exceptions.OperationalError: DPY-6001: Service "XEPDB1" is not registered with the listener at host "127.0.0.1" port 1521. (Similar to ORA-12514)

The above exception was the direct cause of the following exception:

Traceback (most recent call last):
  File "C:\Users\ABIE\AppData\Local\Programs\Python\Python311\Lib\site-packages\sqlalchemy\engine\base.py", line 145, in __init__
    self._dbapi_connection = engine.raw_connection()
                             ^^^^^^^^^^^^^^^^^^^^^^^
  File "C:\Users\ABIE\AppData\Local\Programs\Python\Python311\Lib\site-packages\sqlalchemy\engine\base.py", line 3293, in raw_connection
    return self.pool.connect()
           ^^^^^^^^^^^^^^^^^^^
  File "C:\Users\ABIE\AppData\Local\Programs\Python\Python311\Lib\site-packages\sqlalchemy\pool\base.py", line 452, in connect
    return _ConnectionFairy._checkout(self)
           ^^^^^^^^^^^^^^^^^^^^^^^^^^^^^^^^
  File "C:\Users\ABIE\AppData\Local\Programs\Python\Python311\Lib\site-packages\sqlalchemy\pool\base.py", line 1269, in _checkout
    fairy = _ConnectionRecord.checkout(pool)
            ^^^^^^^^^^^^^^^^^^^^^^^^^^^^^^^^
  File "C:\Users\ABIE\AppData\Local\Programs\Python\Python311\Lib\site-packages\sqlalchemy\pool\base.py", line 716, in checkout
    rec = pool._do_get()
          ^^^^^^^^^^^^^^
  File "C:\Users\ABIE\AppData\Local\Programs\Python\Python311\Lib\site-packages\sqlalchemy\pool\impl.py", line 169, in _do_get
    with util.safe_reraise():
  File "C:\Users\ABIE\AppData\Local\Programs\Python\Python311\Lib\site-packages\sqlalchemy\util\langhelpers.py", line 146, in __exit__
    raise exc_value.with_traceback(exc_tb)
  File "C:\Users\ABIE\AppData\Local\Programs\Python\Python311\Lib\site-packages\sqlalchemy\pool\impl.py", line 167, in _do_get
    return self._create_connection()
           ^^^^^^^^^^^^^^^^^^^^^^^^^
  File "C:\Users\ABIE\AppData\Local\Programs\Python\Python311\Lib\site-packages\sqlalchemy\pool\base.py", line 393, in _create_connection
    return _ConnectionRecord(self)
           ^^^^^^^^^^^^^^^^^^^^^^^
  File "C:\Users\ABIE\AppData\Local\Programs\Python\Python311\Lib\site-packages\sqlalchemy\pool\base.py", line 678, in __init__
    self.__connect()
  File "C:\Users\ABIE\AppData\Local\Programs\Python\Python311\Lib\site-packages\sqlalchemy\pool\base.py", line 902, in __connect
    with util.safe_reraise():
  File "C:\Users\ABIE\AppData\Local\Programs\Python\Python311\Lib\site-packages\sqlalchemy\util\langhelpers.py", line 146, in __exit__
    raise exc_value.with_traceback(exc_tb)
  File "C:\Users\ABIE\AppData\Local\Programs\Python\Python311\Lib\site-packages\sqlalchemy\pool\base.py", line 898, in __connect
    self.dbapi_connection = connection = pool._invoke_creator(self)
                                         ^^^^^^^^^^^^^^^^^^^^^^^^^^
  File "C:\Users\ABIE\AppData\Local\Programs\Python\Python311\Lib\site-packages\sqlalchemy\engine\create.py", line 645, in connect
    return dialect.connect(*cargs, **cparams)
           ^^^^^^^^^^^^^^^^^^^^^^^^^^^^^^^^^^
  File "C:\Users\ABIE\AppData\Local\Programs\Python\Python311\Lib\site-packages\sqlalchemy\engine\default.py", line 616, in connect
    return self.loaded_dbapi.connect(*cargs, **cparams)
           ^^^^^^^^^^^^^^^^^^^^^^^^^^^^^^^^^^^^^^^^^^^^
  File "C:\Users\ABIE\AppData\Local\Programs\Python\Python311\Lib\site-packages\oracledb\connection.py", line 1698, in connect
    return conn_class(dsn=dsn, pool=pool, params=params, **kwargs)
           ^^^^^^^^^^^^^^^^^^^^^^^^^^^^^^^^^^^^^^^^^^^^^^^^^^^^^^^
  File "C:\Users\ABIE\AppData\Local\Programs\Python\Python311\Lib\site-packages\oracledb\connection.py", line 892, in __init__
    impl.connect(params_impl)
  File "src/oracledb/impl/thin/connection.pyx", line 536, in oracledb.thin_impl.ThinConnImpl.connect
  File "src/oracledb/impl/thin/connection.pyx", line 532, in oracledb.thin_impl.ThinConnImpl.connect
  File "src/oracledb/impl/thin/connection.pyx", line 475, in oracledb.thin_impl.ThinConnImpl._connect_with_params
  File "src/oracledb/impl/thin/connection.pyx", line 456, in oracledb.thin_impl.ThinConnImpl._connect_with_description
  File "src/oracledb/impl/thin/connection.pyx", line 418, in oracledb.thin_impl.ThinConnImpl._connect_with_address
  File "C:\Users\ABIE\AppData\Local\Programs\Python\Python311\Lib\site-packages\oracledb\errors.py", line 199, in _raise_err
    raise error.exc_type(error) from cause
oracledb.exceptions.OperationalError: DPY-6005: cannot connect to database (CONNECTION_ID=DcjtJ6o9vCBxd5ZqxJpzOA==).
DPY-6001: Service "XEPDB1" is not registered with the listener at host "127.0.0.1" port 1521. (Similar to ORA-12514)

The above exception was the direct cause of the following exception:

Traceback (most recent call last):
  File "C:\Users\ABIE\Desktop\DataIQ\dataiq\oracle_connector.py", line 200, in connect
    conn = engine.connect()
           ^^^^^^^^^^^^^^^^
  File "C:\Users\ABIE\AppData\Local\Programs\Python\Python311\Lib\site-packages\sqlalchemy\engine\base.py", line 3269, in connect
    return self._connection_cls(self)
           ^^^^^^^^^^^^^^^^^^^^^^^^^^
  File "C:\Users\ABIE\AppData\Local\Programs\Python\Python311\Lib\site-packages\sqlalchemy\engine\base.py", line 147, in __init__
    Connection._handle_dbapi_exception_noconnection(
  File "C:\Users\ABIE\AppData\Local\Programs\Python\Python311\Lib\site-packages\sqlalchemy\engine\base.py", line 2431, in _handle_dbapi_exception_noconnection
    raise sqlalchemy_exception.with_traceback(exc_info[2]) from e
  File "C:\Users\ABIE\AppData\Local\Programs\Python\Python311\Lib\site-packages\sqlalchemy\engine\base.py", line 145, in __init__
    self._dbapi_connection = engine.raw_connection()
                             ^^^^^^^^^^^^^^^^^^^^^^^
  File "C:\Users\ABIE\AppData\Local\Programs\Python\Python311\Lib\site-packages\sqlalchemy\engine\base.py", line 3293, in raw_connection
    return self.pool.connect()
           ^^^^^^^^^^^^^^^^^^^
  File "C:\Users\ABIE\AppData\Local\Programs\Python\Python311\Lib\site-packages\sqlalchemy\pool\base.py", line 452, in connect
    return _ConnectionFairy._checkout(self)
           ^^^^^^^^^^^^^^^^^^^^^^^^^^^^^^^^
  File "C:\Users\ABIE\AppData\Local\Programs\Python\Python311\Lib\site-packages\sqlalchemy\pool\base.py", line 1269, in _checkout
    fairy = _ConnectionRecord.checkout(pool)
            ^^^^^^^^^^^^^^^^^^^^^^^^^^^^^^^^
  File "C:\Users\ABIE\AppData\Local\Programs\Python\Python311\Lib\site-packages\sqlalchemy\pool\base.py", line 716, in checkout
    rec = pool._do_get()
          ^^^^^^^^^^^^^^
  File "C:\Users\ABIE\AppData\Local\Programs\Python\Python311\Lib\site-packages\sqlalchemy\pool\impl.py", line 169, in _do_get
    with util.safe_reraise():
  File "C:\Users\ABIE\AppData\Local\Programs\Python\Python311\Lib\site-packages\sqlalchemy\util\langhelpers.py", line 146, in __exit__
    raise exc_value.with_traceback(exc_tb)
  File "C:\Users\ABIE\AppData\Local\Programs\Python\Python311\Lib\site-packages\sqlalchemy\pool\impl.py", line 167, in _do_get
    return self._create_connection()
           ^^^^^^^^^^^^^^^^^^^^^^^^^
  File "C:\Users\ABIE\AppData\Local\Programs\Python\Python311\Lib\site-packages\sqlalchemy\pool\base.py", line 393, in _create_connection
    return _ConnectionRecord(self)
           ^^^^^^^^^^^^^^^^^^^^^^^
  File "C:\Users\ABIE\AppData\Local\Programs\Python\Python311\Lib\site-packages\sqlalchemy\pool\base.py", line 678, in __init__
    self.__connect()
  File "C:\Users\ABIE\AppData\Local\Programs\Python\Python311\Lib\site-packages\sqlalchemy\pool\base.py", line 902, in __connect
    with util.safe_reraise():
  File "C:\Users\ABIE\AppData\Local\Programs\Python\Python311\Lib\site-packages\sqlalchemy\util\langhelpers.py", line 146, in __exit__
    raise exc_value.with_traceback(exc_tb)
  File "C:\Users\ABIE\AppData\Local\Programs\Python\Python311\Lib\site-packages\sqlalchemy\pool\base.py", line 898, in __connect
    self.dbapi_connection = connection = pool._invoke_creator(self)
                                         ^^^^^^^^^^^^^^^^^^^^^^^^^^
  File "C:\Users\ABIE\AppData\Local\Programs\Python\Python311\Lib\site-packages\sqlalchemy\engine\create.py", line 645, in connect
    return dialect.connect(*cargs, **cparams)
           ^^^^^^^^^^^^^^^^^^^^^^^^^^^^^^^^^^
  File "C:\Users\ABIE\AppData\Local\Programs\Python\Python311\Lib\site-packages\sqlalchemy\engine\default.py", line 616, in connect
    return self.loaded_dbapi.connect(*cargs, **cparams)
           ^^^^^^^^^^^^^^^^^^^^^^^^^^^^^^^^^^^^^^^^^^^^
  File "C:\Users\ABIE\AppData\Local\Programs\Python\Python311\Lib\site-packages\oracledb\connection.py", line 1698, in connect
    return conn_class(dsn=dsn, pool=pool, params=params, **kwargs)
           ^^^^^^^^^^^^^^^^^^^^^^^^^^^^^^^^^^^^^^^^^^^^^^^^^^^^^^^
  File "C:\Users\ABIE\AppData\Local\Programs\Python\Python311\Lib\site-packages\oracledb\connection.py", line 892, in __init__
    impl.connect(params_impl)
  File "src/oracledb/impl/thin/connection.pyx", line 536, in oracledb.thin_impl.ThinConnImpl.connect
  File "src/oracledb/impl/thin/connection.pyx", line 532, in oracledb.thin_impl.ThinConnImpl.connect
  File "src/oracledb/impl/thin/connection.pyx", line 475, in oracledb.thin_impl.ThinConnImpl._connect_with_params
  File "src/oracledb/impl/thin/connection.pyx", line 456, in oracledb.thin_impl.ThinConnImpl._connect_with_description
  File "src/oracledb/impl/thin/connection.pyx", line 418, in oracledb.thin_impl.ThinConnImpl._connect_with_address
  File "C:\Users\ABIE\AppData\Local\Programs\Python\Python311\Lib\site-packages\oracledb\errors.py", line 199, in _raise_err
    raise error.exc_type(error) from cause
sqlalchemy.exc.OperationalError: (oracledb.exceptions.OperationalError) DPY-6005: cannot connect to database (CONNECTION_ID=DcjtJ6o9vCBxd5ZqxJpzOA==).
DPY-6001: Service "XEPDB1" is not registered with the listener at host "127.0.0.1" port 1521. (Similar to ORA-12514)
(Background on this error at: https://sqlalche.me/e/20/e3q8)
2025-10-21 10:33:38 | ERROR | dataiq | Connection test failed: (oracledb.exceptions.OperationalError) DPY-6005: cannot connect to database (CONNECTION_ID=DcjtJ6o9vCBxd5ZqxJpzOA==).
DPY-6001: Service "XEPDB1" is not registered with the listener at host "127.0.0.1" port 1521. (Similar to ORA-12514)
(Background on this error at: https://sqlalche.me/e/20/e3q8)
2025-10-21 10:33:38 | INFO | dataiq | Disposed SQLAlchemy engine
2025-10-21 10:40:04 | INFO | dataiq | SQLAlchemy engine created
2025-10-21 10:40:04 | ERROR | dataiq | Failed to connect to Oracle: (oracledb.exceptions.OperationalError) DPY-6005: cannot connect to database (CONNECTION_ID=hU/s1994r+Tv0Go7Zh4vHA==).
DPY-6001: Service "XEPDB1" is not registered with the listener at host "127.0.0.1" port 1521. (Similar to ORA-12514)
(Background on this error at: https://sqlalche.me/e/20/e3q8)
Traceback (most recent call last):
  File "src/oracledb/impl/thin/connection.pyx", line 414, in oracledb.thin_impl.ThinConnImpl._connect_with_address
  File "src/oracledb/impl/thin/protocol.pyx", line 288, in oracledb.thin_impl.Protocol._connect_phase_one
  File "src/oracledb/impl/thin/protocol.pyx", line 470, in oracledb.thin_impl.Protocol._process_message
  File "src/oracledb/impl/thin/protocol.pyx", line 446, in oracledb.thin_impl.Protocol._process_message
  File "src/oracledb/impl/thin/messages/connect.pyx", line 95, in oracledb.thin_impl.ConnectMessage.process
  File "C:\Users\ABIE\AppData\Local\Programs\Python\Python311\Lib\site-packages\oracledb\errors.py", line 199, in _raise_err
    raise error.exc_type(error) from cause
oracledb.exceptions.OperationalError: DPY-6001: Service "XEPDB1" is not registered with the listener at host "127.0.0.1" port 1521. (Similar to ORA-12514)

The above exception was the direct cause of the following exception:

Traceback (most recent call last):
  File "C:\Users\ABIE\AppData\Local\Programs\Python\Python311\Lib\site-packages\sqlalchemy\engine\base.py", line 145, in __init__
    self._dbapi_connection = engine.raw_connection()
                             ^^^^^^^^^^^^^^^^^^^^^^^
  File "C:\Users\ABIE\AppData\Local\Programs\Python\Python311\Lib\site-packages\sqlalchemy\engine\base.py", line 3293, in raw_connection
    return self.pool.connect()
           ^^^^^^^^^^^^^^^^^^^
  File "C:\Users\ABIE\AppData\Local\Programs\Python\Python311\Lib\site-packages\sqlalchemy\pool\base.py", line 452, in connect
    return _ConnectionFairy._checkout(self)
           ^^^^^^^^^^^^^^^^^^^^^^^^^^^^^^^^
  File "C:\Users\ABIE\AppData\Local\Programs\Python\Python311\Lib\site-packages\sqlalchemy\pool\base.py", line 1269, in _checkout
    fairy = _ConnectionRecord.checkout(pool)
            ^^^^^^^^^^^^^^^^^^^^^^^^^^^^^^^^
  File "C:\Users\ABIE\AppData\Local\Programs\Python\Python311\Lib\site-packages\sqlalchemy\pool\base.py", line 716, in checkout
    rec = pool._do_get()
          ^^^^^^^^^^^^^^
  File "C:\Users\ABIE\AppData\Local\Programs\Python\Python311\Lib\site-packages\sqlalchemy\pool\impl.py", line 169, in _do_get
    with util.safe_reraise():
  File "C:\Users\ABIE\AppData\Local\Programs\Python\Python311\Lib\site-packages\sqlalchemy\util\langhelpers.py", line 146, in __exit__
    raise exc_value.with_traceback(exc_tb)
  File "C:\Users\ABIE\AppData\Local\Programs\Python\Python311\Lib\site-packages\sqlalchemy\pool\impl.py", line 167, in _do_get
    return self._create_connection()
           ^^^^^^^^^^^^^^^^^^^^^^^^^
  File "C:\Users\ABIE\AppData\Local\Programs\Python\Python311\Lib\site-packages\sqlalchemy\pool\base.py", line 393, in _create_connection
    return _ConnectionRecord(self)
           ^^^^^^^^^^^^^^^^^^^^^^^
  File "C:\Users\ABIE\AppData\Local\Programs\Python\Python311\Lib\site-packages\sqlalchemy\pool\base.py", line 678, in __init__
    self.__connect()
  File "C:\Users\ABIE\AppData\Local\Programs\Python\Python311\Lib\site-packages\sqlalchemy\pool\base.py", line 902, in __connect
    with util.safe_reraise():
  File "C:\Users\ABIE\AppData\Local\Programs\Python\Python311\Lib\site-packages\sqlalchemy\util\langhelpers.py", line 146, in __exit__
    raise exc_value.with_traceback(exc_tb)
  File "C:\Users\ABIE\AppData\Local\Programs\Python\Python311\Lib\site-packages\sqlalchemy\pool\base.py", line 898, in __connect
    self.dbapi_connection = connection = pool._invoke_creator(self)
                                         ^^^^^^^^^^^^^^^^^^^^^^^^^^
  File "C:\Users\ABIE\AppData\Local\Programs\Python\Python311\Lib\site-packages\sqlalchemy\engine\create.py", line 645, in connect
    return dialect.connect(*cargs, **cparams)
           ^^^^^^^^^^^^^^^^^^^^^^^^^^^^^^^^^^
  File "C:\Users\ABIE\AppData\Local\Programs\Python\Python311\Lib\site-packages\sqlalchemy\engine\default.py", line 616, in connect
    return self.loaded_dbapi.connect(*cargs, **cparams)
           ^^^^^^^^^^^^^^^^^^^^^^^^^^^^^^^^^^^^^^^^^^^^
  File "C:\Users\ABIE\AppData\Local\Programs\Python\Python311\Lib\site-packages\oracledb\connection.py", line 1698, in connect
    return conn_class(dsn=dsn, pool=pool, params=params, **kwargs)
           ^^^^^^^^^^^^^^^^^^^^^^^^^^^^^^^^^^^^^^^^^^^^^^^^^^^^^^^
  File "C:\Users\ABIE\AppData\Local\Programs\Python\Python311\Lib\site-packages\oracledb\connection.py", line 892, in __init__
    impl.connect(params_impl)
  File "src/oracledb/impl/thin/connection.pyx", line 536, in oracledb.thin_impl.ThinConnImpl.connect
  File "src/oracledb/impl/thin/connection.pyx", line 532, in oracledb.thin_impl.ThinConnImpl.connect
  File "src/oracledb/impl/thin/connection.pyx", line 475, in oracledb.thin_impl.ThinConnImpl._connect_with_params
  File "src/oracledb/impl/thin/connection.pyx", line 456, in oracledb.thin_impl.ThinConnImpl._connect_with_description
  File "src/oracledb/impl/thin/connection.pyx", line 418, in oracledb.thin_impl.ThinConnImpl._connect_with_address
  File "C:\Users\ABIE\AppData\Local\Programs\Python\Python311\Lib\site-packages\oracledb\errors.py", line 199, in _raise_err
    raise error.exc_type(error) from cause
oracledb.exceptions.OperationalError: DPY-6005: cannot connect to database (CONNECTION_ID=hU/s1994r+Tv0Go7Zh4vHA==).
DPY-6001: Service "XEPDB1" is not registered with the listener at host "127.0.0.1" port 1521. (Similar to ORA-12514)

The above exception was the direct cause of the following exception:

Traceback (most recent call last):
  File "C:\Users\ABIE\Desktop\DataIQ\dataiq\oracle_connector.py", line 200, in connect
    conn = engine.connect()
           ^^^^^^^^^^^^^^^^
  File "C:\Users\ABIE\AppData\Local\Programs\Python\Python311\Lib\site-packages\sqlalchemy\engine\base.py", line 3269, in connect
    return self._connection_cls(self)
           ^^^^^^^^^^^^^^^^^^^^^^^^^^
  File "C:\Users\ABIE\AppData\Local\Programs\Python\Python311\Lib\site-packages\sqlalchemy\engine\base.py", line 147, in __init__
    Connection._handle_dbapi_exception_noconnection(
  File "C:\Users\ABIE\AppData\Local\Programs\Python\Python311\Lib\site-packages\sqlalchemy\engine\base.py", line 2431, in _handle_dbapi_exception_noconnection
    raise sqlalchemy_exception.with_traceback(exc_info[2]) from e
  File "C:\Users\ABIE\AppData\Local\Programs\Python\Python311\Lib\site-packages\sqlalchemy\engine\base.py", line 145, in __init__
    self._dbapi_connection = engine.raw_connection()
                             ^^^^^^^^^^^^^^^^^^^^^^^
  File "C:\Users\ABIE\AppData\Local\Programs\Python\Python311\Lib\site-packages\sqlalchemy\engine\base.py", line 3293, in raw_connection
    return self.pool.connect()
           ^^^^^^^^^^^^^^^^^^^
  File "C:\Users\ABIE\AppData\Local\Programs\Python\Python311\Lib\site-packages\sqlalchemy\pool\base.py", line 452, in connect
    return _ConnectionFairy._checkout(self)
           ^^^^^^^^^^^^^^^^^^^^^^^^^^^^^^^^
  File "C:\Users\ABIE\AppData\Local\Programs\Python\Python311\Lib\site-packages\sqlalchemy\pool\base.py", line 1269, in _checkout
    fairy = _ConnectionRecord.checkout(pool)
            ^^^^^^^^^^^^^^^^^^^^^^^^^^^^^^^^
  File "C:\Users\ABIE\AppData\Local\Programs\Python\Python311\Lib\site-packages\sqlalchemy\pool\base.py", line 716, in checkout
    rec = pool._do_get()
          ^^^^^^^^^^^^^^
  File "C:\Users\ABIE\AppData\Local\Programs\Python\Python311\Lib\site-packages\sqlalchemy\pool\impl.py", line 169, in _do_get
    with util.safe_reraise():
  File "C:\Users\ABIE\AppData\Local\Programs\Python\Python311\Lib\site-packages\sqlalchemy\util\langhelpers.py", line 146, in __exit__
    raise exc_value.with_traceback(exc_tb)
  File "C:\Users\ABIE\AppData\Local\Programs\Python\Python311\Lib\site-packages\sqlalchemy\pool\impl.py", line 167, in _do_get
    return self._create_connection()
           ^^^^^^^^^^^^^^^^^^^^^^^^^
  File "C:\Users\ABIE\AppData\Local\Programs\Python\Python311\Lib\site-packages\sqlalchemy\pool\base.py", line 393, in _create_connection
    return _ConnectionRecord(self)
           ^^^^^^^^^^^^^^^^^^^^^^^
  File "C:\Users\ABIE\AppData\Local\Programs\Python\Python311\Lib\site-packages\sqlalchemy\pool\base.py", line 678, in __init__
    self.__connect()
  File "C:\Users\ABIE\AppData\Local\Programs\Python\Python311\Lib\site-packages\sqlalchemy\pool\base.py", line 902, in __connect
    with util.safe_reraise():
  File "C:\Users\ABIE\AppData\Local\Programs\Python\Python311\Lib\site-packages\sqlalchemy\util\langhelpers.py", line 146, in __exit__
    raise exc_value.with_traceback(exc_tb)
  File "C:\Users\ABIE\AppData\Local\Programs\Python\Python311\Lib\site-packages\sqlalchemy\pool\base.py", line 898, in __connect
    self.dbapi_connection = connection = pool._invoke_creator(self)
                                         ^^^^^^^^^^^^^^^^^^^^^^^^^^
  File "C:\Users\ABIE\AppData\Local\Programs\Python\Python311\Lib\site-packages\sqlalchemy\engine\create.py", line 645, in connect
    return dialect.connect(*cargs, **cparams)
           ^^^^^^^^^^^^^^^^^^^^^^^^^^^^^^^^^^
  File "C:\Users\ABIE\AppData\Local\Programs\Python\Python311\Lib\site-packages\sqlalchemy\engine\default.py", line 616, in connect
    return self.loaded_dbapi.connect(*cargs, **cparams)
           ^^^^^^^^^^^^^^^^^^^^^^^^^^^^^^^^^^^^^^^^^^^^
  File "C:\Users\ABIE\AppData\Local\Programs\Python\Python311\Lib\site-packages\oracledb\connection.py", line 1698, in connect
    return conn_class(dsn=dsn, pool=pool, params=params, **kwargs)
           ^^^^^^^^^^^^^^^^^^^^^^^^^^^^^^^^^^^^^^^^^^^^^^^^^^^^^^^
  File "C:\Users\ABIE\AppData\Local\Programs\Python\Python311\Lib\site-packages\oracledb\connection.py", line 892, in __init__
    impl.connect(params_impl)
  File "src/oracledb/impl/thin/connection.pyx", line 536, in oracledb.thin_impl.ThinConnImpl.connect
  File "src/oracledb/impl/thin/connection.pyx", line 532, in oracledb.thin_impl.ThinConnImpl.connect
  File "src/oracledb/impl/thin/connection.pyx", line 475, in oracledb.thin_impl.ThinConnImpl._connect_with_params
  File "src/oracledb/impl/thin/connection.pyx", line 456, in oracledb.thin_impl.ThinConnImpl._connect_with_description
  File "src/oracledb/impl/thin/connection.pyx", line 418, in oracledb.thin_impl.ThinConnImpl._connect_with_address
  File "C:\Users\ABIE\AppData\Local\Programs\Python\Python311\Lib\site-packages\oracledb\errors.py", line 199, in _raise_err
    raise error.exc_type(error) from cause
sqlalchemy.exc.OperationalError: (oracledb.exceptions.OperationalError) DPY-6005: cannot connect to database (CONNECTION_ID=hU/s1994r+Tv0Go7Zh4vHA==).
DPY-6001: Service "XEPDB1" is not registered with the listener at host "127.0.0.1" port 1521. (Similar to ORA-12514)
(Background on this error at: https://sqlalche.me/e/20/e3q8)
2025-10-21 10:40:04 | ERROR | dataiq | Connection test failed: (oracledb.exceptions.OperationalError) DPY-6005: cannot connect to database (CONNECTION_ID=hU/s1994r+Tv0Go7Zh4vHA==).
DPY-6001: Service "XEPDB1" is not registered with the listener at host "127.0.0.1" port 1521. (Similar to ORA-12514)
(Background on this error at: https://sqlalche.me/e/20/e3q8)
2025-10-21 10:40:04 | INFO | dataiq | Disposed SQLAlchemy engine
2025-10-21 10:43:04 | INFO | dataiq | SQLAlchemy engine created
2025-10-21 10:43:04 | ERROR | dataiq | Failed to connect to Oracle: (oracledb.exceptions.OperationalError) DPY-6005: cannot connect to database (CONNECTION_ID=3O29n473LzmOCXiVVpl37g==).
DPY-6001: Service "XEPDB1" is not registered with the listener at host "127.0.0.1" port 1521. (Similar to ORA-12514)
(Background on this error at: https://sqlalche.me/e/20/e3q8)
Traceback (most recent call last):
  File "src/oracledb/impl/thin/connection.pyx", line 414, in oracledb.thin_impl.ThinConnImpl._connect_with_address
  File "src/oracledb/impl/thin/protocol.pyx", line 288, in oracledb.thin_impl.Protocol._connect_phase_one
  File "src/oracledb/impl/thin/protocol.pyx", line 470, in oracledb.thin_impl.Protocol._process_message
  File "src/oracledb/impl/thin/protocol.pyx", line 446, in oracledb.thin_impl.Protocol._process_message
  File "src/oracledb/impl/thin/messages/connect.pyx", line 95, in oracledb.thin_impl.ConnectMessage.process
  File "C:\Users\ABIE\AppData\Local\Programs\Python\Python311\Lib\site-packages\oracledb\errors.py", line 199, in _raise_err
    raise error.exc_type(error) from cause
oracledb.exceptions.OperationalError: DPY-6001: Service "XEPDB1" is not registered with the listener at host "127.0.0.1" port 1521. (Similar to ORA-12514)

The above exception was the direct cause of the following exception:

Traceback (most recent call last):
  File "C:\Users\ABIE\AppData\Local\Programs\Python\Python311\Lib\site-packages\sqlalchemy\engine\base.py", line 145, in __init__
    self._dbapi_connection = engine.raw_connection()
                             ^^^^^^^^^^^^^^^^^^^^^^^
  File "C:\Users\ABIE\AppData\Local\Programs\Python\Python311\Lib\site-packages\sqlalchemy\engine\base.py", line 3293, in raw_connection
    return self.pool.connect()
           ^^^^^^^^^^^^^^^^^^^
  File "C:\Users\ABIE\AppData\Local\Programs\Python\Python311\Lib\site-packages\sqlalchemy\pool\base.py", line 452, in connect
    return _ConnectionFairy._checkout(self)
           ^^^^^^^^^^^^^^^^^^^^^^^^^^^^^^^^
  File "C:\Users\ABIE\AppData\Local\Programs\Python\Python311\Lib\site-packages\sqlalchemy\pool\base.py", line 1269, in _checkout
    fairy = _ConnectionRecord.checkout(pool)
            ^^^^^^^^^^^^^^^^^^^^^^^^^^^^^^^^
  File "C:\Users\ABIE\AppData\Local\Programs\Python\Python311\Lib\site-packages\sqlalchemy\pool\base.py", line 716, in checkout
    rec = pool._do_get()
          ^^^^^^^^^^^^^^
  File "C:\Users\ABIE\AppData\Local\Programs\Python\Python311\Lib\site-packages\sqlalchemy\pool\impl.py", line 169, in _do_get
    with util.safe_reraise():
  File "C:\Users\ABIE\AppData\Local\Programs\Python\Python311\Lib\site-packages\sqlalchemy\util\langhelpers.py", line 146, in __exit__
    raise exc_value.with_traceback(exc_tb)
  File "C:\Users\ABIE\AppData\Local\Programs\Python\Python311\Lib\site-packages\sqlalchemy\pool\impl.py", line 167, in _do_get
    return self._create_connection()
           ^^^^^^^^^^^^^^^^^^^^^^^^^
  File "C:\Users\ABIE\AppData\Local\Programs\Python\Python311\Lib\site-packages\sqlalchemy\pool\base.py", line 393, in _create_connection
    return _ConnectionRecord(self)
           ^^^^^^^^^^^^^^^^^^^^^^^
  File "C:\Users\ABIE\AppData\Local\Programs\Python\Python311\Lib\site-packages\sqlalchemy\pool\base.py", line 678, in __init__
    self.__connect()
  File "C:\Users\ABIE\AppData\Local\Programs\Python\Python311\Lib\site-packages\sqlalchemy\pool\base.py", line 902, in __connect
    with util.safe_reraise():
  File "C:\Users\ABIE\AppData\Local\Programs\Python\Python311\Lib\site-packages\sqlalchemy\util\langhelpers.py", line 146, in __exit__
    raise exc_value.with_traceback(exc_tb)
  File "C:\Users\ABIE\AppData\Local\Programs\Python\Python311\Lib\site-packages\sqlalchemy\pool\base.py", line 898, in __connect
    self.dbapi_connection = connection = pool._invoke_creator(self)
                                         ^^^^^^^^^^^^^^^^^^^^^^^^^^
  File "C:\Users\ABIE\AppData\Local\Programs\Python\Python311\Lib\site-packages\sqlalchemy\engine\create.py", line 645, in connect
    return dialect.connect(*cargs, **cparams)
           ^^^^^^^^^^^^^^^^^^^^^^^^^^^^^^^^^^
  File "C:\Users\ABIE\AppData\Local\Programs\Python\Python311\Lib\site-packages\sqlalchemy\engine\default.py", line 616, in connect
    return self.loaded_dbapi.connect(*cargs, **cparams)
           ^^^^^^^^^^^^^^^^^^^^^^^^^^^^^^^^^^^^^^^^^^^^
  File "C:\Users\ABIE\AppData\Local\Programs\Python\Python311\Lib\site-packages\oracledb\connection.py", line 1698, in connect
    return conn_class(dsn=dsn, pool=pool, params=params, **kwargs)
           ^^^^^^^^^^^^^^^^^^^^^^^^^^^^^^^^^^^^^^^^^^^^^^^^^^^^^^^
  File "C:\Users\ABIE\AppData\Local\Programs\Python\Python311\Lib\site-packages\oracledb\connection.py", line 892, in __init__
    impl.connect(params_impl)
  File "src/oracledb/impl/thin/connection.pyx", line 536, in oracledb.thin_impl.ThinConnImpl.connect
  File "src/oracledb/impl/thin/connection.pyx", line 532, in oracledb.thin_impl.ThinConnImpl.connect
  File "src/oracledb/impl/thin/connection.pyx", line 475, in oracledb.thin_impl.ThinConnImpl._connect_with_params
  File "src/oracledb/impl/thin/connection.pyx", line 456, in oracledb.thin_impl.ThinConnImpl._connect_with_description
  File "src/oracledb/impl/thin/connection.pyx", line 418, in oracledb.thin_impl.ThinConnImpl._connect_with_address
  File "C:\Users\ABIE\AppData\Local\Programs\Python\Python311\Lib\site-packages\oracledb\errors.py", line 199, in _raise_err
    raise error.exc_type(error) from cause
oracledb.exceptions.OperationalError: DPY-6005: cannot connect to database (CONNECTION_ID=3O29n473LzmOCXiVVpl37g==).
DPY-6001: Service "XEPDB1" is not registered with the listener at host "127.0.0.1" port 1521. (Similar to ORA-12514)

The above exception was the direct cause of the following exception:

Traceback (most recent call last):
  File "C:\Users\ABIE\Desktop\DataIQ\dataiq\oracle_connector.py", line 200, in connect
    conn = engine.connect()
           ^^^^^^^^^^^^^^^^
  File "C:\Users\ABIE\AppData\Local\Programs\Python\Python311\Lib\site-packages\sqlalchemy\engine\base.py", line 3269, in connect
    return self._connection_cls(self)
           ^^^^^^^^^^^^^^^^^^^^^^^^^^
  File "C:\Users\ABIE\AppData\Local\Programs\Python\Python311\Lib\site-packages\sqlalchemy\engine\base.py", line 147, in __init__
    Connection._handle_dbapi_exception_noconnection(
  File "C:\Users\ABIE\AppData\Local\Programs\Python\Python311\Lib\site-packages\sqlalchemy\engine\base.py", line 2431, in _handle_dbapi_exception_noconnection
    raise sqlalchemy_exception.with_traceback(exc_info[2]) from e
  File "C:\Users\ABIE\AppData\Local\Programs\Python\Python311\Lib\site-packages\sqlalchemy\engine\base.py", line 145, in __init__
    self._dbapi_connection = engine.raw_connection()
                             ^^^^^^^^^^^^^^^^^^^^^^^
  File "C:\Users\ABIE\AppData\Local\Programs\Python\Python311\Lib\site-packages\sqlalchemy\engine\base.py", line 3293, in raw_connection
    return self.pool.connect()
           ^^^^^^^^^^^^^^^^^^^
  File "C:\Users\ABIE\AppData\Local\Programs\Python\Python311\Lib\site-packages\sqlalchemy\pool\base.py", line 452, in connect
    return _ConnectionFairy._checkout(self)
           ^^^^^^^^^^^^^^^^^^^^^^^^^^^^^^^^
  File "C:\Users\ABIE\AppData\Local\Programs\Python\Python311\Lib\site-packages\sqlalchemy\pool\base.py", line 1269, in _checkout
    fairy = _ConnectionRecord.checkout(pool)
            ^^^^^^^^^^^^^^^^^^^^^^^^^^^^^^^^
  File "C:\Users\ABIE\AppData\Local\Programs\Python\Python311\Lib\site-packages\sqlalchemy\pool\base.py", line 716, in checkout
    rec = pool._do_get()
          ^^^^^^^^^^^^^^
  File "C:\Users\ABIE\AppData\Local\Programs\Python\Python311\Lib\site-packages\sqlalchemy\pool\impl.py", line 169, in _do_get
    with util.safe_reraise():
  File "C:\Users\ABIE\AppData\Local\Programs\Python\Python311\Lib\site-packages\sqlalchemy\util\langhelpers.py", line 146, in __exit__
    raise exc_value.with_traceback(exc_tb)
  File "C:\Users\ABIE\AppData\Local\Programs\Python\Python311\Lib\site-packages\sqlalchemy\pool\impl.py", line 167, in _do_get
    return self._create_connection()
           ^^^^^^^^^^^^^^^^^^^^^^^^^
  File "C:\Users\ABIE\AppData\Local\Programs\Python\Python311\Lib\site-packages\sqlalchemy\pool\base.py", line 393, in _create_connection
    return _ConnectionRecord(self)
           ^^^^^^^^^^^^^^^^^^^^^^^
  File "C:\Users\ABIE\AppData\Local\Programs\Python\Python311\Lib\site-packages\sqlalchemy\pool\base.py", line 678, in __init__
    self.__connect()
  File "C:\Users\ABIE\AppData\Local\Programs\Python\Python311\Lib\site-packages\sqlalchemy\pool\base.py", line 902, in __connect
    with util.safe_reraise():
  File "C:\Users\ABIE\AppData\Local\Programs\Python\Python311\Lib\site-packages\sqlalchemy\util\langhelpers.py", line 146, in __exit__
    raise exc_value.with_traceback(exc_tb)
  File "C:\Users\ABIE\AppData\Local\Programs\Python\Python311\Lib\site-packages\sqlalchemy\pool\base.py", line 898, in __connect
    self.dbapi_connection = connection = pool._invoke_creator(self)
                                         ^^^^^^^^^^^^^^^^^^^^^^^^^^
  File "C:\Users\ABIE\AppData\Local\Programs\Python\Python311\Lib\site-packages\sqlalchemy\engine\create.py", line 645, in connect
    return dialect.connect(*cargs, **cparams)
           ^^^^^^^^^^^^^^^^^^^^^^^^^^^^^^^^^^
  File "C:\Users\ABIE\AppData\Local\Programs\Python\Python311\Lib\site-packages\sqlalchemy\engine\default.py", line 616, in connect
    return self.loaded_dbapi.connect(*cargs, **cparams)
           ^^^^^^^^^^^^^^^^^^^^^^^^^^^^^^^^^^^^^^^^^^^^
  File "C:\Users\ABIE\AppData\Local\Programs\Python\Python311\Lib\site-packages\oracledb\connection.py", line 1698, in connect
    return conn_class(dsn=dsn, pool=pool, params=params, **kwargs)
           ^^^^^^^^^^^^^^^^^^^^^^^^^^^^^^^^^^^^^^^^^^^^^^^^^^^^^^^
  File "C:\Users\ABIE\AppData\Local\Programs\Python\Python311\Lib\site-packages\oracledb\connection.py", line 892, in __init__
    impl.connect(params_impl)
  File "src/oracledb/impl/thin/connection.pyx", line 536, in oracledb.thin_impl.ThinConnImpl.connect
  File "src/oracledb/impl/thin/connection.pyx", line 532, in oracledb.thin_impl.ThinConnImpl.connect
  File "src/oracledb/impl/thin/connection.pyx", line 475, in oracledb.thin_impl.ThinConnImpl._connect_with_params
  File "src/oracledb/impl/thin/connection.pyx", line 456, in oracledb.thin_impl.ThinConnImpl._connect_with_description
  File "src/oracledb/impl/thin/connection.pyx", line 418, in oracledb.thin_impl.ThinConnImpl._connect_with_address
  File "C:\Users\ABIE\AppData\Local\Programs\Python\Python311\Lib\site-packages\oracledb\errors.py", line 199, in _raise_err
    raise error.exc_type(error) from cause
sqlalchemy.exc.OperationalError: (oracledb.exceptions.OperationalError) DPY-6005: cannot connect to database (CONNECTION_ID=3O29n473LzmOCXiVVpl37g==).
DPY-6001: Service "XEPDB1" is not registered with the listener at host "127.0.0.1" port 1521. (Similar to ORA-12514)
(Background on this error at: https://sqlalche.me/e/20/e3q8)
2025-10-21 10:43:04 | ERROR | dataiq | Connection test failed: (oracledb.exceptions.OperationalError) DPY-6005: cannot connect to database (CONNECTION_ID=3O29n473LzmOCXiVVpl37g==).
DPY-6001: Service "XEPDB1" is not registered with the listener at host "127.0.0.1" port 1521. (Similar to ORA-12514)
(Background on this error at: https://sqlalche.me/e/20/e3q8)
2025-10-21 10:43:04 | INFO | dataiq | Disposed SQLAlchemy engine
2025-10-21 10:43:24 | INFO | dataiq | SQLAlchemy engine created
2025-10-21 10:43:24 | ERROR | dataiq | Failed to connect to Oracle: (oracledb.exceptions.OperationalError) DPY-6005: cannot connect to database (CONNECTION_ID=DBLjXBphInHumlaN2p6k0Q==).
DPY-6001: Service "XEPDB1" is not registered with the listener at host "127.0.0.1" port 1521. (Similar to ORA-12514)
(Background on this error at: https://sqlalche.me/e/20/e3q8)
Traceback (most recent call last):
  File "src/oracledb/impl/thin/connection.pyx", line 414, in oracledb.thin_impl.ThinConnImpl._connect_with_address
  File "src/oracledb/impl/thin/protocol.pyx", line 288, in oracledb.thin_impl.Protocol._connect_phase_one
  File "src/oracledb/impl/thin/protocol.pyx", line 470, in oracledb.thin_impl.Protocol._process_message
  File "src/oracledb/impl/thin/protocol.pyx", line 446, in oracledb.thin_impl.Protocol._process_message
  File "src/oracledb/impl/thin/messages/connect.pyx", line 95, in oracledb.thin_impl.ConnectMessage.process
  File "C:\Users\ABIE\AppData\Local\Programs\Python\Python311\Lib\site-packages\oracledb\errors.py", line 199, in _raise_err
    raise error.exc_type(error) from cause
oracledb.exceptions.OperationalError: DPY-6001: Service "XEPDB1" is not registered with the listener at host "127.0.0.1" port 1521. (Similar to ORA-12514)

The above exception was the direct cause of the following exception:

Traceback (most recent call last):
  File "C:\Users\ABIE\AppData\Local\Programs\Python\Python311\Lib\site-packages\sqlalchemy\engine\base.py", line 145, in __init__
    self._dbapi_connection = engine.raw_connection()
                             ^^^^^^^^^^^^^^^^^^^^^^^
  File "C:\Users\ABIE\AppData\Local\Programs\Python\Python311\Lib\site-packages\sqlalchemy\engine\base.py", line 3293, in raw_connection
    return self.pool.connect()
           ^^^^^^^^^^^^^^^^^^^
  File "C:\Users\ABIE\AppData\Local\Programs\Python\Python311\Lib\site-packages\sqlalchemy\pool\base.py", line 452, in connect
    return _ConnectionFairy._checkout(self)
           ^^^^^^^^^^^^^^^^^^^^^^^^^^^^^^^^
  File "C:\Users\ABIE\AppData\Local\Programs\Python\Python311\Lib\site-packages\sqlalchemy\pool\base.py", line 1269, in _checkout
    fairy = _ConnectionRecord.checkout(pool)
            ^^^^^^^^^^^^^^^^^^^^^^^^^^^^^^^^
  File "C:\Users\ABIE\AppData\Local\Programs\Python\Python311\Lib\site-packages\sqlalchemy\pool\base.py", line 716, in checkout
    rec = pool._do_get()
          ^^^^^^^^^^^^^^
  File "C:\Users\ABIE\AppData\Local\Programs\Python\Python311\Lib\site-packages\sqlalchemy\pool\impl.py", line 169, in _do_get
    with util.safe_reraise():
  File "C:\Users\ABIE\AppData\Local\Programs\Python\Python311\Lib\site-packages\sqlalchemy\util\langhelpers.py", line 146, in __exit__
    raise exc_value.with_traceback(exc_tb)
  File "C:\Users\ABIE\AppData\Local\Programs\Python\Python311\Lib\site-packages\sqlalchemy\pool\impl.py", line 167, in _do_get
    return self._create_connection()
           ^^^^^^^^^^^^^^^^^^^^^^^^^
  File "C:\Users\ABIE\AppData\Local\Programs\Python\Python311\Lib\site-packages\sqlalchemy\pool\base.py", line 393, in _create_connection
    return _ConnectionRecord(self)
           ^^^^^^^^^^^^^^^^^^^^^^^
  File "C:\Users\ABIE\AppData\Local\Programs\Python\Python311\Lib\site-packages\sqlalchemy\pool\base.py", line 678, in __init__
    self.__connect()
  File "C:\Users\ABIE\AppData\Local\Programs\Python\Python311\Lib\site-packages\sqlalchemy\pool\base.py", line 902, in __connect
    with util.safe_reraise():
  File "C:\Users\ABIE\AppData\Local\Programs\Python\Python311\Lib\site-packages\sqlalchemy\util\langhelpers.py", line 146, in __exit__
    raise exc_value.with_traceback(exc_tb)
  File "C:\Users\ABIE\AppData\Local\Programs\Python\Python311\Lib\site-packages\sqlalchemy\pool\base.py", line 898, in __connect
    self.dbapi_connection = connection = pool._invoke_creator(self)
                                         ^^^^^^^^^^^^^^^^^^^^^^^^^^
  File "C:\Users\ABIE\AppData\Local\Programs\Python\Python311\Lib\site-packages\sqlalchemy\engine\create.py", line 645, in connect
    return dialect.connect(*cargs, **cparams)
           ^^^^^^^^^^^^^^^^^^^^^^^^^^^^^^^^^^
  File "C:\Users\ABIE\AppData\Local\Programs\Python\Python311\Lib\site-packages\sqlalchemy\engine\default.py", line 616, in connect
    return self.loaded_dbapi.connect(*cargs, **cparams)
           ^^^^^^^^^^^^^^^^^^^^^^^^^^^^^^^^^^^^^^^^^^^^
  File "C:\Users\ABIE\AppData\Local\Programs\Python\Python311\Lib\site-packages\oracledb\connection.py", line 1698, in connect
    return conn_class(dsn=dsn, pool=pool, params=params, **kwargs)
           ^^^^^^^^^^^^^^^^^^^^^^^^^^^^^^^^^^^^^^^^^^^^^^^^^^^^^^^
  File "C:\Users\ABIE\AppData\Local\Programs\Python\Python311\Lib\site-packages\oracledb\connection.py", line 892, in __init__
    impl.connect(params_impl)
  File "src/oracledb/impl/thin/connection.pyx", line 536, in oracledb.thin_impl.ThinConnImpl.connect
  File "src/oracledb/impl/thin/connection.pyx", line 532, in oracledb.thin_impl.ThinConnImpl.connect
  File "src/oracledb/impl/thin/connection.pyx", line 475, in oracledb.thin_impl.ThinConnImpl._connect_with_params
  File "src/oracledb/impl/thin/connection.pyx", line 456, in oracledb.thin_impl.ThinConnImpl._connect_with_description
  File "src/oracledb/impl/thin/connection.pyx", line 418, in oracledb.thin_impl.ThinConnImpl._connect_with_address
  File "C:\Users\ABIE\AppData\Local\Programs\Python\Python311\Lib\site-packages\oracledb\errors.py", line 199, in _raise_err
    raise error.exc_type(error) from cause
oracledb.exceptions.OperationalError: DPY-6005: cannot connect to database (CONNECTION_ID=DBLjXBphInHumlaN2p6k0Q==).
DPY-6001: Service "XEPDB1" is not registered with the listener at host "127.0.0.1" port 1521. (Similar to ORA-12514)

The above exception was the direct cause of the following exception:

Traceback (most recent call last):
  File "C:\Users\ABIE\Desktop\DataIQ\dataiq\oracle_connector.py", line 200, in connect
    conn = engine.connect()
           ^^^^^^^^^^^^^^^^
  File "C:\Users\ABIE\AppData\Local\Programs\Python\Python311\Lib\site-packages\sqlalchemy\engine\base.py", line 3269, in connect
    return self._connection_cls(self)
           ^^^^^^^^^^^^^^^^^^^^^^^^^^
  File "C:\Users\ABIE\AppData\Local\Programs\Python\Python311\Lib\site-packages\sqlalchemy\engine\base.py", line 147, in __init__
    Connection._handle_dbapi_exception_noconnection(
  File "C:\Users\ABIE\AppData\Local\Programs\Python\Python311\Lib\site-packages\sqlalchemy\engine\base.py", line 2431, in _handle_dbapi_exception_noconnection
    raise sqlalchemy_exception.with_traceback(exc_info[2]) from e
  File "C:\Users\ABIE\AppData\Local\Programs\Python\Python311\Lib\site-packages\sqlalchemy\engine\base.py", line 145, in __init__
    self._dbapi_connection = engine.raw_connection()
                             ^^^^^^^^^^^^^^^^^^^^^^^
  File "C:\Users\ABIE\AppData\Local\Programs\Python\Python311\Lib\site-packages\sqlalchemy\engine\base.py", line 3293, in raw_connection
    return self.pool.connect()
           ^^^^^^^^^^^^^^^^^^^
  File "C:\Users\ABIE\AppData\Local\Programs\Python\Python311\Lib\site-packages\sqlalchemy\pool\base.py", line 452, in connect
    return _ConnectionFairy._checkout(self)
           ^^^^^^^^^^^^^^^^^^^^^^^^^^^^^^^^
  File "C:\Users\ABIE\AppData\Local\Programs\Python\Python311\Lib\site-packages\sqlalchemy\pool\base.py", line 1269, in _checkout
    fairy = _ConnectionRecord.checkout(pool)
            ^^^^^^^^^^^^^^^^^^^^^^^^^^^^^^^^
  File "C:\Users\ABIE\AppData\Local\Programs\Python\Python311\Lib\site-packages\sqlalchemy\pool\base.py", line 716, in checkout
    rec = pool._do_get()
          ^^^^^^^^^^^^^^
  File "C:\Users\ABIE\AppData\Local\Programs\Python\Python311\Lib\site-packages\sqlalchemy\pool\impl.py", line 169, in _do_get
    with util.safe_reraise():
  File "C:\Users\ABIE\AppData\Local\Programs\Python\Python311\Lib\site-packages\sqlalchemy\util\langhelpers.py", line 146, in __exit__
    raise exc_value.with_traceback(exc_tb)
  File "C:\Users\ABIE\AppData\Local\Programs\Python\Python311\Lib\site-packages\sqlalchemy\pool\impl.py", line 167, in _do_get
    return self._create_connection()
           ^^^^^^^^^^^^^^^^^^^^^^^^^
  File "C:\Users\ABIE\AppData\Local\Programs\Python\Python311\Lib\site-packages\sqlalchemy\pool\base.py", line 393, in _create_connection
    return _ConnectionRecord(self)
           ^^^^^^^^^^^^^^^^^^^^^^^
  File "C:\Users\ABIE\AppData\Local\Programs\Python\Python311\Lib\site-packages\sqlalchemy\pool\base.py", line 678, in __init__
    self.__connect()
  File "C:\Users\ABIE\AppData\Local\Programs\Python\Python311\Lib\site-packages\sqlalchemy\pool\base.py", line 902, in __connect
    with util.safe_reraise():
  File "C:\Users\ABIE\AppData\Local\Programs\Python\Python311\Lib\site-packages\sqlalchemy\util\langhelpers.py", line 146, in __exit__
    raise exc_value.with_traceback(exc_tb)
  File "C:\Users\ABIE\AppData\Local\Programs\Python\Python311\Lib\site-packages\sqlalchemy\pool\base.py", line 898, in __connect
    self.dbapi_connection = connection = pool._invoke_creator(self)
                                         ^^^^^^^^^^^^^^^^^^^^^^^^^^
  File "C:\Users\ABIE\AppData\Local\Programs\Python\Python311\Lib\site-packages\sqlalchemy\engine\create.py", line 645, in connect
    return dialect.connect(*cargs, **cparams)
           ^^^^^^^^^^^^^^^^^^^^^^^^^^^^^^^^^^
  File "C:\Users\ABIE\AppData\Local\Programs\Python\Python311\Lib\site-packages\sqlalchemy\engine\default.py", line 616, in connect
    return self.loaded_dbapi.connect(*cargs, **cparams)
           ^^^^^^^^^^^^^^^^^^^^^^^^^^^^^^^^^^^^^^^^^^^^
  File "C:\Users\ABIE\AppData\Local\Programs\Python\Python311\Lib\site-packages\oracledb\connection.py", line 1698, in connect
    return conn_class(dsn=dsn, pool=pool, params=params, **kwargs)
           ^^^^^^^^^^^^^^^^^^^^^^^^^^^^^^^^^^^^^^^^^^^^^^^^^^^^^^^
  File "C:\Users\ABIE\AppData\Local\Programs\Python\Python311\Lib\site-packages\oracledb\connection.py", line 892, in __init__
    impl.connect(params_impl)
  File "src/oracledb/impl/thin/connection.pyx", line 536, in oracledb.thin_impl.ThinConnImpl.connect
  File "src/oracledb/impl/thin/connection.pyx", line 532, in oracledb.thin_impl.ThinConnImpl.connect
  File "src/oracledb/impl/thin/connection.pyx", line 475, in oracledb.thin_impl.ThinConnImpl._connect_with_params
  File "src/oracledb/impl/thin/connection.pyx", line 456, in oracledb.thin_impl.ThinConnImpl._connect_with_description
  File "src/oracledb/impl/thin/connection.pyx", line 418, in oracledb.thin_impl.ThinConnImpl._connect_with_address
  File "C:\Users\ABIE\AppData\Local\Programs\Python\Python311\Lib\site-packages\oracledb\errors.py", line 199, in _raise_err
    raise error.exc_type(error) from cause
sqlalchemy.exc.OperationalError: (oracledb.exceptions.OperationalError) DPY-6005: cannot connect to database (CONNECTION_ID=DBLjXBphInHumlaN2p6k0Q==).
DPY-6001: Service "XEPDB1" is not registered with the listener at host "127.0.0.1" port 1521. (Similar to ORA-12514)
(Background on this error at: https://sqlalche.me/e/20/e3q8)
2025-10-21 10:43:24 | ERROR | dataiq | Connection test failed: (oracledb.exceptions.OperationalError) DPY-6005: cannot connect to database (CONNECTION_ID=DBLjXBphInHumlaN2p6k0Q==).
DPY-6001: Service "XEPDB1" is not registered with the listener at host "127.0.0.1" port 1521. (Similar to ORA-12514)
(Background on this error at: https://sqlalche.me/e/20/e3q8)
2025-10-21 10:43:24 | INFO | dataiq | Disposed SQLAlchemy engine
2025-10-21 10:43:33 | INFO | dataiq | SQLAlchemy engine created
2025-10-21 10:43:33 | ERROR | dataiq | Failed to connect to Oracle: (oracledb.exceptions.OperationalError) DPY-6005: cannot connect to database (CONNECTION_ID=R3GpERPUfRxzwO32zY3yOA==).
DPY-6001: Service "XEPDB1" is not registered with the listener at host "127.0.0.1" port 1521. (Similar to ORA-12514)
(Background on this error at: https://sqlalche.me/e/20/e3q8)
Traceback (most recent call last):
  File "src/oracledb/impl/thin/connection.pyx", line 414, in oracledb.thin_impl.ThinConnImpl._connect_with_address
  File "src/oracledb/impl/thin/protocol.pyx", line 288, in oracledb.thin_impl.Protocol._connect_phase_one
  File "src/oracledb/impl/thin/protocol.pyx", line 470, in oracledb.thin_impl.Protocol._process_message
  File "src/oracledb/impl/thin/protocol.pyx", line 446, in oracledb.thin_impl.Protocol._process_message
  File "src/oracledb/impl/thin/messages/connect.pyx", line 95, in oracledb.thin_impl.ConnectMessage.process
  File "C:\Users\ABIE\AppData\Local\Programs\Python\Python311\Lib\site-packages\oracledb\errors.py", line 199, in _raise_err
    raise error.exc_type(error) from cause
oracledb.exceptions.OperationalError: DPY-6001: Service "XEPDB1" is not registered with the listener at host "127.0.0.1" port 1521. (Similar to ORA-12514)

The above exception was the direct cause of the following exception:

Traceback (most recent call last):
  File "C:\Users\ABIE\AppData\Local\Programs\Python\Python311\Lib\site-packages\sqlalchemy\engine\base.py", line 145, in __init__
    self._dbapi_connection = engine.raw_connection()
                             ^^^^^^^^^^^^^^^^^^^^^^^
  File "C:\Users\ABIE\AppData\Local\Programs\Python\Python311\Lib\site-packages\sqlalchemy\engine\base.py", line 3293, in raw_connection
    return self.pool.connect()
           ^^^^^^^^^^^^^^^^^^^
  File "C:\Users\ABIE\AppData\Local\Programs\Python\Python311\Lib\site-packages\sqlalchemy\pool\base.py", line 452, in connect
    return _ConnectionFairy._checkout(self)
           ^^^^^^^^^^^^^^^^^^^^^^^^^^^^^^^^
  File "C:\Users\ABIE\AppData\Local\Programs\Python\Python311\Lib\site-packages\sqlalchemy\pool\base.py", line 1269, in _checkout
    fairy = _ConnectionRecord.checkout(pool)
            ^^^^^^^^^^^^^^^^^^^^^^^^^^^^^^^^
  File "C:\Users\ABIE\AppData\Local\Programs\Python\Python311\Lib\site-packages\sqlalchemy\pool\base.py", line 716, in checkout
    rec = pool._do_get()
          ^^^^^^^^^^^^^^
  File "C:\Users\ABIE\AppData\Local\Programs\Python\Python311\Lib\site-packages\sqlalchemy\pool\impl.py", line 169, in _do_get
    with util.safe_reraise():
  File "C:\Users\ABIE\AppData\Local\Programs\Python\Python311\Lib\site-packages\sqlalchemy\util\langhelpers.py", line 146, in __exit__
    raise exc_value.with_traceback(exc_tb)
  File "C:\Users\ABIE\AppData\Local\Programs\Python\Python311\Lib\site-packages\sqlalchemy\pool\impl.py", line 167, in _do_get
    return self._create_connection()
           ^^^^^^^^^^^^^^^^^^^^^^^^^
  File "C:\Users\ABIE\AppData\Local\Programs\Python\Python311\Lib\site-packages\sqlalchemy\pool\base.py", line 393, in _create_connection
    return _ConnectionRecord(self)
           ^^^^^^^^^^^^^^^^^^^^^^^
  File "C:\Users\ABIE\AppData\Local\Programs\Python\Python311\Lib\site-packages\sqlalchemy\pool\base.py", line 678, in __init__
    self.__connect()
  File "C:\Users\ABIE\AppData\Local\Programs\Python\Python311\Lib\site-packages\sqlalchemy\pool\base.py", line 902, in __connect
    with util.safe_reraise():
  File "C:\Users\ABIE\AppData\Local\Programs\Python\Python311\Lib\site-packages\sqlalchemy\util\langhelpers.py", line 146, in __exit__
    raise exc_value.with_traceback(exc_tb)
  File "C:\Users\ABIE\AppData\Local\Programs\Python\Python311\Lib\site-packages\sqlalchemy\pool\base.py", line 898, in __connect
    self.dbapi_connection = connection = pool._invoke_creator(self)
                                         ^^^^^^^^^^^^^^^^^^^^^^^^^^
  File "C:\Users\ABIE\AppData\Local\Programs\Python\Python311\Lib\site-packages\sqlalchemy\engine\create.py", line 645, in connect
    return dialect.connect(*cargs, **cparams)
           ^^^^^^^^^^^^^^^^^^^^^^^^^^^^^^^^^^
  File "C:\Users\ABIE\AppData\Local\Programs\Python\Python311\Lib\site-packages\sqlalchemy\engine\default.py", line 616, in connect
    return self.loaded_dbapi.connect(*cargs, **cparams)
           ^^^^^^^^^^^^^^^^^^^^^^^^^^^^^^^^^^^^^^^^^^^^
  File "C:\Users\ABIE\AppData\Local\Programs\Python\Python311\Lib\site-packages\oracledb\connection.py", line 1698, in connect
    return conn_class(dsn=dsn, pool=pool, params=params, **kwargs)
           ^^^^^^^^^^^^^^^^^^^^^^^^^^^^^^^^^^^^^^^^^^^^^^^^^^^^^^^
  File "C:\Users\ABIE\AppData\Local\Programs\Python\Python311\Lib\site-packages\oracledb\connection.py", line 892, in __init__
    impl.connect(params_impl)
  File "src/oracledb/impl/thin/connection.pyx", line 536, in oracledb.thin_impl.ThinConnImpl.connect
  File "src/oracledb/impl/thin/connection.pyx", line 532, in oracledb.thin_impl.ThinConnImpl.connect
  File "src/oracledb/impl/thin/connection.pyx", line 475, in oracledb.thin_impl.ThinConnImpl._connect_with_params
  File "src/oracledb/impl/thin/connection.pyx", line 456, in oracledb.thin_impl.ThinConnImpl._connect_with_description
  File "src/oracledb/impl/thin/connection.pyx", line 418, in oracledb.thin_impl.ThinConnImpl._connect_with_address
  File "C:\Users\ABIE\AppData\Local\Programs\Python\Python311\Lib\site-packages\oracledb\errors.py", line 199, in _raise_err
    raise error.exc_type(error) from cause
oracledb.exceptions.OperationalError: DPY-6005: cannot connect to database (CONNECTION_ID=R3GpERPUfRxzwO32zY3yOA==).
DPY-6001: Service "XEPDB1" is not registered with the listener at host "127.0.0.1" port 1521. (Similar to ORA-12514)

The above exception was the direct cause of the following exception:

Traceback (most recent call last):
  File "C:\Users\ABIE\Desktop\DataIQ\dataiq\oracle_connector.py", line 200, in connect
    conn = engine.connect()
           ^^^^^^^^^^^^^^^^
  File "C:\Users\ABIE\AppData\Local\Programs\Python\Python311\Lib\site-packages\sqlalchemy\engine\base.py", line 3269, in connect
    return self._connection_cls(self)
           ^^^^^^^^^^^^^^^^^^^^^^^^^^
  File "C:\Users\ABIE\AppData\Local\Programs\Python\Python311\Lib\site-packages\sqlalchemy\engine\base.py", line 147, in __init__
    Connection._handle_dbapi_exception_noconnection(
  File "C:\Users\ABIE\AppData\Local\Programs\Python\Python311\Lib\site-packages\sqlalchemy\engine\base.py", line 2431, in _handle_dbapi_exception_noconnection
    raise sqlalchemy_exception.with_traceback(exc_info[2]) from e
  File "C:\Users\ABIE\AppData\Local\Programs\Python\Python311\Lib\site-packages\sqlalchemy\engine\base.py", line 145, in __init__
    self._dbapi_connection = engine.raw_connection()
                             ^^^^^^^^^^^^^^^^^^^^^^^
  File "C:\Users\ABIE\AppData\Local\Programs\Python\Python311\Lib\site-packages\sqlalchemy\engine\base.py", line 3293, in raw_connection
    return self.pool.connect()
           ^^^^^^^^^^^^^^^^^^^
  File "C:\Users\ABIE\AppData\Local\Programs\Python\Python311\Lib\site-packages\sqlalchemy\pool\base.py", line 452, in connect
    return _ConnectionFairy._checkout(self)
           ^^^^^^^^^^^^^^^^^^^^^^^^^^^^^^^^
  File "C:\Users\ABIE\AppData\Local\Programs\Python\Python311\Lib\site-packages\sqlalchemy\pool\base.py", line 1269, in _checkout
    fairy = _ConnectionRecord.checkout(pool)
            ^^^^^^^^^^^^^^^^^^^^^^^^^^^^^^^^
  File "C:\Users\ABIE\AppData\Local\Programs\Python\Python311\Lib\site-packages\sqlalchemy\pool\base.py", line 716, in checkout
    rec = pool._do_get()
          ^^^^^^^^^^^^^^
  File "C:\Users\ABIE\AppData\Local\Programs\Python\Python311\Lib\site-packages\sqlalchemy\pool\impl.py", line 169, in _do_get
    with util.safe_reraise():
  File "C:\Users\ABIE\AppData\Local\Programs\Python\Python311\Lib\site-packages\sqlalchemy\util\langhelpers.py", line 146, in __exit__
    raise exc_value.with_traceback(exc_tb)
  File "C:\Users\ABIE\AppData\Local\Programs\Python\Python311\Lib\site-packages\sqlalchemy\pool\impl.py", line 167, in _do_get
    return self._create_connection()
           ^^^^^^^^^^^^^^^^^^^^^^^^^
  File "C:\Users\ABIE\AppData\Local\Programs\Python\Python311\Lib\site-packages\sqlalchemy\pool\base.py", line 393, in _create_connection
    return _ConnectionRecord(self)
           ^^^^^^^^^^^^^^^^^^^^^^^
  File "C:\Users\ABIE\AppData\Local\Programs\Python\Python311\Lib\site-packages\sqlalchemy\pool\base.py", line 678, in __init__
    self.__connect()
  File "C:\Users\ABIE\AppData\Local\Programs\Python\Python311\Lib\site-packages\sqlalchemy\pool\base.py", line 902, in __connect
    with util.safe_reraise():
  File "C:\Users\ABIE\AppData\Local\Programs\Python\Python311\Lib\site-packages\sqlalchemy\util\langhelpers.py", line 146, in __exit__
    raise exc_value.with_traceback(exc_tb)
  File "C:\Users\ABIE\AppData\Local\Programs\Python\Python311\Lib\site-packages\sqlalchemy\pool\base.py", line 898, in __connect
    self.dbapi_connection = connection = pool._invoke_creator(self)
                                         ^^^^^^^^^^^^^^^^^^^^^^^^^^
  File "C:\Users\ABIE\AppData\Local\Programs\Python\Python311\Lib\site-packages\sqlalchemy\engine\create.py", line 645, in connect
    return dialect.connect(*cargs, **cparams)
           ^^^^^^^^^^^^^^^^^^^^^^^^^^^^^^^^^^
  File "C:\Users\ABIE\AppData\Local\Programs\Python\Python311\Lib\site-packages\sqlalchemy\engine\default.py", line 616, in connect
    return self.loaded_dbapi.connect(*cargs, **cparams)
           ^^^^^^^^^^^^^^^^^^^^^^^^^^^^^^^^^^^^^^^^^^^^
  File "C:\Users\ABIE\AppData\Local\Programs\Python\Python311\Lib\site-packages\oracledb\connection.py", line 1698, in connect
    return conn_class(dsn=dsn, pool=pool, params=params, **kwargs)
           ^^^^^^^^^^^^^^^^^^^^^^^^^^^^^^^^^^^^^^^^^^^^^^^^^^^^^^^
  File "C:\Users\ABIE\AppData\Local\Programs\Python\Python311\Lib\site-packages\oracledb\connection.py", line 892, in __init__
    impl.connect(params_impl)
  File "src/oracledb/impl/thin/connection.pyx", line 536, in oracledb.thin_impl.ThinConnImpl.connect
  File "src/oracledb/impl/thin/connection.pyx", line 532, in oracledb.thin_impl.ThinConnImpl.connect
  File "src/oracledb/impl/thin/connection.pyx", line 475, in oracledb.thin_impl.ThinConnImpl._connect_with_params
  File "src/oracledb/impl/thin/connection.pyx", line 456, in oracledb.thin_impl.ThinConnImpl._connect_with_description
  File "src/oracledb/impl/thin/connection.pyx", line 418, in oracledb.thin_impl.ThinConnImpl._connect_with_address
  File "C:\Users\ABIE\AppData\Local\Programs\Python\Python311\Lib\site-packages\oracledb\errors.py", line 199, in _raise_err
    raise error.exc_type(error) from cause
sqlalchemy.exc.OperationalError: (oracledb.exceptions.OperationalError) DPY-6005: cannot connect to database (CONNECTION_ID=R3GpERPUfRxzwO32zY3yOA==).
DPY-6001: Service "XEPDB1" is not registered with the listener at host "127.0.0.1" port 1521. (Similar to ORA-12514)
(Background on this error at: https://sqlalche.me/e/20/e3q8)
2025-10-21 10:43:33 | ERROR | dataiq | Connection test failed: (oracledb.exceptions.OperationalError) DPY-6005: cannot connect to database (CONNECTION_ID=R3GpERPUfRxzwO32zY3yOA==).
DPY-6001: Service "XEPDB1" is not registered with the listener at host "127.0.0.1" port 1521. (Similar to ORA-12514)
(Background on this error at: https://sqlalche.me/e/20/e3q8)
2025-10-21 10:43:33 | INFO | dataiq | Disposed SQLAlchemy engine
